Workbook

Sheet kshotoku1631
A1: Ⅲ．雇用者報酬
A2: Compensation of Employees | S2: (単位:10億円、%)
A3: 名 目 | K3: 実 質(2005暦年連鎖価格)
A4: AT CURRENT PRICES | K4: Chained (2005) yen
C5: 四半期・原系列 | E5: 四半期・季節調整系列 | G5: 年度 、 暦年 | M5: 四半期・原系列 | O5: 四半期・季節調整系列 | Q5: 年度 、 暦年
C6: Original series | E6: Seasonally adjusted series | G6: Fiscal year , Calendar year | M6: Original series | O6: Seasonally adjusted series | Q6: Fiscal year , Calendar year
C7: 実数 | D7: (**) | E7: 実数 | F7: (***) | H7: 実数 | I7: (**) | M7: 実数 | N7: (**) | O7: 実数 | P7: (***) | R7: 実数 | S7: (**)
C8: billion yen | D8: (**) | E8: billion yen | F8: (***) | H8: billion yen | I8: (**) | M8: billion yen | N8: (**) | O8: billion yen | P8: (***) | R8: billion yen | S8: (**)
A9: 1980/ | B9: 1-3. | C9: 25552.1 | E9: 124110.7
B10: 4-6. | C10: 31503 | E10: 126919.2 | F10: 2.3
B11: 7-9. | C11: 32068.3 | E11: 131191 | F11: 3.4
B12: 10-12. | C12: 40327.3 | E12: 134097.1 | F12: 2.2
A13: 1981/ | B13: 1-3. | C13: 27951.7 | D13: 9.4 | E13: 135507.4 | F13: 1.1
B14: 4-6. | C14: 34652.4 | D14: 10 | E14: 138934.6 | F14: 2.5
B15: 7-9. | C15: 34272.8 | D15: 6.9 | E15: 140458.7 | F15: 1.1
B16: 10-12. | C16: 43335.4 | D16: 7.5 | E16: 144577.2 | F16: 2.9
A17: 1982/ | B17: 1-3. | C17: 29837.1 | D17: 6.7 | E17: 144263.5 | F17: -0.2
B18: 4-6. | C18: 36628.4 | D18: 5.7 | E18: 146887 | F18: 1.8
B19: 7-9. | C19: 36421.4 | D19: 6.3 | E19: 149120.3 | F19: 1.5
B20: 10-12. | C20: 45253 | D20: 4.4 | E20: 151218.7 | F20: 1.4
A21: 1983/ | B21: 1-3. | C21: 31930.2 | D21: 7 | E21: 153874.8 | F21: 1.8
B22: 4-6. | C22: 38500.2 | D22: 5.1 | E22: 154328.2 | F22: 0.3
B23: 7-9. | C23: 38256.5 | D23: 5 | E23: 156784.3 | F23: 1.6
B24: 10-12. | C24: 47107.2 | D24: 4.1 | E24: 157849.2 | F24: 0.7
A25: 1984/ | B25: 1-3. | C25: 33437.4 | D25: 4.7 | E25: 160673.2 | F25: 1.8
B26: 4-6. | C26: 40757.7 | D26: 5.9 | E26: 163500.9 | F26: 1.8
B27: 7-9. | C27: 40117.1 | D27: 4.9 | E27: 164339.9 | F27: 0.5
B28: 10-12. | C28: 50005.6 | D28: 6.2 | E28: 167802.4 | F28: 2.1
A29: 1985/ | B29: 1-3. | C29: 35136.8 | D29: 5.1 | E29: 168533.3 | F29: 0.4
B30: 4-6. | C30: 42509.9 | D30: 4.3 | E30: 170237.7 | F30: 1
B31: 7-9. | C31: 42163.1 | D31: 5.1 | E31: 172902.1 | F31: 1.6
B32: 10-12. | C32: 52046.2 | D32: 4.1 | E32: 175093.4 | F32: 1.3
A33: 1986/ | B33: 1-3. | C33: 37257.8 | D33: 6 | E33: 178303.6 | F33: 1.8
B34: 4-6. | C34: 44327.2 | D34: 4.3 | E34: 177664 | F34: -0.4
B35: 7-9. | C35: 43898.5 | D35: 4.1 | E35: 179952.6 | F35: 1.3
B36: 10-12. | C36: 53702.7 | D36: 3.2 | E36: 180927 | F36: 0.5
A37: 1987/ | B37: 1-3. | C37: 38261 | D37: 2.7 | E37: 183103.8 | F37: 1.2
B38: 4-6. | C38: 46264 | D38: 4.4 | E38: 184080.9 | F38: 0.5
B39: 7-9. | C39: 45092.4 | D39: 2.7 | E39: 185299 | F39: 0.7
B40: 10-12. | C40: 55752.8 | D40: 3.8 | E40: 187985.2 | F40: 1.4
...

Sheet kgaku-mk1131
A1: 名目季節調整系列 | R1: (単位:10億円)
A2: Nominal (seasonally adjusted series) | R2: (billion yen)
B3: 家計最終消費支出（再掲） | M3: 財貨・サービス
C4: 居住者家計の海外での直接購入 | D4: （控除）非居住者家計の国内での直接購入 | E4: 国内家計最終消費支出 | L4: 純輸出（再掲） | M4: 輸出（再掲） | P4: 輸入（再掲）
F5: 耐久財 | G5: 半耐久財 | H5: 非耐久財 | I5: サービス | N5: 財貨 | O5: サービス（含む非居住者家計の国内での直接購入） | Q5: 財貨 | R5: サービス（含む居住者家計の海外での直接購入）
B6: Consumptionof households(id, at §Ｉ) | C6: Directpurchasesabroad byresidenthouseholds | D6: (Less) Directpurchases inthe domesticmarket bynon-residenthouseholds | E6: Domestic final consumption expenditure of households | F6: Durablegoods | G6: Semi-durablegoods | H6: Non-durablegoods | I6: Services | M6: Goods & Services
L7: Net Exports(id, at §Ｉ) | M7: Exports(id, at §Ｉ) | P7: Imports(id, at §Ｉ)
N8: Goods | O8: Services（including directpurchases in thedomestic marketby non-residenthouseholds) | Q8: Goods | R8: Services（including directpurchasesabroad byresidenthouseholds)
A9: 1980/ 1- 3. | B9: 126227.9 | C9: 617.1 | D9: 97.7 | E9: 125708.5 | F9: 8636.7 | G9: 16644.7 | H9: 45044.9 | I9: 55382.1 | L9: -3378.3 | M9: 32405.7 | N9: 28347.2 | O9: 4058.4 | P9: 35783.9 | Q9: 29652.4 | R9: 6131.5
A10: 4- 6. | B10: 128731.1 | C10: 625 | D10: 94.4 | E10: 128200.5 | F10: 8282.7 | G10: 17020.1 | H10: 46185.1 | I10: 56712.6 | L10: -4367.3 | M10: 32842.5 | N10: 28954.6 | O10: 3887.9 | P10: 37209.8 | Q10: 31238.9 | R10: 5970.9
A11: 7- 9. | B11: 131821.4 | C11: 624.8 | D11: 89.7 | E11: 131286.3 | F11: 8254.2 | G11: 17233.4 | H11: 47236.7 | I11: 58562 | L11: -1801.9 | M11: 31961.2 | N11: 28252.9 | O11: 3708.2 | P11: 33763.1 | Q11: 28167 | R11: 5596.1
A12: 10-12. | B12: 133934.7 | C12: 532.3 | D12: 93.1 | E12: 133495.5 | F12: 8329.1 | G12: 17748.9 | H12: 48217.9 | I12: 59199.6 | L12: 556.2 | M12: 34029.9 | N12: 30260.8 | O12: 3769.1 | P12: 33473.7 | Q12: 27660.5 | R12: 5813.2
A13: 1981/ 1- 3. | B13: 135583.3 | C13: 572.2 | D13: 95.6 | E13: 135106.6 | F13: 8243.4 | G13: 17163.6 | H13: 49269 | I13: 60430.6 | L13: 1194.6 | M13: 35309.6 | N13: 31386.9 | O13: 3922.7 | P13: 34115 | Q13: 28044.7 | R13: 6070.2
A14: 4- 6. | B14: 137352.8 | C14: 560.2 | D14: 97.1 | E14: 136889.7 | F14: 8711.4 | G14: 16940.8 | H14: 49679.2 | I14: 61558.4 | L14: 1281.3 | M14: 37673.8 | N14: 33369.9 | O14: 4303.9 | P14: 36392.5 | Q14: 29945.2 | R14: 6447.3
A15: 7- 9. | B15: 139438.9 | C15: 564.9 | D15: 120.4 | E15: 138994.4 | F15: 8999.9 | G15: 17159.2 | H15: 50352.8 | I15: 62482.5 | L15: 2879.2 | M15: 39338.2 | N15: 34896.8 | O15: 4441.4 | P15: 36458.9 | Q15: 29910.9 | R15: 6548
A16: 10-12. | B16: 141814 | C16: 556.6 | D16: 98.9 | E16: 141356.3 | F16: 8825.6 | G16: 17703.6 | H16: 51284.1 | I16: 63543.1 | L16: 2106.7 | M16: 38834.4 | N16: 34507.3 | O16: 4327 | P16: 36727.7 | Q16: 30152.6 | R16: 6575.1
A17: 1982/ 1- 3. | B17: 145022.4 | C17: 532 | D17: 109.1 | E17: 144599.5 | F17: 8996.3 | G17: 18460.6 | H17: 51693.6 | I17: 65448.9 | L17: 1863.7 | M17: 39909.6 | N17: 35318.2 | O17: 4591.4 | P17: 38045.9 | Q17: 31386.3 | R17: 6659.6
A18: 4- 6. | B18: 147947.7 | C18: 513.5 | D18: 125 | E18: 147559.1 | F18: 9359.2 | G18: 18574 | H18: 52642.3 | I18: 66983.5 | L18: 2014.4 | M18: 39106.5 | N18: 34628.2 | O18: 4478.3 | P18: 37092 | Q18: 30482.2 | R18: 6609.8
A19: 7- 9. | B19: 148700.2 | C19: 516.2 | D19: 121.3 | E19: 148305.3 | F19: 9177.8 | G19: 18850.5 | H19: 53156.4 | I19: 67120.7 | L19: 1920.6 | M19: 39212.3 | N19: 34696.7 | O19: 4515.6 | P19: 37291.7 | Q19: 30616.2 | R19: 6675.5
A20: 10-12. | B20: 153540.7 | C20: 539.5 | D20: 135.3 | E20: 153136.5 | F20: 10260.4 | G20: 18974.9 | H20: 53777 | I20: 70124.2 | L20: 1639.6 | M20: 38591.4 | N20: 34051.6 | O20: 4539.8 | P20: 36951.8 | Q20: 30213.8 | R20: 6738
... A135: 7- 9. | B135: 271665.8 | C135: 1932.8 | D135: 706.8 | E135: 270439.8 | F135: 21847.2 | G135: 19227.6 | H135: 72622.7 | I135: 156742.3 | L135: -4801.6 | M135: 72755.7 | N135: 64933.2 | O135: 7822.5 | P135: 77557.3 | Q135: 66414.1 | R135: 11143.2
A136: ＊年率で表示している。
A139: avg | B139: =+AVERAGE(B9:B135) -> 239166.08 | C139: =+AVERAGE(C9:C135) -> 2136.3819 | D139: =+AVERAGE(D9:D135) -> 399.30866 | E139: =+AVERAGE(E9:E135) -> 237429 | F139: =+AVERAGE(F9:F135) -> 20408.809 | G139: =+AVERAGE(G9:G135) -> 23519.694 | H139: =+AVERAGE(H9:H135) -> 68177.198 | I139: =+AVERAGE(I9:I135) -> 125323.29 | L139: =+AVERAGE(L9:L135) -> 6315.248

Sheet kgaku-jk1131
A1: 実質季節調整系列 | R1: (単位:2000暦年連鎖価格、10億円)
A2: Real (seasonally adjusted series) | R2: (Billions of chained (2000) yen)
B3: 家計最終消費支出（再掲） | M3: 財貨・サービス
C4: 居住者家計の海外での直接購入 | D4: （控除）非居住者家計の国内での直接購入 | E4: 国内家計最終消費支出 | L4: 純輸出（再掲） | M4: 輸出（再掲） | P4: 輸入（再掲）
F5: 耐久財 | G5: 半耐久財 | H5: 非耐久財 | I5: サービス | N5: 財貨 | O5: サービス（含む非居住者家計の国内での直接購入） | Q5: 財貨 | R5: サービス（含む居住者家計の海外での直接購入）
B6: Consumptionof households(id, at §Ｉ) | C6: Directpurchasesabroad byresidenthouseholds | D6: (Less) Directpurchases inthe domesticmarket bynon-residenthouseholds | E6: Domestic finalconsumptionexpenditure ofhouseholds | F6: Durablegoods | G6: Semi-durablegoods | H6: Non-durablegoods | I6: Services | M6: Goods & Services
L7: Net Exports(id, at §Ｉ) | M7: Exports(id, at §Ｉ) | P7: Imports(id, at §Ｉ)
N8: Goods | O8: Services（including directpurchases in thedomestic marketby non-residenthouseholds) | Q8: Goods | R8: Services（including directpurchasesabroad byresidenthouseholds)
A9: 1980/ 1- 3. | B9: 164321.7 | C9: 663.2 | D9: 130.9 | E9: 163400.1 | F9: 5146.7 | G9: 20835.2 | H9: 56436.4 | I9: 85122.8 | L9: 1300.1 | M9: 19818.1 | N9: 16541.6 | O9: 3718.4 | P9: 18518 | Q9: 13532.1 | R9: 4808.5
A10: 4- 6. | B10: 164003.9 | C10: 698 | D10: 123.4 | E10: 163036.3 | F10: 4937.9 | G10: 21100.4 | H10: 55984.2 | I10: 85458 | L10: 693.7 | M10: 20099.1 | N10: 16940.5 | O10: 3517 | P10: 19405.4 | Q10: 14366.5 | R10: 4724.6
A11: 7- 9. | B11: 165557.5 | C11: 733.5 | D11: 115.3 | E11: 164539.3 | F11: 4900.1 | G11: 21089 | H11: 56052.2 | I11: 87265.6 | L11: 1704.1 | M11: 19895.4 | N11: 16827.5 | O11: 3390.5 | P11: 18191.3 | Q11: 13387.8 | R11: 4563.9
A12: 10-12. | B12: 166481.3 | C12: 608 | D12: 119.9 | E12: 165606.8 | F12: 4923.5 | G12: 21398.6 | H12: 56729.3 | I12: 87251.9 | L12: 3168.6 | M12: 21244.1 | N12: 18073.3 | O12: 3458 | P12: 18075.5 | Q12: 13322.8 | R12: 4500.7
A13: 1981/ 1- 3. | B13: 166230.2 | C13: 629 | D13: 120.1 | E13: 165332.6 | F13: 4889.6 | G13: 20496.2 | H13: 56731.8 | I13: 88110.9 | L13: 3477.8 | M13: 21863.2 | N13: 18669.5 | O13: 3451.2 | P13: 18385.4 | Q13: 13403 | R13: 4828.5
A14: 4- 6. | B14: 167358.8 | C14: 575.3 | D14: 120.9 | E14: 166520.2 | F14: 5169.7 | G14: 20213.5 | H14: 56840.9 | I14: 89021.1 | L14: 3941.5 | M14: 22919.7 | N14: 19469 | O14: 3776.8 | P14: 18978.3 | Q14: 13731.1 | R14: 5160.2
A15: 7- 9. | B15: 168444.5 | C15: 547.4 | D15: 148.6 | E15: 167662.4 | F15: 5335.1 | G15: 20339.4 | H15: 57121.1 | I15: 89455.6 | L15: 4554 | M15: 23568.1 | N15: 20029.7 | O15: 3868.3 | P15: 19014.1 | Q15: 13585.9 | R15: 5459.3
A16: 10-12. | B16: 169824.3 | C16: 534.6 | D16: 122.4 | E16: 169029.1 | F16: 5233.1 | G16: 20831.4 | H16: 57826.5 | I16: 89855.3 | L16: 4123.6 | M16: 23478.1 | N16: 19973.6 | O16: 3822 | P16: 19354.6 | Q16: 13805.9 | R16: 5596.4
A17: 1982/ 1- 3. | B17: 172416.5 | C17: 475.9 | D17: 133 | E17: 171698.3 | F17: 5337.8 | G17: 21664 | H17: 57822.2 | I17: 91768.2 | L17: 3824.9 | M17: 23493.6 | N17: 19920.2 | O17: 3924.6 | P17: 19668.7 | Q17: 13986.8 | R17: 5775.2
A18: 4- 6. | B18: 175600 | C18: 445.4 | D18: 151.9 | E18: 174932.2 | F18: 5589 | G18: 21740.2 | H18: 59293.8 | I18: 93051.5 | L18: 4443.6 | M18: 23268.1 | N18: 19757.3 | O18: 3844.3 | P18: 18824.5 | Q18: 13368.1 | R18: 5560
A19: 7- 9. | B19: 175110.7 | C19: 426.4 | D19: 145.8 | E19: 174461.8 | F19: 5486.3 | G19: 21866.7 | H19: 59241.5 | I19: 92657.2 | L19: 4681.8 | M19: 23302.5 | N19: 19796.8 | O19: 3834.6 | P19: 18620.7 | Q19: 13081.3 | R19: 5752.3
A20: 10-12. | B20: 179828.1 | C20: 430.9 | D20: 163.6 | E20: 179185.2 | F20: 6159.5 | G20: 21859.3 | H20: 59757 | I20: 95997.1 | L20: 5034.7 | M20: 23157.6 | N20: 19659.4 | O20: 3832.2 | P20: 18122.9 | Q20: 12668 | R20: 5711.6
... A135: 7- 9. | B135: 302118.6 | C135: 1623.2 | D135: 737.2 | E135: 301039.1 | F135: 57368.3 | G135: 21414.8 | H135: 69777.4 | I135: 163276.7 | L135: 24646.5 | M135: 85965.7 | N135: 77299.2 | O135: 8759.2 | P135: 61319.2 | Q135: 52089.1 | R135: 9576.1
A136: ＊年率で表示している。
A139: avg | B139: =+AVERAGE(B9:B135) -> 252273.82 | C139: =+AVERAGE(C9:C135) -> 2041.1402 | D139: =+AVERAGE(D9:D135) -> 415.48583 | E139: =+AVERAGE(E9:E135) -> 250220.26 | F139: =+AVERAGE(F9:F135) -> 22165.157 | G139: =+AVERAGE(G9:G135) -> 24611.282 | H139: =+AVERAGE(H9:H135) -> 69798.688 | I139: =+AVERAGE(I9:I135) -> 135865.37 | L139: =+AVERAGE(L9:L135) -> 8983.3441

Sheet gaku-mk1131
A1: 名目季節調整系列 | P1: <参考> | Y1: (単位:10億円)
A2: Nominal Gross Domestic Product (seasonally adjusted series) | P2: <cf> | Y2: (billion yen)
B3: 国内総生産(支出側) | C3: 民間最終消費支出 | F3: 民間住宅 | G3: 民間企業設備 | H3: 民間在庫品増加 | I3: 政府最終消費支出 | J3: 公的固定資本形成 | K3: 公的在庫品増加 | L3: 財貨・サービス | P3: 海外からの所得 | S3: 国民総所得 | U3: 国内需要 | V3: 民間需要 | W3: 公的需要 | Y3: 総固定資本形成
D4: 家計最終消費支出 | L4: 純輸出 | M4: 輸出 | N4: 輸入 | P4: 純受取 | Q4: 受取 | R4: 支払
E5: 除く持ち家の帰属家賃
B6: GDP(expenditure approach) | C6: PrivateConsumption | D6: Consumption ofHouseholds | E6: Excludingimputed rent | F6: PrivateResidentialInvestment | G6: Private Non-Resi.Investment | H6: PrivateInventory | I6: GovernmentConsumption | J6: PublicInvestment | K6: PublicInventory | L6: Goods & Services | P6: Income from /to the rest of the world | S6: GNI | U6: Domestic Demand | V6: PrivateDemand | W6: PublicDemand | Y6: Gross fixed capitalformation
L7: Net Exports | M7: Exports | N7: Imports | P7: Net | Q7: Receipt | R7: Payment
A8: 1980/ 1- 3. | B8: 233029.6 | C8: 128052.3 | D8: 126227.9 | E8: 112301.7 | F8: 15583.7 | G8: 37613.5 | H8: 195.3 | I8: 32919.4 | J8: 22358 | K8: -314.4 | L8: -3378.3 | M8: 32405.7 | N8: 35783.9 | P8: -61 | Q8: 2738.4 | R8: 2799.5 | S8: 232968.6 | U8: 236407.9 | V8: 181444.8 | W8: 54963.1 | Y8: 75555.2
A9: 4- 6. | B9: 237769.2 | C9: 130597.2 | D9: 128731.1 | E9: 114369.3 | F9: 15962 | G9: 38771.5 | H9: 1210.8 | I9: 33600.2 | J9: 22235 | K9: -240.1 | L9: -4367.3 | M9: 32842.5 | N9: 37209.8 | P9: -150.3 | Q9: 2611 | R9: 2761.3 | S9: 237618.9 | U9: 242136.5 | V9: 186541.4 | W9: 55595.1 | Y9: 76968.5
A10: 7- 9. | B10: 245482.1 | C10: 133751.5 | D10: 131821.4 | E10: 117166.8 | F10: 15226.9 | G10: 39100.1 | H10: 2439.1 | I10: 34420.7 | J10: 22425 | K10: -79.3 | L10: -1801.9 | M10: 31961.2 | N10: 33763.1 | P10: -13.7 | Q10: 2557.4 | R10: 2571.2 | S10: 245468.3 | U10: 247284 | V10: 190517.6 | W10: 56766.4 | Y10: 76752
A11: 10-12. | B11: 253512.7 | C11: 135908.7 | D11: 133934.7 | E11: 118987.3 | F11: 14633.4 | G11: 39978.5 | H11: 2761 | I11: 36038.8 | J11: 23886.4 | K11: -250.2 | L11: 556.2 | M11: 34029.9 | N11: 33473.7 | P11: 43 | Q11: 2616.1 | R11: 2573.1 | S11: 253555.7 | U11: 252956.6 | V11: 193281.6 | W11: 59675 | Y11: 78498.3
A12: 1981/ 1- 3. | B12: 255922.4 | C12: 137581.4 | D12: 135583.3 | E12: 120303.3 | F12: 14649.3 | G12: 40811.6 | H12: 1676.9 | I12: 35605.1 | J12: 24660.5 | K12: -257 | L12: 1194.6 | M12: 35309.6 | N12: 34115 | P12: -520 | Q12: 2972.5 | R12: 3492.5 | S12: 255402.4 | U12: 254727.8 | V12: 194719.2 | W12: 60008.6 | Y12: 80121.4
A13: 4- 6. | B13: 260361.1 | C13: 139382.7 | D13: 137352.8 | E13: 121750.6 | F13: 14996.9 | G13: 40684.7 | H13: 4086.1 | I13: 36368.7 | J13: 23853.5 | K13: -292.7 | L13: 1281.3 | M13: 37673.8 | N13: 36392.5 | P13: -484 | Q13: 3432 | R13: 3916 | S13: 259877.1 | U13: 259079.8 | V13: 199150.4 | W13: 59929.5 | Y13: 79535.1
A14: 7- 9. | B14: 261195.9 | C14: 141508.4 | D14: 139438.9 | E14: 123528 | F14: 15093.6 | G14: 41092.9 | H14: -428.1 | I14: 36998 | J14: 24359.2 | K14: -307.3 | L14: 2879.2 | M14: 39338.2 | N14: 36458.9 | P14: -561.1 | Q14: 3876.3 | R14: 4437.4 | S14: 260634.8 | U14: 258316.6 | V14: 197266.7 | W14: 61049.9 | Y14: 80545.6
A15: 10-12. | B15: 265677.1 | C15: 143903.8 | D15: 141814 | E15: 125605.7 | F15: 14582.1 | G15: 41827.3 | H15: 891.2 | I15: 38339.7 | J15: 24092.2 | K15: -65.8 | L15: 2106.7 | M15: 38834.4 | N15: 36727.7 | P15: -199.9 | Q15: 4255.1 | R15: 4455 | S15: 265477.2 | U15: 263570.4 | V15: 201204.3 | W15: 62366.1 | Y15: 80501.6
A16: 1982/ 1- 3. | B16: 271140 | C16: 147113.1 | D16: 145022.4 | E16: 128519.3 | F16: 14461.4 | G16: 41721 | H16: 3617.9 | I16: 38694.3 | J16: 23907.4 | K16: -238.8 | L16: 1863.7 | M16: 39909.6 | N16: 38045.9 | P16: -125.4 | Q16: 4467.1 | R16: 4592.5 | S16: 271014.6 | U16: 269276.3 | V16: 206913.3 | W16: 62362.9 | Y16: 80089.9
A17: 4- 6. | B17: 272602.8 | C17: 150022.9 | D17: 147947.7 | E17: 131146.4 | F17: 14679.6 | G17: 42343.7 | H17: 661.6 | I17: 39111.4 | J17: 23934.8 | K17: -165.6 | L17: 2014.4 | M17: 39106.5 | N17: 37092 | P17: -180.1 | Q17: 4754.2 | R17: 4934.4 | S17: 272422.6 | U17: 270588.3 | V17: 207707.8 | W17: 62880.6 | Y17: 80958.1
A18: 7- 9. | B18: 274408.1 | C18: 150768.2 | D18: 148700.2 | E18: 131616.9 | F18: 15097.2 | G18: 42485.3 | H18: 1129.9 | I18: 39609.8 | J18: 23901.3 | K18: -504.3 | L18: 1920.6 | M18: 39212.3 | N18: 37291.7 | P18: 164.4 | Q18: 4825.8 | R18: 4661.4 | S18: 274572.5 | U18: 272487.4 | V18: 209480.7 | W18: 63006.8 | Y18: 81483.8
A19: 10-12. | B19: 277819.1 | C19: 155641.4 | D19: 153540.7 | E19: 136190.9 | F19: 15543.9 | G19: 41850.9 | H19: 459 | I19: 39257.6 | J19: 23848.7 | K19: -422 | L19: 1639.6 | M19: 38591.4 | N19: 36951.8 | P19: 605.2 | Q19: 4993 | R19: 4387.7 | S19: 278424.3 | U19: 276179.4 | V19: 213495.2 | W19: 62684.3 | Y19: 81243.4
... A134: 7- 9. | B134: 469552.2 | C134: 278005.8 | D134: 271665.8 | E134: 225085.6 | F134: 13967.6 | G134: 65575.3 | H134: -499 | I134: 98025 | J134: 19015.5 | K134: 263.6 | L134: -4801.6 | M134: 72755.7 | N134: 77557.3 | P134: 15002.9 | Q134: 20851.7 | R134: 5848.9 | S134: 484555.1 | U134: 474353.8 | V134: 357049.7 | W134: 117304.2 | Y134: 98558.4
A135: ＊年率で表示している。
A136: ＊総固定資本形成＝民間住宅＋民間企業設備＋公的固定資本形成
A139: avg | B139: =+AVERAGE(B9:B135) -> 438515.47 | C139: =+AVERAGE(C9:C135) -> 244662.99 | D139: =+AVERAGE(D9:D135) -> 240062.42 | E139: =+AVERAGE(E9:E135) -> 205665.78 | F139: =+AVERAGE(F9:F135) -> 19082.314 | G139: =+AVERAGE(G9:G135) -> 68070.467 | H139: =+AVERAGE(H9:H135) -> 957.63968 | I139: =+AVERAGE(I9:I135) -> 70746.279 | ... L139: =+AVERAGE(L9:L135) -> 6392.181 | W139: =+AVERAGE(W9:W135) -> 99349.878
C140: =+C139/$C$139 -> 1 | F140: =+F139/$C$139 -> 0.077994282 | I140: =+I139/$C$139 -> 0.28915807 | J140: =+J139/$C$139 -> 0.11643713 | K140: =+K139/$C$139 -> 0.00047306407 | W140: =+W139/$C$139 -> 0.40606827
G141: =+G139/$G$139 -> 1 | H141: =+H139/$G$139 -> 0.014068358 | L141: =+L139/$G$139 -> 0.093905348

Sheet gaku-jk1131
A1: 実質季節調整系列 | Q1: <参考> | AB1: (単位:2000暦年連鎖価格、10億円)
A2: Real Gross Domestic Product (seasonally adjusted series) | Q2: <cf> | AB2: (Billions of chained (2000) yen)
B3: 国内総生産(支出側) | C3: 民間最終消費支出 | F3: 民間住宅 | G3: 民間企業設備 | H3: 民間在庫品増加 | I3: 政府最終消費支出 | J3: 公的固定資本形成 | K3: 公的在庫品増加 | L3: 財貨・サービス | O3: 開差 | Q3: 交易利得 | R3: 国内総所得 | S3: 海外からの所得 | V3: 国民総所得 | X3: 国内需要 | Y3: 民間需要 | Z3: 公的需要 | AB3: 総固定資本形成
D4: 家計最終消費支出 | L4: 純輸出 | M4: 輸出 | N4: 輸入 | S4: 純受取 | T4: 受取 | U4: 支払
E5: 除く持ち家の帰属家賃
B6: GDP(expenditure approach) | C6: PrivateConsumption | D6: Consumption ofHouseholds | E6: Excludingimputed rent | F6: PrivateResidentialInvestment | G6: Private Non-Resi.Investment | H6: PrivateInventory | I6: GovernmentConsumption | J6: PublicInvestment | K6: PublicInventory | L6: Goods & Services | O6: Residual | Q6: Tradinggains/losses | R6: GDI | S6: Income from /to the rest of the world | V6: GNI | X6: DomesticDemand | Y6: PrivateDemand | Z6: PublicDemand | AB6: Gross fixed capitalformation
L7: Net Exports | M7: Exports | N7: Imports | S7: Net | T7: Receipt | U7: Payment
A8: 1980/ 1- 3. | B8: 280828.2 | C8: 166750.6 | D8: 164321.7 | E8: 139484.8 | F8: 19358.5 | G8: 34479.1 | H8: 568.9 | I8: 42623.1 | J8: 25651.5 | K8: -2196.8 | L8: 1300.1 | M8: 19818.1 | N8: 18518 | O8: -7706.8 | Q8: -3199.4 | R8: 277628.8 | S8: -70.3 | T8: 3305.6 | U8: 3375.9 | V8: 277558.5 | X8: 285025.8 | Y8: 218515 | Z8: 66976 | AB8: 77308.7
A9: 4- 6. | B9: 279347.8 | C9: 166430.2 | D9: 164003.9 | E9: 138851.7 | F9: 19104.4 | G9: 34907.1 | H9: 842.6 | I9: 42929.9 | J9: 24673.4 | K9: -1964.7 | L9: 693.7 | M9: 20099.1 | N9: 19405.4 | O9: -8268.9 | Q9: -3156.6 | R9: 276191.2 | S9: -180.1 | T9: 3075.8 | U9: 3255.9 | V9: 276011.1 | X9: 284979.4 | Y9: 219074.4 | Z9: 66353.8 | AB9: 76696.1
A10: 7- 9. | B10: 285605 | C10: 168019.5 | D10: 165557.5 | E10: 140164.1 | F10: 18488.6 | G10: 34904.7 | H10: 2277 | I10: 43416.2 | J10: 24607.9 | K10: -2228.9 | L10: 1704.1 | M10: 19895.4 | N10: 18191.3 | O10: -5584.2 | Q10: -2748.3 | R10: 282856.6 | S10: -16.7 | T10: 2980.4 | U10: 2997.2 | V10: 282839.9 | X10: 288941.4 | Y10: 222794.8 | Z10: 66583.3 | AB10: 76129.4
A11: 10-12. | B11: 291675.5 | C11: 168970.5 | D11: 166481.3 | E11: 140885.9 | F11: 18007.2 | G11: 35675.3 | H11: 2216.1 | I11: 44014.2 | J11: 26232.4 | K11: -2749.8 | L11: 3168.6 | M11: 21244.1 | N11: 18075.5 | O11: -3858.9 | Q11: -2844.7 | R11: 288830.9 | S11: 47.3 | T11: 3022.5 | U11: 2975.2 | V11: 288878.2 | X11: 292201.6 | Y11: 224088.3 | Z11: 68587.7 | AB11: 78053.1
A12: 1981/ 1- 3. | B12: 293463.7 | C12: 168737.9 | D12: 166230.2 | E12: 140489.3 | F12: 18094.2 | G12: 36179.8 | H12: 1737.1 | I12: 44521.7 | J12: 26990.6 | K12: -1982 | L12: 3477.8 | M12: 21863.2 | N12: 18385.4 | O12: -4293.4 | Q12: -2785.2 | R12: 290678.5 | S12: -596.7 | T12: 3419.6 | U12: 4016.3 | V12: 290081.8 | X12: 293504 | Y12: 223656.4 | Z12: 70362.7 | AB12: 79367.7
A13: 4- 6. | B13: 297055 | C13: 169896.1 | D13: 167358.8 | E13: 141412.8 | F13: 18419.6 | G13: 36176.5 | H13: 2574.6 | I13: 45458.2 | J13: 26030 | K13: -1992.9 | L13: 3941.5 | M13: 22919.7 | N13: 18978.3 | O13: -3448.6 | Q13: -3216.7 | R13: 293838.4 | S13: -556.3 | T13: 3932.8 | U13: 4489.2 | V13: 293282.1 | X13: 296411.2 | Y13: 226699.1 | Z13: 70210 | AB13: 78766.7
A14: 7- 9. | B14: 296394.3 | C14: 171014.6 | D14: 168444.5 | E14: 142302.8 | F14: 18538.7 | G14: 36687.1 | H14: 276.1 | I14: 45951.7 | J14: 26397.4 | K14: -1839.5 | L14: 4554 | M14: 23568.1 | N14: 19014.1 | O14: -5185.8 | Q14: -2936.5 | R14: 293457.8 | S14: -641.4 | T14: 4413.9 | U14: 5055.3 | V14: 292816.5 | X14: 294594 | Y14: 223953.4 | Z14: 71172.7 | AB14: 79763
A15: 10-12. | B15: 298557.8 | C15: 172400.5 | D15: 169824.3 | E15: 143470 | F15: 17726.3 | G15: 37260.6 | H15: 1027.5 | I15: 46590.1 | J15: 26008.6 | K15: -1596.2 | L15: 4123.6 | M15: 23478.1 | N15: 19354.6 | O15: -4983.1 | Q15: -2929.4 | R15: 295628.4 | S15: -228.5 | T15: 4806.8 | U15: 5035.3 | V15: 295399.9 | X15: 297693.3 | Y15: 226708.8 | Z15: 71512.2 | AB15: 79385
A16: 1982/ 1- 3. | B16: 303133.2 | C16: 174972.9 | D16: 172416.5 | E16: 145790 | F16: 17460.6 | G16: 36887.5 | H16: 2909.9 | I16: 47083.6 | J16: 25703.7 | K16: -1729.4 | L16: 3824.9 | M16: 23493.6 | N16: 19668.7 | O16: -3980.5 | Q16: -2793 | R16: 300340.1 | S16: -141 | T16: 5024.4 | U16: 5165.4 | V16: 300199.2 | X16: 302942.2 | Y16: 231864.8 | Z16: 71568.5 | AB16: 78479
A17: 4- 6. | B17: 305214.4 | C17: 178113.1 | D17: 175600 | E17: 148681.7 | F17: 17728.4 | G17: 37765.3 | H17: 672.2 | I17: 47373.9 | J17: 25769.3 | K17: -1532.8 | L17: 4443.6 | M17: 23268.1 | N17: 18824.5 | O17: -5118.7 | Q17: -3330.8 | R17: 301883.5 | S17: -202.9 | T17: 5338.3 | U17: 5541.1 | V17: 301680.6 | X17: 303624.4 | Y17: 232086.7 | Z17: 72042.8 | AB17: 79731.5
A18: 7- 9. | B18: 306548.2 | C18: 177590.4 | D18: 175110.7 | E18: 148063.1 | F18: 18133.2 | G18: 37735.6 | H18: 1180.2 | I18: 47864.3 | J18: 25581.6 | K18: -1915.7 | L18: 4681.8 | M18: 23302.5 | N18: 18620.7 | O18: -4303.1 | Q18: -3629.3 | R18: 302918.9 | S18: 180 | T18: 5379.1 | U18: 5199.1 | V18: 303099 | X18: 304449.2 | Y18: 232889 | Z18: 72059.7 | AB18: 79855.4
A19: 10-12. | B19: 310808 | C19: 182334 | D19: 179828.1 | E19: 152401.1 | F19: 18597.5 | G19: 37055.1 | H19: 802.1 | I19: 48340.5 | J19: 25442.4 | K19: -2211 | L19: 5034.7 | M19: 23157.6 | N19: 18122.9 | O19: -4587.4 | Q19: -4138.7 | R19: 306669.3 | S19: 674.7 | T19: 5572.6 | U19: 4897.9 | V19: 307344.1 | X19: 307907.1 | Y19: 236214.2 | Z19: 72170 | AB19: 79348.5
... A134: 7- 9. | B134: 542503.9 | C134: 308997.9 | D134: 302118.6 | E134: 250367.9 | F134: 13315.3 | G134: 73474.3 | H134: -287.7 | I134: 105080.7 | J134: 18443.1 | K134: 314.7 | L134: 24646.5 | M134: 85965.7 | N134: 61319.2 | O134: -1481 | Q134: -29351.4 | R134: 513152.5 | S134: 16348.9 | T134: 22705.1 | U134: 6356.2 | V134: 529501.4 | X134: 518013 | Y134: 394281.1 | Z134: 123569.6 | AB134: 104594.9
A135: ＊年率で表示している。
A136: ＊開差＝国内総生産(支出側)－国内総生産(支出側)の内訳項目計

Sheet kshotoku1722
A1: Ⅲ.雇用者報酬
A2: Compensation of Employees | S2: (単位:10億円、%)
A3: 名 目 | K3: 実 質(2011暦年連鎖価格)
A4: Nominal | K4: Real (Chained (2011) Yen)
C5: 四半期・原系列 | E5: 四半期・季節調整系列 | G5: 年度 、 暦年 | M5: 四半期・原系列 | O5: 四半期・季節調整系列 | Q5: 年度 、 暦年
C6: Original Series | E6: Seasonally Adjusted Series | G6: Fiscal Year , Calendar Year | M6: Original Series | O6: Seasonally Adjusted Series | Q6: Fiscal Year , Calendar Year
C7: 実数 | D7: (**) | E7: 実数 | F7: (***) | H7: 実数 | I7: (**) | M7: 実数 | N7: (**) | O7: 実数 | P7: (***) | R7: 実数 | S7: (**)
C8: Billion Yen | D8: (**) | E8: Billion Yen | F8: (***) | H8: Billion Yen | I8: (**) | M8: Billion Yen | N8: (**) | O8: Billion Yen | P8: (***) | R8: Billion Yen | S8: (**)
A9: 1994/ | B9: 1-3. | C9: 53407.2 | E9: 257247.3 | K9: 1994/ | L9: 1-3. | M9: 47687.9 | O9: 228441.1
B10: 4-6. | C10: 66121.2 | E10: 263611.9 | F10: 2.5 | L10: 4-6. | M10: 58404.7 | O10: 233595.2 | P10: 2.3
B11: 7-9. | C11: 63292.8 | E11: 259229.4 | F11: -1.7 | L11: 7-9. | M11: 56364.7 | O11: 230373.1 | P11: -1.4
B12: 10-12. | C12: 78268.5 | E12: 263214.7 | F12: 1.5 | L12: 10-12. | M12: 69264 | O12: 233918.5 | P12: 1.5
A13: 1995/ | B13: 1-3. | C13: 54613.6 | D13: 2.3 | E13: 262822.7 | F13: -0.1 | K13: 1995/ | L13: 1-3. | M13: 48929.7 | N13: 2.6 | O13: 234197.7 | P13: 0.1
B14: 4-6. | C14: 66251.3 | D14: 0.2 | E14: 264163.8 | F14: 0.5 | L14: 4-6. | M14: 59095.6 | N14: 1.2 | O14: 236474.2 | P14: 1
B15: 7-9. | C15: 64975.6 | D15: 2.7 | E15: 265998 | F15: 0.7 | L15: 7-9. | M15: 58397.6 | N15: 3.6 | O15: 238589 | P15: 0.9
B16: 10-12. | C16: 79668.1 | D16: 1.8 | E16: 268509.3 | F16: 0.9 | L16: 10-12. | M16: 71295 | N16: 2.9 | O16: 241245.8 | P16: 1.1
A17: 1996/ | B17: 1-3. | C17: 55704.7 | D17: 2 | E17: 267305.4 | F17: -0.4 | K17: 1996/ | L17: 1-3. | M17: 50398.9 | N17: 3 | O17: 240523 | P17: -0.3
B18: 4-6. | C18: 67411.9 | D18: 1.8 | E18: 268747.4 | F18: 0.5 | L18: 4-6. | M18: 60350.9 | N18: 2.1 | O18: 241383.4 | P18: 0.4
B19: 7-9. | C19: 66353.5 | D19: 2.1 | E19: 271624.3 | F19: 1.1 | L19: 7-9. | M19: 59818.7 | N19: 2.4 | O19: 244429.8 | P19: 1.3
B20: 10-12. | C20: 80720.9 | D20: 1.3 | E20: 272798.8 | F20: 0.4 | L20: 10-12. | M20: 72333.8 | N20: 1.5 | O20: 245517.7 | P20: 0.4
A21: 1997/ | B21: 1-3. | C21: 57974.1 | D21: 4.1 | E21: 277130.1 | F21: 1.6 | K21: 1997/ | L21: 1-3. | M21: 52494.4 | N21: 4.2 | O21: 249487 | P21: 1.6
B22: 4-6. | C22: 69814.1 | D22: 3.6 | E22: 278190.1 | F22: 0.4 | L22: 4-6. | M22: 61620.9 | N22: 2.1 | O22: 246372.8 | P22: -1.2
B23: 7-9. | C23: 68188.3 | D23: 2.8 | E23: 279329.9 | F23: 0.4 | L23: 7-9. | M23: 60560.9 | N23: 1.2 | O23: 247512.1 | P23: 0.5
B24: 10-12. | C24: 82266.2 | D24: 1.9 | E24: 278817.4 | F24: -0.2 | L24: 10-12. | M24: 72742.8 | N24: 0.6 | O24: 247765.1 | P24: 0.1
A25: 1998/ | B25: 1-3. | C25: 58280 | D25: 0.5 | E25: 277440.5 | F25: -0.5 | K25: 1998/ | L25: 1-3. | M25: 52199.3 | N25: -0.6 | O25: 247048.3 | P25: -0.3
B26: 4-6. | C26: 69257.1 | D26: -0.8 | E26: 275589.9 | F26: -0.7 | L26: 4-6. | M26: 61498.2 | N26: -0.2 | O26: 245553.1 | P26: -0.6
B27: 7-9. | C27: 66477 | D27: -2.5 | E27: 272725.1 | F27: -1 | L27: 7-9. | M27: 59576.6 | N27: -1.6 | O27: 243739.8 | P27: -0.7
B28: 10-12. | C28: 80064.6 | D28: -2.7 | E28: 272228.3 | F28: -0.2 | L28: 10-12. | M28: 70943.1 | N28: -2.5 | O28: 242559.1 | P28: -0.5
A29: 1999/ | B29: 1-3. | C29: 57090.2 | D29: -2 | E29: 270516.2 | F29: -0.6 | K29: 1999/ | L29: 1-3. | M29: 51425.6 | N29: -1.5 | O29: 242253.3 | P29: -0.1
B30: 4-6. | C30: 67592.5 | D30: -2.4 | E30: 268651 | F30: -0.7 | L30: 4-6. | M30: 60346.9 | N30: -1.9 | O30: 240690.3 | P30: -0.6
B31: 7-9. | C31: 65404.6 | D31: -1.6 | E31: 268720.7 | F31: 0 | L31: 7-9. | M31: 58830.5 | N31: -1.3 | O31: 240983.2 | P31: 0.1
B32: 10-12. | C32: 78719 | D32: -1.7 | E32: 268309.1 | F32: -0.2 | L32: 10-12. | M32: 70564.8 | N32: -0.5 | O32: 241792.9 | P32: 0.3
A33: 2000/ | B33: 1-3. | C33: 57022.8 | D33: -0.1 | E33: 269444 | F33: 0.4 | K33: 2000/ | L33: 1-3. | M33: 51798.6 | N33: 0.7 | O33: 243322.9 | P33: 0.6
B34: 4-6. | C34: 67761.1 | D34: 0.2 | E34: 268733.7 | F34: -0.3 | L34: 4-6. | M34: 61156.9 | N34: 1.3 | O34: 243389.5 | P34: 0
B35: 7-9. | C35: 65487.5 | D35: 0.1 | E35: 269580.7 | F35: 0.3 | L35: 7-9. | M35: 59633.1 | N35: 1.4 | O35: 244889.3 | P35: 0.6
B36: 10-12. | C36: 79207.6 | D36: 0.6 | E36: 270499.4 | F36: 0.3 | L36: 10-12. | M36: 71924.2 | N36: 1.9 | O36: 246823.8 | P36: 0.8
A37: 2001/ | B37: 1-3. | C37: 57880.1 | D37: 1.5 | E37: 272914.6 | F37: 0.9 | K37: 2001/ | L37: 1-3. | M37: 53071.3 | N37: 2.5 | O37: 248692.1 | P37: 0.8
B38: 4-6. | C38: 67971.5 | D38: 0.3 | E38: 268430.5 | F38: -1.6 | L38: 4-6. | M38: 62208.1 | N38: 1.7 | O38: 246527.6 | P38: -0.9
B39: 7-9. | C39: 64342.6 | D39: -1.7 | E39: 265650.7 | F39: -1 | L39: 7-9. | M39: 59468.3 | N39: -0.3 | O39: 245143.9 | P39: -0.6
B40: 10-12. | C40: 76048.4 | D40: -4 | E40: 260297.7 | F40: -2 | L40: 10-12. | M40: 70329.4 | N40: -2.2 | O40: 241786 | P40: -1.4
...

Sheet kgaku-mk1722
A1: 名目季節調整系列 | Y1: (単位:10億円)
A2: Nominal, Seasonally Adjusted Series | Y2: (Billion Yen)
B3: 家計最終消費支出（再掲） | K3: 形態別総固定資本形成 | P3: 総資本形成 | S3: 財貨・サービス
C4: 居住者家計の海外での直接購入 | D4: （控除）非居住者家計の国内での直接購入 | E4: 国内家計最終消費支出 | K4: 住宅 | L4: その他の建物・構築物 | M4: 輸送用機械 | N4: その他の機械設備等 | O4: 知的財産生産物 | Q4: うち在庫変動 | S4: 純輸出（再掲） | T4: 輸出（再掲） | W4: 輸入（再掲）
F5: 耐久財 | G5: 半耐久財 | H5: 非耐久財 | I5: サービス | U5: 財貨 | V5: サービス（含む非居住者家計の国内での直接購入） | X5: 財貨 | Y5: サービス（含む居住者家計の海外での直接購入）
B6: Consumptionof Households(id, at §Ｉ) | C6: DirectPurchasesAbroad byResidentHouseholds | D6: (Less) DirectPurchases inthe DomesticMarket byNon-ResidentHouseholds | E6: Domestic FinalConsumptionExpenditure ofHouseholds | F6: DurableGoods | G6: Semi-DurableGoods | H6: Non-DurableGoods | I6: Services | K6: Gross Fixed Capital Formation by Type | P6: Gross CapitalFormation | Q6: Of WhichChange inInventories | S6: Goods & Services
K7: ResidentialInvestment | L7: Other Buildingsand Structures | M7: TransportEquipment | N7: OtherMachinery andEquipment etc. | O7: IntellectualPropertyProducts | S7: Net Exports(id, at §Ｉ) | T7: Exports(id, at §Ｉ) | W7: Imports(id, at §Ｉ)
U8: Goods | V8: Services（Including DirectPurchases in theDomestic Marketby Non-ResidentHouseholds) | X8: Goods | Y8: Services（Including DirectPurchasesAbroad byResidentHouseholds)
A9: 1994/ 1- 3. | B9: 261777.1 | C9: 2600.1 | D9: 269.7 | E9: 259446.7 | F9: 21744.5 | G9: 22820.1 | H9: 74540.1 | I9: 140341.9 | K9: 26371.6 | L9: 58706.7 | M9: 7102.3 | N9: 37529.7 | O9: 18016.4 | P9: 150031 | Q9: 2735 | S9: 11000.2 | T9: 44990.7 | U9: 38972.8 | V9: 6017.9 | W9: 33990.4 | X9: 22993.1 | Y9: 10997.4
A10: 4- 6. | B10: 262262.7 | C10: 2650 | D10: 269.2 | E10: 259881.8 | F10: 22109.8 | G10: 23198.7 | H10: 74247.1 | I10: 140326.3 | K10: 27409 | L10: 58374.5 | M10: 6996.6 | N10: 38205.5 | O10: 17929.7 | P10: 146505.6 | Q10: -2238.3 | S10: 9964.8 | T10: 45487.7 | U10: 39475.8 | V10: 6011.8 | W10: 35522.9 | X10: 24178.5 | Y10: 11344.4
A11: 7- 9. | B11: 265821.2 | C11: 2531.7 | D11: 225.2 | E11: 263514.6 | F11: 23555.5 | G11: 22717.1 | H11: 74634.6 | I11: 142607.4 | K11: 29808.7 | L11: 55322.9 | M11: 7205.7 | N11: 38282.1 | O11: 18105.7 | P11: 149428.9 | Q11: 717.7 | S11: 8579.2 | T11: 45045.2 | U11: 39351.2 | V11: 5694.1 | W11: 36466.1 | X11: 25278 | Y11: 11188
A12: 10-12. | B12: 265264.9 | C12: 2442.2 | D12: 220.6 | E12: 263043.2 | F12: 23357.6 | G12: 22560.2 | H12: 74318.1 | I12: 142807.4 | K12: 28502.8 | L12: 54175.2 | M12: 7149 | N12: 39303.7 | O12: 18254.1 | P12: 146910.1 | Q12: -704.2 | S12: 8606.2 | T12: 45098.2 | U12: 39515.4 | V12: 5582.8 | W12: 36492 | X12: 25722 | Y12: 10769.9
A13: 1995/ 1- 3. | B13: 266488.5 | C13: 2496.9 | D13: 187.5 | E13: 264179.2 | F13: 24193 | G13: 22939.4 | H13: 74824.9 | I13: 142221.9 | K13: 27512.1 | L13: 54645.8 | M13: 7337.2 | N13: 39379.5 | O13: 17822.9 | P13: 148228.5 | Q13: 1725.6 | S13: 7756.7 | T13: 45059 | U13: 39581.8 | V13: 5477.2 | W13: 37302.3 | X13: 26005.1 | Y13: 11297.2
A14: 4- 6. | B14: 268686.8 | C14: 2546.7 | D14: 175.6 | E14: 266315.7 | F14: 25369.6 | G14: 23029.5 | H14: 75239.9 | I14: 142676.6 | K14: 26755 | L14: 54788.9 | M14: 7707.7 | N14: 42279.7 | O14: 18529.6 | P14: 151189.8 | Q14: 1374.6 | S14: 7394.1 | T14: 44066.3 | U14: 39035.1 | V14: 5031.2 | W14: 36672.2 | X14: 26116.1 | Y14: 10556.1
A15: 7- 9. | B15: 270195.9 | C15: 2896.2 | D15: 215.8 | E15: 267515.5 | F15: 24886.8 | G15: 23577.2 | H15: 75369.5 | I15: 143682 | K15: 26111.7 | L15: 58851.2 | M15: 7230 | N15: 42961 | O15: 18678.9 | P15: 156049.9 | Q15: 2266 | S15: 6271.9 | T15: 46797.9 | U15: 40726.5 | V15: 6071.4 | W15: 40526 | X15: 28598.5 | Y15: 11927.6
A16: 10-12. | B16: 271775.3 | C16: 3096.7 | D16: 244.3 | E16: 268922.8 | F16: 24521 | G16: 23602.2 | H16: 75459.5 | I16: 145340.1 | K16: 26617.6 | L16: 58360.7 | M16: 7044.5 | N16: 43891 | O16: 19135.3 | P16: 156852.2 | Q16: 1396 | S16: 4476.6 | T16: 47873.8 | U16: 41511.7 | V16: 6362.1 | W16: 43397.2 | X16: 30571.9 | Y16: 12825.3
A17: 1996/ 1- 3. | B17: 272896.5 | C17: 3225.2 | D17: 284.3 | E17: 269955.5 | F17: 24714.7 | G17: 22719.2 | H17: 74441.5 | I17: 148080.2 | K17: 27727 | L17: 59657.1 | M17: 6987.4 | N17: 44370.3 | O17: 19456.6 | P17: 159809.8 | Q17: 1920 | S17: 3814.5 | T17: 48791.1 | U17: 42164.9 | V17: 6626.2 | W17: 44976.6 | X17: 31726.6 | Y17: 13250
A18: 4- 6. | B18: 274902.2 | C18: 3150 | D18: 304.5 | E18: 272056.8 | F18: 24944.6 | G18: 22379.9 | H18: 75267.5 | I18: 149464.8 | K18: 29045.6 | L18: 58093.2 | M18: 7147.7 | N18: 46209 | O18: 19889.8 | P18: 164057.9 | Q18: 3522.1 | S18: 1330.9 | T18: 48905 | U18: 42186.2 | V18: 6718.8 | W18: 47574.1 | X18: 34225.2 | Y18: 13348.9
A19: 7- 9. | B19: 274573 | C19: 3205 | D19: 318.7 | E19: 271686.7 | F19: 25404.9 | G19: 22091.5 | H19: 73689.8 | I19: 150500.6 | K19: 30455.1 | L19: 55378.6 | M19: 7387 | N19: 47270.6 | O19: 20172.2 | P19: 162306.3 | Q19: 1572.2 | S19: 1629.7 | T19: 49604.3 | U19: 42701.6 | V19: 6902.7 | W19: 47974.6 | X19: 34374 | Y19: 13600.7
A20: 10-12. | B20: 277684.8 | C20: 3338.9 | D20: 336 | E20: 274682 | F20: 25921.8 | G20: 21911.5 | H20: 75307.2 | I20: 151541.5 | K20: 31456.3 | L20: 54149.8 | M20: 7478.1 | N20: 47378.3 | O20: 20695 | P20: 163447.8 | Q20: 2625.8 | S20: 2264.7 | T20: 51956.4 | U20: 44878.5 | V20: 7077.9 | W20: 49691.6 | X20: 35585.6 | Y20: 14106
... A102: 4- 6. | B102: 296926.3 | C102: 1843.6 | D102: 3345.7 | E102: 298428.4 | F102: 25879.4 | G102: 15350 | H102: 80016.9 | I102: 177182 | K102: 18186.8 | L102: 40388.1 | M102: 7939.7 | N102: 32047.8 | O102: 30419.5 | P102: 128037.5 | Q102: -1402.7 | S102: 3401.3 | T102: 93549.7 | U102: 74302.1 | V102: 19247.6 | W102: 90148.3 | X102: 70921.7 | Y102: 19226.6
A103: ＊年率で表示している。

Sheet kgaku-jk1722
A1: 実質季節調整系列 | Y1: (単位:2011暦年連鎖価格、10億円)
A2: Real, Seasonally Adjusted Series | Y2: (Billions of Chained (2011) Yen)
B3: 家計最終消費支出（再掲） | K3: 形態別総固定資本形成 | P3: 総資本形成 | S3: 財貨・サービス
C4: 居住者家計の海外での直接購入 | D4: （控除）非居住者家計の国内での直接購入 | E4: 国内家計最終消費支出 | K4: 住宅 | L4: その他の建物・構築物 | M4: 輸送用機械 | N4: その他の機械設備等 | O4: 知的財産生産物 | Q4: うち在庫変動 | S4: 純輸出（再掲） | T4: 輸出（再掲） | W4: 輸入（再掲）
F5: 耐久財 | G5: 半耐久財 | H5: 非耐久財 | I5: サービス | U5: 財貨 | V5: サービス（含む非居住者家計の国内での直接購入） | X5: 財貨 | Y5: サービス（含む居住者家計の海外での直接購入）
B6: Consumptionof Households(id, at §Ｉ) | C6: DirectPurchasesAbroad byResidentHouseholds | D6: (Less) DirectPurchases inthe DomesticMarket byNon-ResidentHouseholds | E6: Domestic FinalConsumptionExpenditure ofHouseholds | F6: DurableGoods | G6: Semi-DurableGoods | H6: Non-DurableGoods | I6: Services | K6: Gross Fixed Capital Formation by Type | P6: Gross CapitalFormation | Q6: Of WhichChange inInventories | S6: Goods & Services
K7: ResidentialInvestment | L7: Other Buildingsand Structures | M7: TransportEquipment | N7: OtherMachinery andEquipment etc. | O7: IntellectualPropertyProducts | S7: Net Exports(id, at §Ｉ) | T7: Exports(id, at §Ｉ) | W7: Imports(id, at §Ｉ)
U8: Goods | V8: Services（Including DirectPurchases in theDomestic Marketby Non-ResidentHouseholds) | X8: Goods | Y8: Services（Including DirectPurchasesAbroad byResidentHouseholds)
A9: 1994/ 1- 3. | B9: 239049.9 | C9: 3853 | D9: 262.3 | E9: 235760.5 | F9: 6929.5 | G9: 19971.3 | H9: 76350.5 | I9: 142657.8 | K9: 26362.9 | L9: 60026.4 | M9: 6435.2 | N9: 22809.6 | O9: 17577.4 | P9: 130161.1 | Q9: 3428.5 | S9: -9150.2 | T9: 33923.4 | U9: 28753.6 | V9: 5251.1 | W9: 43073.6 | X9: 29535.6 | Y9: 12516.7
A10: 4- 6. | B10: 238591.4 | C10: 3853.8 | D10: 262.7 | E10: 235304.2 | F10: 7161.8 | G10: 20331.6 | H10: 76353.1 | I10: 141019.3 | K10: 27367.9 | L10: 59537.3 | M10: 6395.4 | N10: 23434.1 | O10: 17619.2 | P10: 126100.9 | Q10: -2269 | S10: -9661 | T10: 34107.3 | U10: 28859.2 | V10: 5339.3 | W10: 43768.3 | X10: 30222.9 | Y10: 12530
A11: 7- 9. | B11: 242143.6 | C11: 3806.5 | D11: 219.9 | E11: 238827.4 | F11: 7708.3 | G11: 20005.7 | H11: 77081.4 | I11: 142900.3 | K11: 29786.3 | L11: 56200.8 | M11: 6609.2 | N11: 23597.7 | O11: 17889.3 | P11: 129241.3 | Q11: 587.6 | S11: -10343.7 | T11: 34735.6 | U11: 29671.3 | V11: 5102.9 | W11: 45079.3 | X11: 31434 | Y11: 12631.8
A12: 10-12. | B12: 241315.1 | C12: 3751.5 | D12: 214.1 | E12: 238031 | F12: 7721.8 | G12: 19895.8 | H12: 76756.7 | I12: 142419 | K12: 28547.9 | L12: 55338.2 | M12: 6564.2 | N12: 24401.7 | O12: 18035.2 | P12: 127504.5 | Q12: -766 | S12: -10601 | T12: 34897.7 | U12: 29911.5 | V12: 5004.7 | W12: 45498.7 | X12: 32369 | Y12: 12174.7
A13: 1995/ 1- 3. | B13: 242841.8 | C13: 3964.5 | D13: 182.3 | E13: 239391.1 | F13: 8125.1 | G13: 20319.1 | H13: 77663.8 | I13: 141312.3 | K13: 27563.5 | L13: 55808.4 | M13: 6745.6 | N13: 24538.4 | O13: 17621.2 | P13: 129635.8 | Q13: 2272.4 | S13: -11786.9 | T13: 35325.1 | U13: 30367.1 | V13: 4958.7 | W13: 47112 | X13: 33087.9 | Y13: 12989.9
A14: 4- 6. | B14: 245698.5 | C14: 4359 | D14: 171.6 | E14: 241984 | F14: 8661 | G14: 20391.5 | H14: 78316 | I14: 141811.8 | K14: 26951.1 | L14: 56026 | M14: 7117.7 | N14: 26756.1 | O14: 18374.3 | P14: 132292 | Q14: 1273.8 | S14: -12579.8 | T14: 35877 | U14: 30970.3 | V14: 4882.9 | W14: 48456.7 | X14: 34771.7 | Y14: 12699.5
A15: 7- 9. | B15: 247319.2 | C15: 4440.7 | D15: 211 | E15: 243584 | F15: 8591.9 | G15: 20887.4 | H15: 78867 | I15: 142692.1 | K15: 26277 | L15: 60088 | M15: 6667.9 | N15: 27211.4 | O15: 18489.2 | P15: 136746.9 | Q15: 2187.3 | S15: -14937.4 | T15: 36199.3 | U15: 30669.3 | V15: 5618.8 | W15: 51136.7 | X15: 36570.1 | Y15: 13513.5
A16: 10-12. | B16: 248939.2 | C16: 4454.2 | D16: 238.8 | E16: 245213.9 | F16: 8580.1 | G16: 20868.1 | H16: 79422.2 | I16: 144012.1 | K16: 26868.4 | L16: 59713.8 | M16: 6475.7 | N16: 28060 | O16: 18909.2 | P16: 137699.8 | Q16: 1316.3 | S16: -17456.1 | T16: 36105 | U16: 30415.1 | V16: 5815 | W16: 53561.1 | X16: 38368.1 | Y16: 14096.9
A17: 1996/ 1- 3. | B17: 250030.3 | C17: 4481.5 | D17: 277.9 | E17: 246320.2 | F17: 8770.1 | G17: 20073.7 | H17: 78494.1 | I17: 146437.4 | K17: 27917.2 | L17: 61001.1 | M17: 6414.1 | N17: 28665.5 | O17: 19241.3 | P17: 141195.5 | Q17: 2377 | S17: -17623 | T17: 36675.8 | U17: 30778.1 | V17: 6054.9 | W17: 54298.8 | X17: 38903 | Y17: 14285.5
A18: 4- 6. | B18: 251053.7 | C18: 4092 | D18: 297.8 | E18: 247584.4 | F18: 8997.2 | G18: 19844 | H18: 78918.1 | I18: 147016.9 | K18: 29236.1 | L18: 59426.6 | M18: 6564.9 | N18: 30282.8 | O18: 19675.7 | P18: 145024.4 | Q18: 3272.5 | S18: -19275.3 | T18: 36655.3 | U18: 30636.7 | V18: 6205.7 | W18: 55930.7 | X18: 40721.9 | Y18: 14135.9
A19: 7- 9. | B19: 250902.8 | C19: 4124.6 | D19: 311.5 | E19: 247429.2 | F19: 9279.7 | G19: 19641.7 | H19: 77358.7 | I19: 147748.4 | K19: 30436.9 | L19: 56200.3 | M19: 6768.3 | N19: 31299 | O19: 19883.7 | P19: 143502.2 | Q19: 1454.7 | S19: -18130.7 | T19: 37695.6 | U19: 31557.5 | V19: 6320.8 | W19: 55826.4 | X19: 40426.9 | Y19: 14304.8
A20: 10-12. | B20: 253565.5 | C20: 4132.7 | D20: 327.4 | E20: 250088.8 | F20: 9554.4 | G20: 19521.3 | H20: 78959.7 | I20: 148487.8 | K20: 31124 | L20: 54780.6 | M20: 6895.7 | N20: 31602.2 | O20: 20336.2 | P20: 144142.1 | Q20: 2528.1 | S20: -17098.8 | T20: 39316.9 | U20: 33020.1 | V20: 6464 | W20: 56415.7 | X20: 40778.1 | Y20: 14523.3
... A102: 4- 6. | B102: 293369.8 | C102: 1318.6 | D102: 3174.4 | E102: 295295.5 | F102: 27446.9 | G102: 14552.5 | H102: 75269.8 | I102: 178416.3 | K102: 17098.6 | L102: 38553.1 | M102: 7686.4 | N102: 32152.3 | O102: 29799.1 | P102: 124405.1 | Q102: -1247.6 | S102: -3185.1 | T102: 87955 | U102: 70317.7 | V102: 17555.7 | W102: 91140.1 | X102: 73356 | Y102: 17901.2
A103: ＊年率で表示している。

Sheet gaku-mk1722
A1: 名目季節調整系列 | P1: <参考> | AA1: (単位:10億円)
A2: Nominal, Seasonally Adjusted Series | P2: <cf> | AA2: (Billion Yen)
B3: 国内総生産(支出側) | C3: 民間最終消費支出 | F3: 民間住宅 | G3: 民間企業設備 | H3: 民間在庫変動 | I3: 政府最終消費支出 | J3: 公的固定資本形成 | K3: 公的在庫変動 | L3: 財貨・サービス | P3: 海外からの所得 | S3: 国民総所得 | U3: 国内需要 | V3: 民間需要 | W3: 公的需要 | Y3: 総固定資本形成 | AA3: 最終需要
D4: 家計最終消費支出 | L4: 純輸出 | M4: 輸出 | N4: 輸入 | P4: 純受取 | Q4: 受取 | R4: 支払
E5: 除く持ち家の帰属家賃
B6: GDP(Expenditure Approach) | C6: PrivateConsumption | D6: Consumption ofHouseholds | E6: ExcludingImputed Rent | F6: PrivateResidentialInvestment | G6: Private Non-Resi.Investment | H6: Changein PrivateInventories | I6: GovernmentConsumption | J6: PublicInvestment | K6: Changein PublicInventories | L6: Goods & Services | P6: Income from /to the Rest of the World | S6: GNI | U6: DomesticDemand | V6: PrivateDemand | W6: PublicDemand | Y6: Gross Fixed CapitalFormation | AA6: Final Sales of Domestic Product
L7: Net Exports | M7: Exports | N7: Imports | P7: Net | Q7: Receipt | R7: Payment
A8: 1994/ 1- 3. | B8: 500939.5 | C8: 266326.9 | D8: 261777.1 | E8: 227333.8 | F8: 24875.9 | G8: 76097.8 | H8: 3177.8 | I8: 73581.4 | J8: 46322.3 | K8: -442.8 | L8: 11000.2 | M8: 44990.7 | N8: 33990.4 | P8: 4435.1 | Q8: 15711.7 | R8: 11276.6 | S8: 505374.6 | U8: 489939.3 | V8: 370478.5 | W8: 119460.8 | Y8: 147296.1 | AA8: 498204.6
A9: 4- 6. | B9: 498477.8 | C9: 266882.3 | D9: 262262.7 | E9: 227447.4 | F9: 26083.5 | G9: 75329.9 | H9: -2760.5 | I9: 75125.1 | J9: 47330.5 | K9: 522.3 | L9: 9964.8 | M9: 45487.7 | N9: 35522.9 | P9: 4185.7 | Q9: 15667.5 | R9: 11481.8 | S9: 502663.4 | U9: 488513 | V9: 365535.1 | W9: 122977.9 | Y9: 148743.9 | AA9: 500716.1
A10: 7- 9. | B10: 504391.1 | C10: 270475.7 | D10: 265821.2 | E10: 230598.6 | F10: 28413.2 | G10: 74808.8 | H10: 64.3 | I10: 75907.3 | J10: 45489.2 | K10: 653.4 | L10: 8579.2 | M10: 45045.2 | N10: 36466.1 | P10: 4184.1 | Q10: 16025.4 | R10: 11841.3 | S10: 508575.2 | U10: 495812 | V10: 373762 | W10: 122049.9 | Y10: 148711.3 | AA10: 503673.5
A11: 10-12. | B11: 502220.4 | C11: 269973.9 | D11: 265264.9 | E11: 229560.9 | F11: 27067.4 | G11: 75883 | H11: -1406.9 | I11: 76730.3 | J11: 44663.9 | K11: 702.7 | L11: 8606.2 | M11: 45098.2 | N11: 36492 | P11: 4229.8 | Q11: 16565.2 | R11: 12335.4 | S11: 506450.3 | U11: 493614.2 | V11: 371517.4 | W11: 122096.9 | Y11: 147614.3 | AA11: 502924.7
A12: 1995/ 1- 3. | B12: 504971.9 | C12: 271265.7 | D12: 266488.5 | E12: 230416.7 | F12: 26075.5 | G12: 77722.1 | H12: 1899.6 | I12: 77721.1 | J12: 42705.2 | K12: -174 | L12: 7756.7 | M12: 45059 | N12: 37302.3 | P12: 4237.4 | Q12: 16860.5 | R12: 12623.1 | S12: 509209.3 | U12: 497215.3 | V12: 376962.9 | W12: 120252.4 | Y12: 146502.8 | AA12: 503246.3
A13: 4- 6. | B13: 510326.4 | C13: 273538.6 | D13: 268686.8 | E13: 232275.1 | F13: 25136.2 | G13: 80315.5 | H13: 1130.1 | I13: 78203.9 | J13: 44363.6 | K13: 244.5 | L13: 7394.1 | M13: 44066.3 | N13: 36672.2 | P13: 3483.2 | Q13: 15910 | R13: 12426.8 | S13: 513809.6 | U13: 502932.3 | V13: 380120.4 | W13: 122812 | Y13: 149815.2 | AA13: 508951.9
A14: 7- 9. | B14: 516624.7 | C14: 275117.6 | D14: 270195.9 | E14: 233384 | F14: 24544.2 | G14: 81502.9 | H14: 2090.5 | I14: 79185.4 | J14: 47736.8 | K14: 175.4 | L14: 6271.9 | M14: 46797.9 | N14: 40526 | P14: 5005.9 | Q14: 20060.9 | R14: 15055 | S14: 521630.7 | U14: 510352.9 | V14: 383255.2 | W14: 127097.6 | Y14: 153783.9 | AA14: 514358.7
A15: 10-12. | B15: 517836.1 | C15: 276740.9 | D15: 271775.3 | E15: 234596 | F15: 25106.5 | G15: 82476.5 | H15: 1180.5 | I15: 79766.3 | J15: 47873.2 | K15: 215.5 | L15: 4476.6 | M15: 47873.8 | N15: 43397.2 | P15: 5303.1 | Q15: 20683.2 | R15: 15380.1 | S15: 523139.2 | U15: 513359.5 | V15: 385504.4 | W15: 127855.1 | Y15: 155456.2 | AA15: 516440.1
A16: 1996/ 1- 3. | B16: 521415.5 | C16: 277884.7 | D16: 272896.5 | E16: 235340.8 | F16: 26205.8 | G16: 81422.1 | H16: 1445.6 | I16: 79906.4 | J16: 50261.9 | K16: 474.4 | L16: 3814.5 | M16: 48791.1 | N16: 44976.6 | P16: 5782.4 | Q16: 12756.3 | R16: 6974 | S16: 527197.8 | U16: 517601 | V16: 386958.2 | W16: 130642.8 | Y16: 157889.8 | AA16: 519495.4
A17: 4- 6. | B17: 526228.5 | C17: 279927.8 | D17: 274902.2 | E17: 236900.2 | F17: 27557.3 | G17: 83545.7 | H17: 3353.7 | I17: 80911.9 | J17: 49432.9 | K17: 168.4 | L17: 1330.9 | M17: 48905 | N17: 47574.1 | P17: 6535.3 | Q17: 12954.3 | R17: 6419 | S17: 532763.8 | U17: 524897.6 | V17: 394384.5 | W17: 130513.1 | Y17: 160535.9 | AA17: 522706.4
A18: 7- 9. | B18: 525385.4 | C18: 279640.8 | D18: 274573 | E18: 236141.1 | F18: 28889.1 | G18: 84545.1 | H18: 1389.8 | I18: 81808.6 | J18: 47299.8 | K18: 182.4 | L18: 1629.7 | M18: 49604.3 | N18: 47974.6 | P18: 6247.4 | Q18: 12465.5 | R18: 6218.1 | S18: 531632.8 | U18: 523755.7 | V18: 394464.9 | W18: 129290.8 | Y18: 160734.1 | AA18: 523813.2
A19: 10-12. | B19: 530701.9 | C19: 282766.6 | D19: 277684.8 | E19: 238806.1 | F19: 29856.5 | G19: 84612.6 | H19: 2397 | I19: 82222.8 | J19: 46352.9 | K19: 228.8 | L19: 2264.7 | M19: 51956.4 | N19: 49691.6 | P19: 6308.4 | Q19: 12605.2 | R19: 6296.9 | S19: 537010.3 | U19: 528437.2 | V19: 399632.7 | W19: 128804.5 | Y19: 160822 | AA19: 528076.1
... A101: 4- 6. | B101: 542774.4 | C101: 304695 | D101: 296926.3 | E101: 246990.4 | F101: 17561.6 | G101: 84579.2 | H101: -1427.8 | I101: 106640.6 | J101: 27299.4 | K101: 25.2 | L101: 3401.3 | M101: 93549.7 | N101: 90148.3 | P101: 17982.5 | Q101: 29776.6 | R101: 11794.1 | S101: 560756.9 | U101: 539373.1 | V101: 405408 | W101: 133965.1 | Y101: 129440.2 | AA101: 544177.1

Sheet gaku-jk1722
A1: 実質季節調整系列 | Q1: <参考> | AD1: (単位:2011暦年連鎖価格、10億円)
A2: Real, Seasonally Adjusted Series | Q2: <cf> | AD2: (Billions of Chained (2011) Yen)
B3: 国内総生産(支出側) | C3: 民間最終消費支出 | F3: 民間住宅 | G3: 民間企業設備 | H3: 民間在庫変動 | I3: 政府最終消費支出 | J3: 公的固定資本形成 | K3: 公的在庫変動 | L3: 財貨・サービス | O3: 開差 | Q3: 交易利得 | R3: 国内総所得 | S3: 海外からの所得 | V3: 国民総所得 | X3: 国内需要 | Y3: 民間需要 | Z3: 公的需要 | AB3: 総固定資本形成 | AD3: 最終需要
D4: 家計最終消費支出 | L4: 純輸出 | M4: 輸出 | N4: 輸入 | S4: 純受取 | T4: 受取 | U4: 支払
E5: 除く持ち家の帰属家賃
B6: GDP(Expenditure Approach) | C6: PrivateConsumption | D6: Consumption ofHouseholds | E6: ExcludingImputed Rent | F6: PrivateResidentialInvestment | G6: Private Non-Resi.Investment | H6: Changein PrivateInventories | I6: GovernmentConsumption | J6: PublicInvestment | K6: Changein PublicInventories | L6: Goods & Services | O6: Residual | Q6: TradingGains/Losses | R6: GDI | S6: Income from /to the Rest of the World | V6: GNI | X6: DomesticDemand | Y6: PrivateDemand | Z6: PublicDemand | AB6: Gross Fixed CapitalFormation | AD6: Final Sales of Domestic Product
L7: Net Exports | M7: Exports | N7: Imports | S7: Net | T7: Receipt | U7: Payment
A8: 1994/ 1- 3. | B8: 425598.9 | C8: 243131.5 | D8: 239049.9 | E8: 202446.4 | F8: 24842.4 | G8: 60160.5 | H8: 3808.3 | I8: 70584.5 | J8: 44413.4 | K8: -716.7 | L8: -9150.2 | M8: 33923.4 | N8: 43073.6 | O8: -11474.8 | Q8: 19874.1 | R8: 445473 | S8: 4015.1 | T8: 14219.8 | U8: 10204.7 | V8: 449488.1 | X8: 444360.7 | Y8: 330912.9 | Z8: 113557.1 | AB8: 126536.2 | AD8: 421953.9
A9: 4- 6. | B9: 421812 | C9: 242713.6 | D9: 238591.4 | E9: 201817.8 | F9: 26021 | G9: 59749.4 | H9: -2723.4 | I9: 71541.4 | J9: 45332.2 | K9: 785.3 | L9: -9661 | M9: 34107.3 | N9: 43768.3 | O9: -11946.4 | Q9: 19240.2 | R9: 441052.2 | S9: 3772.1 | T9: 14181.9 | U9: 10409.7 | V9: 444824.4 | X9: 440613.8 | Y9: 324566.3 | Z9: 116378.4 | AB9: 127933.7 | AD9: 423523.2
A10: 7- 9. | B10: 428451.1 | C10: 246283.7 | D10: 242143.6 | E10: 205098.4 | F10: 28366.1 | G10: 59661 | H10: -64.1 | I10: 72019.3 | J10: 43681.3 | K10: 975.1 | L10: -10343.7 | M10: 34735.6 | N10: 45079.3 | O10: -12127.6 | Q10: 18744.3 | R10: 447195.5 | S10: 3777.1 | T10: 14485.7 | U10: 10708.5 | V10: 450972.6 | X10: 447892.9 | Y10: 332705.9 | Z10: 115350.2 | AB10: 128379.6 | AD10: 427516.2
A11: 10-12. | B11: 426034.4 | C11: 245497.6 | D11: 241315.1 | E11: 204118.9 | F11: 27078.9 | G11: 60824.5 | H11: -1409.1 | I11: 72159.5 | J11: 43010.2 | K11: 1015.2 | L11: -10601 | M11: 34897.7 | N11: 45498.7 | O11: -11541.4 | Q11: 19081.3 | R11: 445115.7 | S11: 3832 | T11: 14981.6 | U11: 11149.6 | V11: 448947.7 | X11: 445432.6 | Y11: 330748.3 | Z11: 114855.6 | AB11: 127926.4 | AD11: 426358.9
A12: 1995/ 1- 3. | B12: 430299.9 | C12: 247086.9 | D12: 242841.8 | E12: 205439.5 | F12: 26096.3 | G12: 62462.5 | H12: 2273 | I12: 73635.7 | J12: 41094.9 | K12: -90.3 | L12: -11786.9 | M12: 35325.1 | N12: 47112 | O12: -10472.2 | Q12: 19550.7 | R12: 449850.6 | S12: 3839.3 | T12: 15260.4 | U12: 11421.2 | V12: 453689.8 | X12: 450642.2 | Y12: 336940.3 | Z12: 113731 | AB12: 127132.7 | AD12: 427751.7
A13: 4- 6. | B13: 435620.9 | C13: 250013 | D13: 245698.5 | E13: 208067.5 | F13: 25299.7 | G13: 64990.4 | H13: 1072.5 | I13: 73962 | J13: 42827.1 | K13: 258.1 | L13: -12579.8 | M13: 35877 | N13: 48456.7 | O13: -10222.1 | Q13: 20303.1 | R13: 455924 | S13: 3152.9 | T13: 14486.2 | U13: 11333.2 | V13: 459076.9 | X13: 456630.6 | Y13: 340718.2 | Z13: 115985.2 | AB13: 130740.4 | AD13: 434009.4
A14: 7- 9. | B14: 440854.1 | C14: 251697.5 | D14: 247319.2 | E14: 209492.2 | F14: 24680.7 | G14: 66029.7 | H14: 2011.1 | I14: 74812.5 | J14: 46151 | K14: 183.8 | L14: -14937.4 | M14: 36199.3 | N14: 51136.7 | O14: -9774.9 | Q14: 21210.1 | R14: 462064.2 | S14: 4542.4 | T14: 18239.9 | U14: 13697.5 | V14: 466606.6 | X14: 463762.8 | Y14: 343912 | Z14: 120056 | AB14: 134317.8 | AD14: 438386.4
A15: 10-12. | B15: 441692.5 | C15: 253348.4 | D15: 248939.2 | E15: 210902.8 | F15: 25322.1 | G15: 67046.5 | H15: 1109.4 | I15: 74947.1 | J15: 46285.3 | K15: 265.2 | L15: -17456.1 | M15: 36105 | N15: 53561.1 | O15: -9175.4 | Q15: 21854 | R15: 463546.5 | S15: 4849 | T15: 18842.3 | U15: 13993.4 | V15: 468395.4 | X15: 466518.9 | Y15: 346329.9 | Z15: 120368.7 | AB15: 136093.7 | AD15: 440034.6
A16: 1996/ 1- 3. | B16: 446782.3 | C16: 254442.5 | D16: 250030.3 | E16: 211792.2 | F16: 26364 | G16: 66541.2 | H16: 1852.5 | I16: 75536 | J16: 48665.5 | K16: 719.1 | L16: -17623 | M16: 36675.8 | N16: 54298.8 | O16: -9715.5 | Q16: 21323.9 | R16: 468106.3 | S16: 5268.4 | T16: 11617.8 | U16: 6349.4 | V16: 473374.6 | X16: 471790.1 | Y16: 348503.5 | Z16: 123556.9 | AB16: 138603.3 | AD16: 444164.6
A17: 4- 6. | B17: 450410.1 | C17: 255478.6 | D17: 251053.7 | E17: 212602.3 | F17: 27716.5 | G17: 68710.2 | H17: 3032.4 | I17: 75584.3 | J17: 48045.8 | K17: 238.5 | L17: -19275.3 | M17: 36655.3 | N17: 55930.7 | O17: -9120.9 | Q17: 20552.5 | R17: 470962.6 | S17: 5945.4 | T17: 11799.7 | U17: 5854.3 | V17: 476908 | X17: 476832.9 | Y17: 354294.6 | Z17: 122698.5 | AB17: 141556.4 | AD17: 446943.1
A18: 7- 9. | B18: 450363.8 | C18: 255355.3 | D18: 250902.8 | E18: 212249 | F18: 28849.1 | G18: 69800.7 | H18: 1242.6 | I18: 75960.2 | J18: 45867 | K18: 270.3 | L18: -18130.7 | M18: 37695.6 | N18: 55826.4 | O18: -8850.6 | Q18: 19692.7 | R18: 470056.5 | S18: 5666.3 | T18: 11318.6 | U18: 5652.2 | V18: 475722.8 | X18: 475490.7 | Y18: 354616.9 | Z18: 120963.6 | AB18: 141748.3 | AD18: 448565.9
A19: 10-12. | B19: 455846.1 | C19: 258015.5 | D19: 253565.5 | E19: 214657.3 | F19: 29508.1 | G19: 69858.5 | H19: 2258.5 | I19: 77059.8 | J19: 44753.4 | K19: 315.5 | L19: -17098.8 | M19: 39316.9 | N19: 56415.7 | O19: -8824.3 | Q19: 19231.7 | R19: 475077.8 | S19: 5757.6 | T19: 11476.4 | U19: 5718.8 | V19: 480835.4 | X19: 479855 | Y19: 358888.3 | Z19: 121006.6 | AB19: 141379.5 | AD19: 453059.2
... A101: 4- 6. | B101: 529241.6 | C101: 301186.4 | D101: 293369.8 | E101: 240181.5 | F101: 16517.5 | G101: 82952.6 | H101: -1254.8 | I101: 106215.2 | J101: 26005.6 | K101: 29.4 | L101: -3185.1 | M101: 87955 | N101: 91140.1 | O101: 774.8 | Q101: 6501.2 | R101: 535742.8 | S101: 17812.2 | T101: 29390.4 | U101: 11578.1 | V101: 553555 | X101: 531849.7 | Y101: 399630 | Z101: 132219 | AB101: 125445.9 | AD101: 530241.4
A102: ＊開差＝国内総生産(支出側)－国内総生産(支出側)の内訳項目計
A103: ＊財貨・サービスの純輸出は連鎖方式での計算ができないため、財貨・サービスの輸出－財貨・サービスの輸入により求めている。このため寄与度とは符号が一致しない場合がある。

Sheet kdef-cy1131
A1: 暦年デフレーター | Q1: (2000暦年＝100)
A2: Deflators (calendar year) | R2: (Calendar year of 2000 = 100)
B3: 家計最終消費支出（再掲） | M3: 財貨・サービス
C4: 居住者家計の海外での直接購入 | D4: （控除）非居住者家計の国内での直接購入 | E4: 国内家計最終消費支出 | L4: 純輸出（再掲） | M4: 輸出（再掲） | P4: 輸入（再掲）
A5: 暦年 | F5: 耐久財 | G5: 半耐久財 | H5: 非耐久財 | I5: サービス | N5: 財貨 | O5: サービス（含む非居住者家計の国内での直接購入） | Q5: 財貨 | R5: サービス（含む居住者家計の海外での直接購入）
B6: Consumptionof households(id, at §Ｉ) | C6: Directpurchasesabroad byresidenthouseholds | D6: (Less) Directpurchases inthe domesticmarket bynon-residenthouseholds | E6: Domestic finalconsumptionexpenditure ofhouseholds | F6: Durablegoods | G6: Semi-durablegoods | H6: Non-durablegoods | I6: Services | M6: Goods & Services
L7: Net Exports(id, at §Ｉ) | M7: Exports(id, at §Ｉ) | P7: Imports(id, at §Ｉ)
A8: Calendar Year | N8: Goods | O8: Services（including directpurchases in thedomestic marketby non-residenthouseholds) | Q8: Goods | R8: Services（including directpurchasesabroad byresidenthouseholds)
A9: 1980/1-12. | B9: 79.1 | C9: 88.7 | D9: 76.7 | E9: 79.1 | F9: 168.3 | G9: 81.5 | H9: 83 | I9: 66.6 | L9: *** | M9: 161.9 | N9: 169.3 | O9: 109.5 | P9: 188.9 | Q9: 213.6 | R9: 126.4
A10: 1981/1-12. | B10: 82.7 | C10: 98.8 | D10: 80.5 | E10: 82.6 | F10: 168.6 | G10: 84.3 | H10: 87.8 | I10: 69.6 | L10: *** | M10: 164.7 | N10: 171.8 | O10: 114 | P10: 189.7 | Q10: 216.4 | R10: 121.7
A11: 1982/1-12. | B11: 84.8 | C11: 118.3 | D11: 82.6 | E11: 84.8 | F11: 167.4 | G11: 86 | H11: 89.5 | I11: 72.2 | L11: *** | M11: 168.2 | N11: 175.2 | O11: 117.4 | P11: 198.5 | Q11: 230.9 | R11: 117
A12: 1983/1-12. | B12: 86.5 | C12: 117.3 | D12: 84.1 | E12: 86.4 | F12: 165.7 | G12: 87.4 | H12: 91 | I12: 74.1 | L12: *** | M12: 159.9 | N12: 165.8 | O12: 116.3 | P12: 188.6 | Q12: 216.9 | R12: 117.3
A13: 1984/1-12. | B13: 88.4 | C13: 121.6 | D13: 86 | E13: 88.3 | F13: 163.8 | G13: 88.9 | H13: 93.4 | I13: 75.9 | L13: *** | M13: 159.2 | N13: 164.8 | O13: 117.5 | P13: 183.6 | Q13: 209.4 | R13: 118.8
A14: 1985/1-12. | B14: 89.7 | C14: 124 | D14: 87.7 | E14: 89.6 | F14: 161.8 | G14: 90.6 | H14: 94.2 | I14: 77.7 | L14: *** | M14: 155.5 | N14: 161.3 | O14: 113 | P14: 179.8 | Q14: 204.2 | R14: 118.7
A15: 1986/1-12. | B15: 90.1 | C15: 89.1 | D15: 88 | E15: 90.1 | F15: 156.9 | G15: 91.6 | H15: 93.4 | I15: 79.2 | L15: *** | M15: 135.1 | N15: 139.5 | O15: 102.3 | P15: 122.2 | Q15: 132.3 | R15: 98.4
A16: 1987/1-12. | B16: 90.3 | C16: 79.6 | D16: 87.9 | E16: 90.5 | F16: 151.7 | G16: 92.2 | H16: 92 | I16: 80.9 | L16: *** | M16: 128.6 | N16: 132.4 | O16: 100.1 | P16: 115.9 | Q16: 123.8 | R16: 97.2
A17: 1988/1-12. | B17: 90.7 | C17: 74.3 | D17: 88.3 | E17: 90.9 | F17: 146.3 | G17: 92.7 | H17: 91.8 | I17: 82.2 | L17: *** | M17: 124.7 | N17: 128 | O17: 99.3 | P17: 111.3 | Q17: 117.4 | R17: 96.9
A18: 1989/1-12. | B18: 92.5 | C18: 84.7 | D18: 90.4 | E18: 92.6 | F18: 139.7 | G18: 95.4 | H18: 93.4 | I18: 84.7 | L18: *** | M18: 128.6 | N18: 132.5 | O18: 100 | P18: 116.4 | Q18: 124.1 | R18: 98.5
A19: 1990/1-12. | B19: 94.9 | C19: 94.7 | D19: 93 | E19: 94.9 | F19: 137.1 | G19: 98.2 | H19: 96.1 | I19: 87.2 | L19: *** | M19: 130.2 | N19: 134.1 | O19: 101.5 | P19: 124.6 | Q19: 133.5 | R19: 104.1
A20: 1991/1-12. | B20: 97.5 | C20: 93.7 | D20: 96.1 | E20: 97.6 | F20: 135.6 | G20: 101.3 | H20: 99.5 | I20: 89.9 | L20: *** | M20: 125.9 | N20: 128.6 | O20: 104.9 | P20: 118.2 | Q20: 124.5 | R20: 103.6
... A39: 2010/1-12. | B39: 91.3 | C39: 121.6 | D39: 96.4 | E39: 91 | F39: 45.4 | G39: 91 | H39: 101.9 | I39: 96.3 | L39: *** | M39: 86.9 | N39: 86.1 | O39: 93.4 | P39: 117.9 | Q39: 117.2 | R39: 117.5

Sheet def-cy1131
A1: 暦年デフレーター | P1: <参考> | V1: (2000暦年＝100)
A2: Deflators (calendar year) | P2: <cf> | W2: (Calendar year of 2000 = 100)
B3: 国内総生産(支出側) | C3: 民間最終消費支出 | F3: 民間住宅 | G3: 民間企業設備 | H3: 民間在庫品増加 | I3: 政府最終消費支出 | J3: 公的固定資本形成 | K3: 公的在庫品増加 | L3: 財貨・サービス | P3: 海外からの所得 | S3: 国民総所得 | U3: 国内需要 | V3: 民間需要 | W3: 公的需要 | Y3: 総固定資本形成
A4: 暦年 | D4: 家計最終消費支出 | L4: 純輸出 | M4: 輸出 | N4: 輸入 | P4: 純受取 | Q4: 受取 | R4: 支払
E5: 除く持ち家の帰属家賃
B6: GDP(expenditure approach) | C6: PrivateConsumption | D6: Consumption ofHouseholds | E6: Excludingimputed rent | F6: PrivateResidentialInvestment | G6: PrivateNon-Resi.Investment | H6: PrivateInventory | I6: GovernmentConsumption | J6: PublicInvestment | K6: PublicInventory | L6: Goods & Services | P6: Income from /to the rest of the world | S6: GNI | U6: DomesticDemand | V6: PrivateDemand | W6: PublicDemand | Y6: Gross fixed capitalformation
A7: Calendar Year | L7: Net Exports | M7: Exports | N7: Imports | P7: Net | Q7: Receipt | R7: Payment
A8: 1980/1-12. | B8: 85.4 | C8: 79 | D8: 79.1 | E8: 83 | F8: 82 | G8: 111 | H8: 169.6 | I8: 79.3 | J8: 89.9 | K8: 51.2 | L8: *** | M8: 161.9 | N8: 188.9 | P8: *** | Q8: 85 | R8: 84.9 | S8: 86.3 | U8: 85.2 | V8: 85.2 | W8: 84.6 | Y8: 99.9
A9: 1981/1-12. | B9: 88.1 | C9: 82.6 | D9: 82.7 | E9: 86.7 | F9: 81.5 | G9: 112.3 | H9: 161.7 | I9: 80.8 | J9: 92 | K9: 54.3 | L9: *** | M9: 164.7 | N9: 189.7 | P9: *** | Q9: 87.8 | R9: 87.7 | S9: 89 | U9: 87.7 | V9: 88.1 | W9: 85.9 | Y9: 101.1
A10: 1982/1-12. | B10: 89.5 | C10: 84.8 | D10: 84.8 | E10: 88.9 | F10: 83.1 | G10: 112.7 | H10: 160.4 | I10: 82.2 | J10: 93.3 | K10: 57.5 | L10: *** | M10: 168.2 | N10: 198.5 | P10: *** | Q10: 89.4 | R10: 89.3 | S10: 90.5 | U10: 89.4 | V10: 89.9 | W10: 87.1 | Y10: 102
A11: 1983/1-12. | B11: 90.3 | C11: 86.4 | D11: 86.5 | E11: 90.4 | F11: 83.2 | G11: 111.9 | H11: 155.8 | I11: 82.4 | J11: 93.2 | K11: 60 | L11: *** | M11: 159.9 | N11: 188.6 | P11: *** | Q11: 90.3 | R11: 90.2 | S11: 91.3 | U11: 90.3 | V11: 91.1 | W11: 87 | Y11: 101.6
A12: 1984/1-12. | B12: 91.9 | C12: 88.3 | D12: 88.4 | E12: 92.3 | F12: 84.5 | G12: 111.6 | H12: 153.6 | I12: 83.4 | J12: 94.1 | K12: 63.1 | L12: *** | M12: 159.2 | N12: 183.6 | P12: *** | Q12: 91.7 | R12: 91.6 | S12: 92.8 | U12: 91.7 | V12: 92.5 | W12: 88.3 | Y12: 102
A13: 1985/1-12. | B13: 92.8 | C13: 89.7 | D13: 89.7 | E13: 93.5 | F13: 85.1 | G13: 111.4 | H13: 149.3 | I13: 85.9 | J13: 94 | K13: 67 | L13: *** | M13: 155.5 | N13: 179.8 | P13: *** | Q13: 92.6 | R13: 92.5 | S13: 93.7 | U13: 92.7 | V13: 92.9 | W13: 91.9 | Y13: 102
A14: 1986/1-12. | B14: 94.5 | C14: 90 | D14: 90.1 | E14: 93.5 | F14: 84.7 | G14: 109.9 | H14: 137.3 | I14: 86.9 | J14: 93.4 | K14: 69.2 | L14: *** | M14: 135.1 | N14: 122.2 | P14: *** | Q14: 92.7 | R14: 92.7 | S14: 93.8 | U14: 92.7 | V14: 93.3 | W14: 90.5 | Y14: 101
A15: 1987/1-12. | B15: 94.4 | C15: 90.3 | D15: 90.3 | E15: 93.3 | F15: 86.1 | G15: 108.1 | H15: 134.6 | I15: 87.2 | J15: 93.4 | K15: 75.5 | L15: *** | M15: 128.6 | N15: 115.9 | P15: *** | Q15: 92.7 | R15: 92.7 | S15: 93.7 | U15: 92.7 | V15: 93.3 | W15: 90.6 | Y15: 100.3
A16: 1988/1-12. | B16: 94.7 | C16: 90.7 | D16: 90.7 | E16: 93.3 | F16: 87.5 | G16: 107.5 | H16: 131.2 | I16: 87.6 | J16: 94.5 | K16: 78.5 | L16: *** | M16: 124.7 | N16: 111.3 | P16: *** | Q16: 93 | R16: 93 | S16: 93.9 | U16: 93 | V16: 93.7 | W16: 90.5 | Y16: 100.5
A17: 1989/1-12. | B17: 96.8 | C17: 92.5 | D17: 92.5 | E17: 95 | F17: 92.5 | G17: 108.5 | H17: 129.9 | I17: 90.7 | J17: 98.6 | K17: 81.5 | L17: *** | M17: 128.6 | N17: 116.4 | P17: *** | Q17: 95.2 | R17: 95.2 | S17: 96.1 | U17: 95.2 | V17: 95.6 | W17: 93.9 | Y17: 103
A18: 1990/1-12. | B18: 99 | C18: 94.9 | D18: 94.9 | E18: 97.2 | F18: 95.9 | G18: 111.1 | H18: 129.9 | I18: 94.1 | J18: 102 | K18: 85.2 | L18: *** | M18: 130.2 | N18: 124.6 | P18: *** | Q18: 97.6 | R18: 97.7 | S18: 98.6 | U18: 97.9 | V18: 98.1 | W18: 97.3 | Y18: 105.9
A19: 1991/1-12. | B19: 101.6 | C19: 97.5 | D19: 97.5 | E19: 99.7 | F19: 98.9 | G19: 112.9 | H19: 128.7 | I19: 96.6 | J19: 105.1 | K19: 86 | L19: *** | M19: 125.9 | N19: 118.2 | P19: *** | Q19: 100.2 | R19: 100.2 | S19: 101.1 | U19: 100.4 | V19: 100.5 | W19: 99.8 | Y19: 108.2
... A38: 2010/1-12. | B38: 88.7 | C38: 91.3 | D38: 91.3 | E38: 91.3 | F38: 102.9 | G38: 89.6 | H38: 96.5 | I38: 93.9 | J38: 101.5 | K38: 103.4 | L38: *** | M38: 86.9 | N38: 117.9 | P38: *** | Q38: 92.3 | R38: 92.8 | S38: 92.3 | U38: 92.4 | V38: 91.6 | W38: 95.2 | Y38: 94
A39: ＊在庫デフレーターは暦年平均デフレーターである。

Sheet kdef-cy1722
A1: 暦年デフレーター | Y1: (2011暦年＝100)
A2: Deflators, Calendar Year | Y2: (Calendar Year of 2011 = 100)
B3: 家計最終消費支出（再掲） | K3: 形態別総固定資本形成 | P3: 総資本形成 | S3: 財貨・サービス
C4: 居住者家計の海外での直接購入 | D4: （控除）非居住者家計の国内での直接購入 | E4: 国内家計最終消費支出 | K4: 住宅 | L4: その他の建物・構築物 | M4: 輸送用機械 | N4: その他の機械設備等 | O4: 知的財産生産物 | Q4: うち在庫変動 | S4: 純輸出（再掲） | T4: 輸出（再掲） | W4: 輸入（再掲）
F5: 耐久財 | G5: 半耐久財 | H5: 非耐久財 | I5: サービス | U5: 財貨 | V5: サービス（含む非居住者家計の国内での直接購入） | X5: 財貨 | Y5: サービス（含む居住者家計の海外での直接購入）
