Workbook
Name IQ_CH: 110000
Name IQ_CQ: 5000
Name IQ_CY: 10000
Name IQ_DAILY: 500000
Name IQ_FH: 100000
Name IQ_FQ: 500
Name IQ_FY: 1000
Name IQ_LTM: 2000
Name IQ_MONTH: 15000
Name IQ_NTM: 6000
Name IQ_WEEK: 50000
Name IQ_YTD: 3000
Name KAN: [1]台風10号!#REF!
Name KIN: [1]台風10号!#REF!
Name NAKA: [1]台風10号!#REF!
Name OA: [1]台風10号!#REF!

Sheet ReadMe
A1: ＜使用している系列＞
A2: 変数名 | B2: 系列名 | C2: 元データ | D2: データシート | F2: ＜推計期間＞
A3: l_pi_c | B3: GDPデフレーター、前期比 | C3: 内閣府 | D3: ・rG（Real GDP、Quarterly、SAAR） ・nG（名目GDP、Quarterly、SAAR） | F3: From | G3: 29587
A4: l_IC | B4: 一人あたり民間企業設備、前期比 | C4: 内閣府、FERIS | D4: ・rG（Private Non-resi. Investment、Quarterly、SAAR） ・L | F4: To | G4: 43830
A5: l_pi_d | B5: 設備投資デフレーター、前期比 | C5: 内閣府 | D5: ・nG（Private Non-resi. Investment、Quarterly、SAAR） ・rG（Private Non-resi. Investment、Quarterly、SAAR）
A6: l_Output | B6: 一人あたりGDP、前期比 | C6: 内閣府、FERIS | D6: ・rG（Real GDP、Quarterly、SAAR） ・L
A7: l_HC | B7: 一人あたり労働時間、前期比 | C7: FERIS | D7: ・HC ・L
A8: l_WC | B8: 労働時間あたり雇用者報酬、前期比 | C8: FERIS | D8: ・HC ・W
A9: l_NSR | B9: O/N無担保コール | C9: FERIS | D9: ・NSR
A10: l_NB | B10: 一人あたり株式・出資金（銀行）、前期比 | C10: FERIS、 TSE | D10: ・FoF ・TSE
A11: l_NEC | B11: 一人あたり株式・出資金（全産業除く金融）、前期比 | C11: FERIS、 TSE | D11: ・FoF ・TSE
A12: fdr、edr | B12: 水害（地震）に伴う資本ストックの毀損率 | C12: 水害統計、内閣府など | D12: ・KC ・Prec

Sheet Est_Input
A1: 0.0027846044 | B1: -0.00045873031 | C1: 0.0067402807 | D1: 0.0010552605 | E1: -0.0017642513 | F1: 0.0052390651 | G1: 0.016002831 | H1: 0.05879122 | I1: 0.032692788 | J1: 0.0016402926 | K1: 1.8811945e-06 | L1: 0 | M1: 1.8816085e-05 | N1: 0
A2: 0.0048072759 | B2: -0.0054417691 | C2: -0.0015149499 | D2: 0.0037915402 | E2: 0.0020069905 | F2: 0.016392131 | G2: 0.012639809 | H2: 0.072590823 | I2: 0.098415782 | J2: 0.0026641167 | K2: 1.0176172e-05 | L2: 0 | M2: 0.0001021931 | N2: 0
A3: 0.0037623024 | B3: 0.0045618017 | C3: 0.00081389227 | D3: -0.0021157097 | E3: -0.0014346438 | F3: 0.0058348398 | G3: 0.012956657 | H3: 0.030722605 | I3: 0.009251296 | J3: -0.0021738097 | K3: 0.00012791863 | L3: 0 | M3: 0.0012825875 | N3: 0
A4: 0.0079386769 | B4: 0.011694605 | C4: 0.0035634008 | D4: -0.00064836801 | E4: 0.0063245614 | F4: 0.015599714 | G4: 0.011985728 | H4: 0.029128466 | I4: -0.050158192 | J4: -0.0034848393 | K4: 3.3841984e-05 | L4: 0 | M4: 0.00033680802 | N4: 0
A5: 0.0081071171 | B5: -0.029581005 | C5: 0.011339683 | D5: 0.0070776947 | E5: -0.0054675138 | F5: -0.0041615862 | G5: 0.011400246 | H5: 0.049196286 | I5: -0.027728394 | J5: 0.01276377 | K5: 3.7262107e-09 | L5: 0 | M5: 1.2790655e-08 | N5: 0
A6: -0.0017829102 | B6: 0.01737315 | C6: -0.0079526696 | D6: -0.00044101021 | E6: -0.00071596527 | F6: 0.010874336 | G6: 0.012766229 | H6: -0.0045379114 | I6: -0.040252156 | J6: -0.0011657143 | K6: 7.9622957e-07 | L6: 0 | M6: 2.7419417e-06 | N6: 0
A7: 0.0039362704 | B7: -0.0096227948 | C7: 0.0079068257 | D7: -0.0033082036 | E7: 0.004771704 | F7: 0.0022155584 | G7: 0.012635611 | H7: -0.010734414 | I7: -0.046932758 | J7: -0.0061293065 | K7: 0.00043801327 | L7: 0 | M7: 0.0015062354 | N7: 0
A8: -0.0017421231 | B8: -0.021995012 | C8: 0.0047791871 | D8: 0.0072819017 | E8: -0.0015997993 | F8: 0.0075961307 | G8: 0.011963804 | H8: 0.030739889 | I8: 0.081193306 | J8: 0.0068826866 | K8: 1.5471717e-05 | L8: 0 | M8: 5.2835882e-05 | N8: 0
A9: 0.0072469827 | B9: 0.00046590275 | C9: 0.0033124437 | D9: -0.002163038 | E9: 0.0013975164 | F9: 0.0080853081 | G9: 0.011464503 | H9: 0.024165133 | I9: 0.039893613 | J9: -0.00093952474 | K9: 7.256219e-08 | L9: 0 | M9: 7.553346e-07 | N9: 0
A10: 0.00092317972 | B10: 0.022306377 | C10: -0.0077632074 | D10: 0.0012869666 | E10: 0.0032787662 | F10: -0.0082680848 | G10: 0.010381764 | H10: 0.012528124 | I10: 0.069357062 | J10: -0.00046467901 | K10: 1.4628971e-05 | L10: 0 | M10: 0.0001526301 | N10: 0
A11: -0.00015568745 | B11: -0.01027704 | C11: -0.0013800356 | D11: 0.0063601784 | E11: 0.0010896921 | F11: 0.0067557518 | G11: 0.01103424 | H11: 0.00065364744 | I11: 0.066873936 | J11: 0.0049601218 | K11: 0.00011627605 | L11: 0 | M11: 0.0012102654 | N11: 0
A12: 0.0033201735 | B12: -0.0043510189 | C12: -4.5299758e-05 | D12: 0.00012712574 | E12: -0.002254558 | F12: 0.000990176 | G12: 0.010607817 | H12: 0.0022150482 | I12: 0.038466924 | J12: 0.0024938241 | K12: 3.0948793e-07 | L12: 0 | M12: 3.198023e-06 | N12: 0
... A156: -0.0026108453 | B156: -0.049459531 | C156: 0.0019070804 | D156: -0.022890649 | E156: -0.0035349156 | F156: 0.0068009114 | G156: -0.0051493551 | H156: 0.079399644 | I156: 0.070758789 | J156: -0.020385128 | K156: 0.0011271662 | L156: 0 | M156: 0.00071660115 | N156: 0

Sheet x-form->

Sheet G
B2: (1) 実質GDP | C2: (2) 実質民間設備投資
B5: (3) インフレ率 | C5: (4) 資本財価格
B8: (5) 名目雇用者報酬（時間当たり） | C8: (6) 労働時間
B12: (7) 政策金利 | C12: (8) ソロー残差
B15: (9) 銀行の実質純資産 | C15: (10) 企業の実質純資産
B18: (11) 水害による民間資本毀損率 | C18: (12) 水害による公的資本毀損率

Sheet E
B2: (1) Real GDP | C2: (2) Real investment
B5: (3) GDP deflator | C5: (4) Investment deflator
B8: (5) Nominal wage | C8: (6) Working hours
B12: (7) Policy rate | C12: (8) Measured TFP (Solow residuals)
B15: (9) Real net worth in FI sector | C15: (10) Real net worth in goods-producing sector
B18: (11) Flood-related capital depreciation rate

Sheet Gdata
B1: =ReadMe!G3 -> 29587 | D1: Aggregate | P1: Additional
B2: =ReadMe!G4 -> 43830 | C2: Avg.
C3: Std
B4: Quarter | C4: Q Name | D4: GDP | E4: I | F4: Pi | G4: QC | H4: W | I4: L | J4: R | K4: Solow | L4: NB | M4: NEC | N4: fdr | O4: fdr_p | P4: Business Cycle
B5: 29221 | C5: =YEAR(B5)&"Q"&QUOTIENT(MONTH(B5)-1,3)+1 -> 1980Q1 | P5: 500 | Q5: 0
B6: =EDATE(B5,3) -> 29312 | C6: =YEAR(B6)&"Q"&QUOTIENT(MONTH(B6)-1,3)+1 -> 1980Q2 | P6: 500 | Q6: 0
B7: =EDATE(B6,3) -> 29403 | C7: =YEAR(B7)&"Q"&QUOTIENT(MONTH(B7)-1,3)+1 -> 1980Q3 | P7: 500 | Q7: 0
B8: =EDATE(B7,3) -> 29495 | C8: =YEAR(B8)&"Q"&QUOTIENT(MONTH(B8)-1,3)+1 -> 1980Q4 | P8: 500 | Q8: 0
A9: =RIGHT(YEAR(B9),2) -> 81 | B9: =EDATE(B8,3) -> 29587 | C9: =YEAR(B9)&"Q"&QUOTIENT(MONTH(B9)-1,3)+1 -> 1981Q1 | D9: =LN(l_Output!C7/l_Output!C3)*100 -> 3.296717 | E9: =LN('l_IC,pi_d'!D7/'l_IC,pi_d'!D3)*100 -> 2.7721612 | F9: =LN(l_pi_c!G7/l_pi_c!G3)*100 -> 4.8680664 | G9: =LN('l_IC,pi_d'!F7/'l_IC,pi_d'!F3)*100 -> 3.9687634 | H9: =LN('l_HC,WC'!M7/'l_HC,WC'!M3)*100 -> 8.6786525 | I9: =LN('l_HC,WC'!K7/'l_HC,WC'!K3)*100 -> -0.73343186 | J9: =l_NSR!B7 -> 8.6965703 | K9: =LN(l_Solow!H7/l_Solow!H3)*100 -> 4.0875575 | L9: =LN('l_NB,NEC'!O7/'l_NB,NEC'!O3)*100 -> 9.6122625 | M9: =LN('l_NB,NEC'!P7/'l_NB,NEC'!P3)*100 -> 14.262669 | N9: ='fdr,edr'!S7*10000 -> 0.018811945 | O9: ='fdr,edr (TFP)'!S7*10000 -> 0.18816085 | P9: 500 | Q9: 0
B10: =EDATE(B9,3) -> 29677 | C10: =YEAR(B10)&"Q"&QUOTIENT(MONTH(B10)-1,3)+1 -> 1981Q2 | D10: =LN(l_Output!C8/l_Output!C4)*100 -> 5.115387 | E10: =LN('l_IC,pi_d'!D8/'l_IC,pi_d'!D4)*100 -> 2.1983172 | F10: =LN(l_pi_c!G8/l_pi_c!G4)*100 -> 2.7712212 | G10: =LN('l_IC,pi_d'!F8/'l_IC,pi_d'!F4)*100 -> 1.7348448 | H10: =LN('l_HC,WC'!M8/'l_HC,WC'!M4)*100 -> 9.0083155 | I10: =LN('l_HC,WC'!K8/'l_HC,WC'!K4)*100 -> -0.67763672 | J10: =l_NSR!B8 -> 7.2716017 | K10: =LN(l_Solow!H8/l_Solow!H4)*100 -> 5.1345523 | L10: =LN('l_NB,NEC'!O8/'l_NB,NEC'!O4)*100 -> 16.706818 | M10: =LN('l_NB,NEC'!P8/'l_NB,NEC'!P4)*100 -> 23.730491 | N10: ='fdr,edr'!S8*10000 -> 0.10176172 | O10: ='fdr,edr (TFP)'!S8*10000 -> 1.021931 | P10: 500 | Q10: 0
B11: =EDATE(B10,3) -> 29768 | C11: =YEAR(B11)&"Q"&QUOTIENT(MONTH(B11)-1,3)+1 -> 1981Q3 | D11: =LN(l_Output!C9/l_Output!C5)*100 -> 3.5260051 | E11: =LN('l_IC,pi_d'!D9/'l_IC,pi_d'!D5)*100 -> 3.9366105 | F11: =LN(l_pi_c!G9/l_pi_c!G5)*100 -> 2.1021767 | G11: =LN('l_IC,pi_d'!F9/'l_IC,pi_d'!F5)*100 -> 0.35175004 | H11: =LN('l_HC,WC'!M9/'l_HC,WC'!M5)*100 -> 6.3450647 | I11: =LN('l_HC,WC'!K9/'l_HC,WC'!K5)*100 -> -0.10861854 | J11: =l_NSR!B9 -> 7.4052542 | K11: =LN(l_Solow!H9/l_Solow!H5)*100 -> 2.9328786 | L11: =LN('l_NB,NEC'!O9/'l_NB,NEC'!O5)*100 -> 18.416873 | M11: =LN('l_NB,NEC'!P9/'l_NB,NEC'!P5)*100 -> 23.238006 | N11: ='fdr,edr'!S9*10000 -> 1.2791863 | O11: ='fdr,edr (TFP)'!S9*10000 -> 12.825875 | P11: 500 | Q11: 0
B12: =EDATE(B11,3) -> 29860 | C12: =YEAR(B12)&"Q"&QUOTIENT(MONTH(B12)-1,3)+1 -> 1981Q4 | D12: =LN(l_Output!C10/l_Output!C6)*100 -> 2.0577792 | E12: =LN('l_IC,pi_d'!D10/'l_IC,pi_d'!D6)*100 -> 3.1943465 | F12: =LN(l_pi_c!G10/l_pi_c!G6)*100 -> 1.9813789 | G12: =LN('l_IC,pi_d'!F10/'l_IC,pi_d'!F6)*100 -> 0.53709854 | H12: =LN('l_HC,WC'!M10/'l_HC,WC'!M6)*100 -> 6.4558006 | I12: =LN('l_HC,WC'!K10/'l_HC,WC'!K6)*100 -> 0.52211624 | J12: =l_NSR!B10 -> 6.9960924 | K12: =LN(l_Solow!H10/l_Solow!H6)*100 -> 1.0501934 | L12: =LN('l_NB,NEC'!O10/'l_NB,NEC'!O6)*100 -> 20.14227 | M12: =LN('l_NB,NEC'!P10/'l_NB,NEC'!P6)*100 -> 14.881329 | N12: ='fdr,edr'!S10*10000 -> 0.33841984 | O12: ='fdr,edr (TFP)'!S10*10000 -> 3.3680802 | P12: 500 | Q12: 0
B13: =EDATE(B12,3) -> 29952 | C13: =YEAR(B13)&"Q"&QUOTIENT(MONTH(B13)-1,3)+1 -> 1982Q1 | D13: =LN(l_Output!C11/l_Output!C7)*100 -> 2.6600226 | E13: =LN('l_IC,pi_d'!D11/'l_IC,pi_d'!D7)*100 -> 0.28211899 | F13: =LN(l_pi_c!G11/l_pi_c!G7)*100 -> 2.5136301 | G13: =LN('l_IC,pi_d'!F11/'l_IC,pi_d'!F7)*100 -> 0.99703873 | H13: =LN('l_HC,WC'!M11/'l_HC,WC'!M7)*100 -> 5.5157355 | I13: =LN('l_HC,WC'!K11/'l_HC,WC'!K7)*100 -> 0.15179 | J13: =l_NSR!B11 -> 6.749928 | K13: =LN(l_Solow!H11/l_Solow!H7)*100 -> 2.1625412 | L13: =LN('l_NB,NEC'!O11/'l_NB,NEC'!O7)*100 -> 19.182776 | M13: =LN('l_NB,NEC'!P11/'l_NB,NEC'!P7)*100 -> 8.8392107 | N13: ='fdr,edr'!S11*10000 -> 3.7262107e-05 | O13: ='fdr,edr (TFP)'!S11*10000 -> 0.00012790655 | P13: 500 | Q13: 0
B14: =EDATE(B13,3) -> 30042 | C14: =YEAR(B14)&"Q"&QUOTIENT(MONTH(B14)-1,3)+1 -> 1982Q2 | D14: =LN(l_Output!C12/l_Output!C8)*100 -> 2.2367676 | E14: =LN('l_IC,pi_d'!D12/'l_IC,pi_d'!D8)*100 -> 2.5636109 | F14: =LN(l_pi_c!G12/l_pi_c!G8)*100 -> 1.8546115 | G14: =LN('l_IC,pi_d'!F12/'l_IC,pi_d'!F8)*100 -> 0.35326676 | H14: =LN('l_HC,WC'!M12/'l_HC,WC'!M8)*100 -> 4.9639559 | I14: =LN('l_HC,WC'!K12/'l_HC,WC'!K8)*100 -> -0.12050558 | J14: =l_NSR!B12 -> 7.3249129 | K14: =LN(l_Solow!H12/l_Solow!H8)*100 -> 1.7795581 | L14: =LN('l_NB,NEC'!O12/'l_NB,NEC'!O8)*100 -> 11.469903 | M14: =LN('l_NB,NEC'!P12/'l_NB,NEC'!P8)*100 -> -5.0275832 | N14: ='fdr,edr'!S12*10000 -> 0.0079622957 | O14: ='fdr,edr (TFP)'!S12*10000 -> 0.027419417 | P14: 500 | Q14: 0
B15: =EDATE(B14,3) -> 30133 | C15: =YEAR(B15)&"Q"&QUOTIENT(MONTH(B15)-1,3)+1 -> 1982Q3 | D15: =LN(l_Output!C13/l_Output!C9)*100 -> 2.1175182 | E15: =LN('l_IC,pi_d'!D13/'l_IC,pi_d'!D9)*100 -> 1.1451512 | F15: =LN(l_pi_c!G13/l_pi_c!G9)*100 -> 1.8720083 | G15: =LN('l_IC,pi_d'!F13/'l_IC,pi_d'!F9)*100 -> 1.0625601 | H15: =LN('l_HC,WC'!M13/'l_HC,WC'!M9)*100 -> 4.6020278 | I15: =LN('l_HC,WC'!K13/'l_HC,WC'!K9)*100 -> 0.5001292 | J15: =l_NSR!B13 -> 7.2698315 | K15: =LN(l_Solow!H13/l_Solow!H9)*100 -> 1.3840084 | L15: =LN('l_NB,NEC'!O13/'l_NB,NEC'!O9)*100 -> 7.324201 | M15: =LN('l_NB,NEC'!P13/'l_NB,NEC'!P9)*100 -> -10.645989 | N15: ='fdr,edr'!S13*10000 -> 4.3801327 | O15: ='fdr,edr (TFP)'!S13*10000 -> 15.062354 | P15: 500 | Q15: 0
B16: =EDATE(B15,3) -> 30225 | C16: =YEAR(B16)&"Q"&QUOTIENT(MONTH(B16)-1,3)+1 -> 1982Q4 | D16: =LN(l_Output!C14/l_Output!C10)*100 -> 2.9105452 | E16: =LN('l_IC,pi_d'!D14/'l_IC,pi_d'!D10)*100 -> -2.2238105 | F16: =LN(l_pi_c!G14/l_pi_c!G10)*100 -> 0.90392833 | G16: =LN('l_IC,pi_d'!F14/'l_IC,pi_d'!F10)*100 -> 1.1841387 | H16: =LN('l_HC,WC'!M14/'l_HC,WC'!M10)*100 -> 3.8016694 | I16: =LN('l_HC,WC'!K14/'l_HC,WC'!K10)*100 -> -0.29230687 | J16: =l_NSR!B14 -> 6.9868667 | K16: =LN(l_Solow!H14/l_Solow!H10)*100 -> 2.420761 | L16: =LN('l_NB,NEC'!O14/'l_NB,NEC'!O10)*100 -> 7.4853433 | M16: =LN('l_NB,NEC'!P14/'l_NB,NEC'!P10)*100 -> 2.4891612 | N16: ='fdr,edr'!S14*10000 -> 0.15471717 | O16: ='fdr,edr (TFP)'!S14*10000 -> 0.52835882 | P16: 500 | Q16: 0
B17: =EDATE(B16,3) -> 30317 | C17: =YEAR(B17)&"Q"&QUOTIENT(MONTH(B17)-1,3)+1 -> 1983Q1 | D17: =LN(l_Output!C15/l_Output!C11)*100 -> 1.9864719 | E17: =LN('l_IC,pi_d'!D15/'l_IC,pi_d'!D11)*100 -> 0.7808803 | F17: =LN(l_pi_c!G15/l_pi_c!G11)*100 -> 0.8179149 | G17: =LN('l_IC,pi_d'!F15/'l_IC,pi_d'!F11)*100 -> 0.38141484 | H17: =LN('l_HC,WC'!M15/'l_HC,WC'!M11)*100 -> 5.0263589 | I17: =LN('l_HC,WC'!K15/'l_HC,WC'!K11)*100 -> 0.39419614 | J17: =l_NSR!B15 -> 6.7769241 | K17: =LN(l_Solow!H15/l_Solow!H11)*100 -> 1.0504315 | L17: =LN('l_NB,NEC'!O15/'l_NB,NEC'!O11)*100 -> 4.9822279 | M17: =LN('l_NB,NEC'!P15/'l_NB,NEC'!P11)*100 -> 9.2513619 | N17: ='fdr,edr'!S15*10000 -> 0.0007256219 | O17: ='fdr,edr (TFP)'!S15*10000 -> 0.007553346 | P17: 500 | Q17: 0
B18: =EDATE(B17,3) -> 30407 | C18: =YEAR(B18)&"Q"&QUOTIENT(MONTH(B18)-1,3)+1 -> 1983Q2 | D18: =LN(l_Output!C16/l_Output!C12)*100 -> 2.1592696 | E18: =LN('l_IC,pi_d'!D16/'l_IC,pi_d'!D12)*100 -> 1.2742031 | F18: =LN(l_pi_c!G16/l_pi_c!G12)*100 -> 1.0885239 | G18: =LN('l_IC,pi_d'!F16/'l_IC,pi_d'!F12)*100 -> 0.40036105 | H18: =LN('l_HC,WC'!M16/'l_HC,WC'!M12)*100 -> 3.1121168 | I18: =LN('l_HC,WC'!K16/'l_HC,WC'!K12)*100 -> 0.79366928 | J18: =l_NSR!B16 -> 6.3227234 | K18: =LN(l_Solow!H16/l_Solow!H12)*100 -> 1.120535 | L18: =LN('l_NB,NEC'!O16/'l_NB,NEC'!O12)*100 -> 6.6888314 | M18: =LN('l_NB,NEC'!P16/'l_NB,NEC'!P12)*100 -> 20.212284 | N18: ='fdr,edr'!S16*10000 -> 0.14628971 | O18: ='fdr,edr (TFP)'!S16*10000 -> 1.526301 | Q18: 0
B19: =EDATE(B18,3) -> 30498 | C19: =YEAR(B19)&"Q"&QUOTIENT(MONTH(B19)-1,3)+1 -> 1983Q3 | D19: =LN(l_Output!C17/l_Output!C13)*100 -> 3.1261078 | E19: =LN('l_IC,pi_d'!D17/'l_IC,pi_d'!D13)*100 -> 1.2087785 | F19: =LN(l_pi_c!G17/l_pi_c!G13)*100 -> 0.6793281 | G19: =LN('l_IC,pi_d'!F17/'l_IC,pi_d'!F13)*100 -> -0.52832507 | H19: =LN('l_HC,WC'!M17/'l_HC,WC'!M13)*100 -> 3.5661362 | I19: =LN('l_HC,WC'!K17/'l_HC,WC'!K13)*100 -> 0.42546809 | J19: =l_NSR!B17 -> 6.5962583 | K19: =LN(l_Solow!H17/l_Solow!H13)*100 -> 2.2294779 | L19: =LN('l_NB,NEC'!O17/'l_NB,NEC'!O13)*100 -> 7.8276376 | M19: =LN('l_NB,NEC'!P17/'l_NB,NEC'!P13)*100 -> 31.592953 | N19: ='fdr,edr'!S17*10000 -> 1.1627605 | O19: ='fdr,edr (TFP)'!S17*10000 -> 12.102654 | Q19: 0
B20: =EDATE(B19,3) -> 30590 | C20: =YEAR(B20)&"Q"&QUOTIENT(MONTH(B20)-1,3)+1 -> 1983Q4 | D20: =LN(l_Output!C18/l_Output!C14)*100 -> 2.4106302 | E20: =LN('l_IC,pi_d'!D18/'l_IC,pi_d'!D14)*100 -> 2.9731779 | F20: =LN(l_pi_c!G18/l_pi_c!G14)*100 -> 1.1855578 | G20: =LN('l_IC,pi_d'!F18/'l_IC,pi_d'!F14)*100 -> -1.0107738 | H20: =LN('l_HC,WC'!M18/'l_HC,WC'!M14)*100 -> 2.9055407 | I20: =LN('l_HC,WC'!K18/'l_HC,WC'!K14)*100 -> 0.35999222 | J20: =l_NSR!B18 -> 6.4174308 | K20: =LN(l_Solow!H18/l_Solow!H14)*100 -> 1.7905916 | L20: =LN('l_NB,NEC'!O18/'l_NB,NEC'!O14)*100 -> 4.9751535 | M20: =LN('l_NB,NEC'!P18/'l_NB,NEC'!P14)*100 -> 27.320315 | N20: ='fdr,edr'!S18*10000 -> 0.0030948793 | O20: ='fdr,edr (TFP)'!S18*10000 -> 0.03198023 | Q20: 0
B21: =EDATE(B20,3) -> 30682 | C21: =YEAR(B21)&"Q"&QUOTIENT(MONTH(B21)-1,3)+1 -> 1984Q1 | D21: =LN(l_Output!C19/l_Output!C15)*100 -> 3.035957 | E21: =LN('l_IC,pi_d'!D19/'l_IC,pi_d'!D15)*100 -> 5.5271422 | F21: =LN(l_pi_c!G19/l_pi_c!G15)*100 -> 1.0490767 | G21: =LN('l_IC,pi_d'!F19/'l_IC,pi_d'!F15)*100 -> -1.2716886 | H21: =LN('l_HC,WC'!M19/'l_HC,WC'!M15)*100 -> 2.2097883 | I21: =LN('l_HC,WC'!K19/'l_HC,WC'!K15)*100 -> 1.0686317 | J21: =l_NSR!B19 -> 6.3133616 | K21: =LN(l_Solow!H19/l_Solow!H15)*100 -> 1.9347712 | L21: =LN('l_NB,NEC'!O19/'l_NB,NEC'!O15)*100 -> 38.187069 | M21: =LN('l_NB,NEC'!P19/'l_NB,NEC'!P15)*100 -> 31.703858 | N21: ='fdr,edr'!S19*10000 -> 0.00074510278 | O21: ='fdr,edr (TFP)'!S19*10000 -> 0.0080741185 | Q21: 0
B22: =EDATE(B21,3) -> 30773 | C22: =YEAR(B22)&"Q"&QUOTIENT(MONTH(B22)-1,3)+1 -> 1984Q2 | D22: =LN(l_Output!C20/l_Output!C16)*100 -> 4.076201 | E22: =LN('l_IC,pi_d'!D20/'l_IC,pi_d'!D16)*100 -> 3.8615445 | F22: =LN(l_pi_c!G20/l_pi_c!G16)*100 -> 1.1989803 | G22: =LN('l_IC,pi_d'!F20/'l_IC,pi_d'!F16)*100 -> -0.19495964 | H22: =LN('l_HC,WC'!M20/'l_HC,WC'!M16)*100 -> 4.2942683 | I22: =LN('l_HC,WC'!K20/'l_HC,WC'!K16)*100 -> 0.42079363 | J22: =l_NSR!B20 -> 5.9687111 | K22: =LN(l_Solow!H20/l_Solow!H16)*100 -> 3.4527965 | L22: =LN('l_NB,NEC'!O20/'l_NB,NEC'!O16)*100 -> 47.581958 | M22: =LN('l_NB,NEC'!P20/'l_NB,NEC'!P16)*100 -> 21.40981 | N22: ='fdr,edr'!S20*10000 -> 0.83741228 | O22: ='fdr,edr (TFP)'!S20*10000 -> 9.0863814 | Q22: 0
B23: =EDATE(B22,3) -> 30864 | C23: =YEAR(B23)&"Q"&QUOTIENT(MONTH(B23)-1,3)+1 -> 1984Q3 | D23: =LN(l_Output!C21/l_Output!C17)*100 -> 3.4739641 | E23: =LN('l_IC,pi_d'!D21/'l_IC,pi_d'!D17)*100 -> 7.9604454 | F23: =LN(l_pi_c!G21/l_pi_c!G17)*100 -> 1.6301791 | G23: =LN('l_IC,pi_d'!F21/'l_IC,pi_d'!F17)*100 -> 0.69798083 | H23: =LN('l_HC,WC'!M21/'l_HC,WC'!M17)*100 -> 3.7589327 | I23: =LN('l_HC,WC'!K21/'l_HC,WC'!K17)*100 -> -0.10524092 | J23: =l_NSR!B21 -> 6.2837443 | K23: =LN(l_Solow!H21/l_Solow!H17)*100 -> 3.3117531 | L23: =LN('l_NB,NEC'!O21/'l_NB,NEC'!O17)*100 -> 41.834149 | M23: =LN('l_NB,NEC'!P21/'l_NB,NEC'!P17)*100 -> 14.014149 | N23: ='fdr,edr'!S21*10000 -> 0.39354193 | O23: ='fdr,edr (TFP)'!S21*10000 -> 4.2708745 | Q23: 0
B24: =EDATE(B23,3) -> 30956 | C24: =YEAR(B24)&"Q"&QUOTIENT(MONTH(B24)-1,3)+1 -> 1984Q4 | D24: =LN(l_Output!C22/l_Output!C18)*100 -> 3.156924 | E24: =LN('l_IC,pi_d'!D22/'l_IC,pi_d'!D18)*100 -> 11.173818 | F24: =LN(l_pi_c!G22/l_pi_c!G18)*100 -> 1.9117243 | G24: =LN('l_IC,pi_d'!F22/'l_IC,pi_d'!F18)*100 -> 1.1866407 | H24: =LN('l_HC,WC'!M22/'l_HC,WC'!M18)*100 -> 3.9303724 | I24: =LN('l_HC,WC'!K22/'l_HC,WC'!K18)*100 -> 1.1592971 | J24: =l_NSR!B22 -> 6.3535323 | K24: =LN(l_Solow!H22/l_Solow!H18)*100 -> 2.2301405 | L24: =LN('l_NB,NEC'!O22/'l_NB,NEC'!O18)*100 -> 61.587174 | M24: =LN('l_NB,NEC'!P22/'l_NB,NEC'!P18)*100 -> 15.963998 | N24: ='fdr,edr'!S22*10000 -> 0.0011767324 | O24: ='fdr,edr (TFP)'!S22*10000 -> 0.012721827 | Q24: 0
A25: =RIGHT(YEAR(B25),2) -> 85 | B25: =EDATE(B24,3) -> 31048 | C25: =YEAR(B25)&"Q"&QUOTIENT(MONTH(B25)-1,3)+1 -> 1985Q1 | D25: =LN(l_Output!C23/l_Output!C19)*100 -> 3.2938283 | E25: =LN('l_IC,pi_d'!D23/'l_IC,pi_d'!D19)*100 -> 9.5859077 | F25: =LN(l_pi_c!G23/l_pi_c!G19)*100 -> 1.729712 | G25: =LN('l_IC,pi_d'!F23/'l_IC,pi_d'!F19)*100 -> 1.2110191 | H25: =LN('l_HC,WC'!M23/'l_HC,WC'!M19)*100 -> 5.3673552 | I25: =LN('l_HC,WC'!K23/'l_HC,WC'!K19)*100 -> -1.5730653 | J25: =l_NSR!B23 -> 6.3817538 | K25: =LN(l_Solow!H23/l_Solow!H19)*100 -> 3.994314 | L25: =LN('l_NB,NEC'!O23/'l_NB,NEC'!O19)*100 -> 49.615598 | M25: =LN('l_NB,NEC'!P23/'l_NB,NEC'!P19)*100 -> 10.336728 | N25: ='fdr,edr'!S23*10000 -> 0.022474263 | O25: ='fdr,edr (TFP)'!S23*10000 -> 0.16268931 | Q25: 0
B26: =EDATE(B25,3) -> 31138 | C26: =YEAR(B26)&"Q"&QUOTIENT(MONTH(B26)-1,3)+1 -> 1985Q2 | D26: =LN(l_Output!C24/l_Output!C20)*100 -> 3.393217 | E26: =LN('l_IC,pi_d'!D24/'l_IC,pi_d'!D20)*100 -> 7.3864095 | F26: =LN(l_pi_c!G24/l_pi_c!G20)*100 -> 1.6377352 | G26: =LN('l_IC,pi_d'!F24/'l_IC,pi_d'!F20)*100 -> 0.49525613 | H26: =LN('l_HC,WC'!M24/'l_HC,WC'!M20)*100 -> 3.4990541 | I26: =LN('l_HC,WC'!K24/'l_HC,WC'!K20)*100 -> -0.39948415 | J26: =l_NSR!B24 -> 6.1977519 | K26: =LN(l_Solow!H24/l_Solow!H20)*100 -> 3.265507 | L26: =LN('l_NB,NEC'!O24/'l_NB,NEC'!O20)*100 -> 44.949099 | M26: =LN('l_NB,NEC'!P24/'l_NB,NEC'!P20)*100 -> 14.613948 | N26: ='fdr,edr'!S24*10000 -> 1.2846545 | O26: ='fdr,edr (TFP)'!S24*10000 -> 9.3340517 | Q26: 0
B27: =EDATE(B26,3) -> 31229 | C27: =YEAR(B27)&"Q"&QUOTIENT(MONTH(B27)-1,3)+1 -> 1985Q3 | D27: =LN(l_Output!C25/l_Output!C21)*100 -> 4.1549242 | E27: =LN('l_IC,pi_d'!D25/'l_IC,pi_d'!D21)*100 -> 8.2984879 | F27: =LN(l_pi_c!G25/l_pi_c!G21)*100 -> 1.0064912 | G27: =LN('l_IC,pi_d'!F25/'l_IC,pi_d'!F21)*100 -> -0.0077643672 | H27: =LN('l_HC,WC'!M25/'l_HC,WC'!M21)*100 -> 4.6047286 | I27: =LN('l_HC,WC'!K25/'l_HC,WC'!K21)*100 -> -0.44601423 | J27: =l_NSR!B25 -> 6.3871667 | K27: =LN(l_Solow!H25/l_Solow!H21)*100 -> 3.7861445 | L27: =LN('l_NB,NEC'!O25/'l_NB,NEC'!O21)*100 -> 56.277206 | M27: =LN('l_NB,NEC'!P25/'l_NB,NEC'!P21)*100 -> 13.912145 | N27: ='fdr,edr'!S25*10000 -> 0.66663324 | O27: ='fdr,edr (TFP)'!S25*10000 -> 4.8505742 | P27: 500 | Q27: 0
B28: =EDATE(B27,3) -> 31321 | C28: =YEAR(B28)&"Q"&QUOTIENT(MONTH(B28)-1,3)+1 -> 1985Q4 | D28: =LN(l_Output!C26/l_Output!C22)*100 -> 5.4153789 | E28: =LN('l_IC,pi_d'!D26/'l_IC,pi_d'!D22)*100 -> 6.3427203 | F28: =LN(l_pi_c!G26/l_pi_c!G22)*100 -> 0.72067786 | G28: =LN('l_IC,pi_d'!F26/'l_IC,pi_d'!F22)*100 -> -0.83469028 | H28: =LN('l_HC,WC'!M26/'l_HC,WC'!M22)*100 -> 4.5304726 | I28: =LN('l_HC,WC'!K26/'l_HC,WC'!K22)*100 -> -1.2058157 | J28: =l_NSR!B26 -> 7.4403333 | K28: =LN(l_Solow!H26/l_Solow!H22)*100 -> 5.4100054 | L28: =LN('l_NB,NEC'!O26/'l_NB,NEC'!O22)*100 -> 29.886142 | M28: =LN('l_NB,NEC'!P26/'l_NB,NEC'!P22)*100 -> 12.122801 | N28: ='fdr,edr'!S26*10000 -> 0.040842875 | O28: ='fdr,edr (TFP)'!S26*10000 -> 0.29630704 | P28: 500 | Q28: 0
B29: =EDATE(B28,3) -> 31413 | C29: =YEAR(B29)&"Q"&QUOTIENT(MONTH(B29)-1,3)+1 -> 1986Q1 | D29: =LN(l_Output!C27/l_Output!C23)*100 -> 4.0547095 | E29: =LN('l_IC,pi_d'!D27/'l_IC,pi_d'!D23)*100 -> 4.1143887 | F29: =LN(l_pi_c!G27/l_pi_c!G23)*100 -> 1.2186317 | G29: =LN('l_IC,pi_d'!F27/'l_IC,pi_d'!F23)*100 -> -1.2688331 | H29: =LN('l_HC,WC'!M27/'l_HC,WC'!M23)*100 -> 5.0850821 | I29: =LN('l_HC,WC'!K27/'l_HC,WC'!K23)*100 -> -0.40093833 | J29: =l_NSR!B27 -> 6.2754333 | K29: =LN(l_Solow!H27/l_Solow!H23)*100 -> 3.7236742 | L29: =LN('l_NB,NEC'!O27/'l_NB,NEC'!O23)*100 -> 14.01065 | M29: =LN('l_NB,NEC'!P27/'l_NB,NEC'!P23)*100 -> 18.483226 | N29: ='fdr,edr'!S27*10000 -> 0.00060848468 | O29: ='fdr,edr (TFP)'!S27*10000 -> 0.0025313408 | P29: 500 | Q29: 0
B30: =EDATE(B29,3) -> 31503 | C30: =YEAR(B30)&"Q"&QUOTIENT(MONTH(B30)-1,3)+1 -> 1986Q2 | D30: =LN(l_Output!C28/l_Output!C24)*100 -> 2.4390061 | E30: =LN('l_IC,pi_d'!D28/'l_IC,pi_d'!D24)*100 -> 8.6162632 | F30: =LN(l_pi_c!G28/l_pi_c!G24)*100 -> 1.6050091 | G30: =LN('l_IC,pi_d'!F28/'l_IC,pi_d'!F24)*100 -> -1.1106946 | H30: =LN('l_HC,WC'!M28/'l_HC,WC'!M24)*100 -> 3.8083676 | I30: =LN('l_HC,WC'!K28/'l_HC,WC'!K24)*100 -> -0.53035824 | J30: =l_NSR!B28 -> 4.6293 | K30: =LN(l_Solow!H28/l_Solow!H24)*100 -> 2.3274265 | L30: =LN('l_NB,NEC'!O28/'l_NB,NEC'!O24)*100 -> 18.581521 | M30: =LN('l_NB,NEC'!P28/'l_NB,NEC'!P24)*100 -> 31.849991 | N30: ='fdr,edr'!S28*10000 -> 0.13485414 | O30: ='fdr,edr (TFP)'!S28*10000 -> 0.56335523 | P30: 500 | Q30: 0
B31: =EDATE(B30,3) -> 31594 | C31: =YEAR(B31)&"Q"&QUOTIENT(MONTH(B31)-1,3)+1 -> 1986Q3 | D31: =LN(l_Output!C29/l_Output!C25)*100 -> 1.5976988 | E31: =LN('l_IC,pi_d'!D29/'l_IC,pi_d'!D25)*100 -> 4.0140386 | F31: =LN(l_pi_c!G29/l_pi_c!G25)*100 -> 2.1545448 | G31: =LN('l_IC,pi_d'!F29/'l_IC,pi_d'!F25)*100 -> -1.9514486 | H31: =LN('l_HC,WC'!M29/'l_HC,WC'!M25)*100 -> 3.5981882 | I31: =LN('l_HC,WC'!K29/'l_HC,WC'!K25)*100 -> -0.62031285 | J31: =l_NSR!B29 -> 4.6884667 | K31: =LN(l_Solow!H29/l_Solow!H25)*100 -> 1.7436746 | L31: =LN('l_NB,NEC'!O29/'l_NB,NEC'!O25)*100 -> 34.123214 | M31: =LN('l_NB,NEC'!P29/'l_NB,NEC'!P25)*100 -> 43.146808 | N31: ='fdr,edr'!S29*10000 -> 4.4946044 | O31: ='fdr,edr (TFP)'!S29*10000 -> 18.799125 | P31: 500 | Q31: 0
B32: =EDATE(B31,3) -> 31686 | C32: =YEAR(B32)&"Q"&QUOTIENT(MONTH(B32)-1,3)+1 -> 1986Q4 | D32: =LN(l_Output!C30/l_Output!C26)*100 -> 1.1777353 | E32: =LN('l_IC,pi_d'!D30/'l_IC,pi_d'!D26)*100 -> 4.0306093 | F32: =LN(l_pi_c!G30/l_pi_c!G26)*100 -> 1.4652653 | G32: =LN('l_IC,pi_d'!F30/'l_IC,pi_d'!F26)*100 -> -1.9845137 | H32: =LN('l_HC,WC'!M30/'l_HC,WC'!M26)*100 -> 3.5112953 | I32: =LN('l_HC,WC'!K30/'l_HC,WC'!K26)*100 -> -1.2551567 | J32: =l_NSR!B30 -> 4.2521 | K32: =LN(l_Solow!H30/l_Solow!H26)*100 -> 1.4545508 | L32: =LN('l_NB,NEC'!O30/'l_NB,NEC'!O26)*100 -> 38.550195 | M32: =LN('l_NB,NEC'!P30/'l_NB,NEC'!P26)*100 -> 38.341168 | N32: ='fdr,edr'!S30*10000 -> 0.04607891 | O32: ='fdr,edr (TFP)'!S30*10000 -> 0.19209311 | P32: 500 | Q32: 0
B33: =EDATE(B32,3) -> 31778 | C33: =YEAR(B33)&"Q"&QUOTIENT(MONTH(B33)-1,3)+1 -> 1987Q1 | D33: =LN(l_Output!C31/l_Output!C27)*100 -> 1.4807594 | E33: =LN('l_IC,pi_d'!D31/'l_IC,pi_d'!D27)*100 -> 4.5625476 | F33: =LN(l_pi_c!G31/l_pi_c!G27)*100 -> 0.39861365 | G33: =LN('l_IC,pi_d'!F31/'l_IC,pi_d'!F27)*100 -> -1.8158203 | H33: =LN('l_HC,WC'!M31/'l_HC,WC'!M27)*100 -> 1.7422287 | I33: =LN('l_HC,WC'!K31/'l_HC,WC'!K27)*100 -> -0.091444413 | J33: =l_NSR!B31 -> 4.1998 | K33: =LN(l_Solow!H31/l_Solow!H27)*100 -> 0.57758863 | L33: =LN('l_NB,NEC'!O31/'l_NB,NEC'!O27)*100 -> 72.344522 | M33: =LN('l_NB,NEC'!P31/'l_NB,NEC'!P27)*100 -> 37.333257 | N33: ='fdr,edr'!S31*10000 -> 0.0098800487 | O33: ='fdr,edr (TFP)'!S31*10000 -> 0.03139051 | Q33: 0
B34: =EDATE(B33,3) -> 31868 | C34: =YEAR(B34)&"Q"&QUOTIENT(MONTH(B34)-1,3)+1 -> 1987Q2 | D34: =LN(l_Output!C32/l_Output!C28)*100 -> 3.0186528 | E34: =LN('l_IC,pi_d'!D32/'l_IC,pi_d'!D28)*100 -> 4.1546792 | F34: =LN(l_pi_c!G32/l_pi_c!G28)*100 -> -0.44949298 | G34: =LN('l_IC,pi_d'!F32/'l_IC,pi_d'!F28)*100 -> -2.228216 | H34: =LN('l_HC,WC'!M32/'l_HC,WC'!M28)*100 -> 2.7924887 | I34: =LN('l_HC,WC'!K32/'l_HC,WC'!K28)*100 -> -0.21900774 | J34: =l_NSR!B32 -> 3.4391667 | K34: =LN(l_Solow!H32/l_Solow!H28)*100 -> 1.8348968 | L34: =LN('l_NB,NEC'!O32/'l_NB,NEC'!O28)*100 -> 83.423185 | M34: =LN('l_NB,NEC'!P32/'l_NB,NEC'!P28)*100 -> 32.696784 | N34: ='fdr,edr'!S32*10000 -> 0.81888621 | O34: ='fdr,edr (TFP)'!S32*10000 -> 2.614856 | Q34: 0
B35: =EDATE(B34,3) -> 31959 | C35: =YEAR(B35)&"Q"&QUOTIENT(MONTH(B35)-1,3)+1 -> 1987Q3 | D35: =LN(l_Output!C33/l_Output!C29)*100 -> 4.180343 | E35: =LN('l_IC,pi_d'!D33/'l_IC,pi_d'!D29)*100 -> 6.622639 | F35: =LN(l_pi_c!G33/l_pi_c!G29)*100 -> -0.4085586 | G35: =LN('l_IC,pi_d'!F33/'l_IC,pi_d'!F29)*100 -> -1.4005425 | H35: =LN('l_HC,WC'!M33/'l_HC,WC'!M29)*100 -> 1.3821711 | I35: =LN('l_HC,WC'!K33/'l_HC,WC'!K29)*100 -> 0.58498056 | J35: =l_NSR!B33 -> 3.3747667 | K35: =LN(l_Solow!H33/l_Solow!H29)*100 -> 2.4128633 | L35: =LN('l_NB,NEC'!O33/'l_NB,NEC'!O29)*100 -> 53.863242 | M35: =LN('l_NB,NEC'!P33/'l_NB,NEC'!P29)*100 -> 28.130853 | N35: ='fdr,edr'!S33*10000 -> 2.8761271 | O35: ='fdr,edr (TFP)'!S33*10000 -> 9.2090843 | Q35: 0
B36: =EDATE(B35,3) -> 32051 | C36: =YEAR(B36)&"Q"&QUOTIENT(MONTH(B36)-1,3)+1 -> 1987Q4 | D36: =LN(l_Output!C34/l_Output!C30)*100 -> 5.5926263 | E36: =LN('l_IC,pi_d'!D34/'l_IC,pi_d'!D30)*100 -> 7.0064977 | F36: =LN(l_pi_c!G34/l_pi_c!G30)*100 -> -0.2354861 | G36: =LN('l_IC,pi_d'!F34/'l_IC,pi_d'!F30)*100 -> -0.917259 | H36: =LN('l_HC,WC'!M34/'l_HC,WC'!M30)*100 -> 1.0207388 | I36: =LN('l_HC,WC'!K34/'l_HC,WC'!K30)*100 -> 1.8516297 | J36: =l_NSR!B34 -> 3.6614333 | K36: =LN(l_Solow!H34/l_Solow!H30)*100 -> 2.9760004 | L36: =LN('l_NB,NEC'!O34/'l_NB,NEC'!O30)*100 -> 37.682196 | M36: =LN('l_NB,NEC'!P34/'l_NB,NEC'!P30)*100 -> 18.575808 | N36: ='fdr,edr'!S34*10000 -> 0.13361484 | O36: ='fdr,edr (TFP)'!S34*10000 -> 0.42656479 | Q36: 0
B37: =EDATE(B36,3) -> 32143 | C37: =YEAR(B37)&"Q"&QUOTIENT(MONTH(B37)-1,3)+1 -> 1988Q1 | D37: =LN(l_Output!C35/l_Output!C31)*100 -> 7.0800517 | E37: =LN('l_IC,pi_d'!D35/'l_IC,pi_d'!D31)*100 -> 11.809084 | F37: =LN(l_pi_c!G35/l_pi_c!G31)*100 -> 0.46779474 | G37: =LN('l_IC,pi_d'!F35/'l_IC,pi_d'!F31)*100 -> -0.72541314 | H37: =LN('l_HC,WC'!M35/'l_HC,WC'!M31)*100 -> 0.64163567 | I37: =LN('l_HC,WC'!K35/'l_HC,WC'!K31)*100 -> 2.9741871 | J37: =l_NSR!B35 -> 3.686 | K37: =LN(l_Solow!H35/l_Solow!H31)*100 -> 3.8459373 | L37: =LN('l_NB,NEC'!O35/'l_NB,NEC'!O31)*100 -> 10.948475 | M37: =LN('l_NB,NEC'!P35/'l_NB,NEC'!P31)*100 -> 20.264537 | N37: ='fdr,edr'!S35*10000 -> 0.00019487743 | O37: ='fdr,edr (TFP)'!S35*10000 -> 0.0025358281 | Q37: 0
B38: =EDATE(B37,3) -> 32234 | C38: =YEAR(B38)&"Q"&QUOTIENT(MONTH(B38)-1,3)+1 -> 1988Q2 | D38: =LN(l_Output!C36/l_Output!C32)*100 -> 5.7615167 | E38: =LN('l_IC,pi_d'!D36/'l_IC,pi_d'!D32)*100 -> 13.354511 | F38: =LN(l_pi_c!G36/l_pi_c!G32)*100 -> 0.39600923 | G38: =LN('l_IC,pi_d'!F36/'l_IC,pi_d'!F32)*100 -> -0.079298519 | H38: =LN('l_HC,WC'!M36/'l_HC,WC'!M32)*100 -> 3.8575027 | I38: =LN('l_HC,WC'!K36/'l_HC,WC'!K32)*100 -> 0.22966159 | J38: =l_NSR!B36 -> 3.5175667 | K38: =LN(l_Solow!H36/l_Solow!H32)*100 -> 4.1552979 | L38: =LN('l_NB,NEC'!O36/'l_NB,NEC'!O32)*100 -> -12.149433 | M38: =LN('l_NB,NEC'!P36/'l_NB,NEC'!P32)*100 -> 18.626097 | N38: ='fdr,edr'!S36*10000 -> 0.22743185 | O38: ='fdr,edr (TFP)'!S36*10000 -> 2.981655 | Q38: 0
B39: =EDATE(B38,3) -> 32325 | C39: =YEAR(B39)&"Q"&QUOTIENT(MONTH(B39)-1,3)+1 -> 1988Q3 | D39: =LN(l_Output!C37/l_Output!C33)*100 -> 5.7634393 | E39: =LN('l_IC,pi_d'!D37/'l_IC,pi_d'!D33)*100 -> 16.935978 | F39: =LN(l_pi_c!G37/l_pi_c!G33)*100 -> 0.53325625 | G39: =LN('l_IC,pi_d'!F37/'l_IC,pi_d'!F33)*100 -> -0.33895656 | H39: =LN('l_HC,WC'!M37/'l_HC,WC'!M33)*100 -> 4.8048741 | I39: =LN('l_HC,WC'!K37/'l_HC,WC'!K33)*100 -> 0.7200512 | J39: =l_NSR!B37 -> 3.9766 | K39: =LN(l_Solow!H37/l_Solow!H33)*100 -> 3.7702477 | L39: =LN('l_NB,NEC'!O37/'l_NB,NEC'!O33)*100 -> -6.9001981 | M39: =LN('l_NB,NEC'!P37/'l_NB,NEC'!P33)*100 -> 14.513579 | N39: ='fdr,edr'!S37*10000 -> 0.15885252 | O39: ='fdr,edr (TFP)'!S37*10000 -> 2.0975875 | Q39: 0
B40: =EDATE(B39,3) -> 32417 | C40: =YEAR(B40)&"Q"&QUOTIENT(MONTH(B40)-1,3)+1 -> 1988Q4 | D40: =LN(l_Output!C38/l_Output!C34)*100 -> 4.3002685 | E40: =LN('l_IC,pi_d'!D38/'l_IC,pi_d'!D34)*100 -> 18.057692 | F40: =LN(l_pi_c!G38/l_pi_c!G34)*100 -> 1.0398713 | G40: =LN('l_IC,pi_d'!F38/'l_IC,pi_d'!F34)*100 -> -0.37371655 | H40: =LN('l_HC,WC'!M38/'l_HC,WC'!M34)*100 -> 5.6298863 | I40: =LN('l_HC,WC'!K38/'l_HC,WC'!K34)*100 -> -0.34763427 | J40: =l_NSR!B38 -> 4.1589667 | K40: =LN(l_Solow!H38/l_Solow!H34)*100 -> 3.0662268 | L40: =LN('l_NB,NEC'!O38/'l_NB,NEC'!O34)*100 -> 18.063933 | M40: =LN('l_NB,NEC'!P38/'l_NB,NEC'!P34)*100 -> 28.348148 | N40: ='fdr,edr'!S38*10000 -> 0.033382003 | O40: ='fdr,edr (TFP)'!S38*10000 -> 0.44185114 | Q40: 0
...

Sheet Agg
A1: =ReadMe!G3 -> 29587 | C1: Aggregate | M1: Deviation from average | W1: Level | AB1: Level | AG1: Level
A2: =ReadMe!G4 -> 43830 | B2: Avg. | C2: =AVERAGEIFS(C$6:C$168,$A$6:$A$168,">="&$A$1,$A$6:$A$168,"<"&$A$2) -> 0.00013023228 | D2: =AVERAGEIFS(D$6:D$168,$A$6:$A$168,">="&$A$1,$A$6:$A$168,"<"&$A$2) -> 0.0053968894 | E2: =AVERAGEIFS(E$6:E$168,$A$6:$A$168,">="&$A$1,$A$6:$A$168,"<"&$A$2) -> -0.0010579096 | F2: =AVERAGEIFS(F$6:F$168,$A$6:$A$168,">="&$A$1,$A$6:$A$168,"<"&$A$2) -> 0.0046237673 | G2: =AVERAGEIFS(G$6:G$168,$A$6:$A$168,">="&$A$1,$A$6:$A$168,"<"&$A$2) -> 2.2126388e-05 | H2: =AVERAGEIFS(H$6:H$168,$A$6:$A$168,">="&$A$1,$A$6:$A$168,"<"&$A$2) -> 0.005373064 | I2: =AVERAGEIFS(I$6:I$168,$A$6:$A$168,">="&$A$1,$A$6:$A$168,"<"&$A$2) -> 0.0050635107 | J2: =AVERAGEIFS(J$6:J$168,$A$6:$A$168,">="&$A$1,$A$6:$A$168,"<"&$A$2) -> 0.0025473957 | ... L2: =AVERAGEIFS(L$6:L$168,$A$6:$A$168,">="&$A$1,$A$6:$A$168,"<"&$A$2) -> 0.0029640435 | M2: =AVERAGE(M6:M168) -> -2.3991448e-18 | N2: =AVERAGE(N6:N168) -> 1.7792036e-18 | O2: =AVERAGE(O6:O168) -> 9.9246199e-19 | P2: =AVERAGE(P6:P168) -> 0 | Q2: =AVERAGE(Q6:Q168) -> -1.8181236e-18 | R2: =AVERAGE(R6:R168) -> -3.6974074e-18 | S2: =AVERAGE(S6:S168) -> 2.0905642e-18 | T2: =AVERAGE(T6:T168) -> 1.7703075e-17 | ... Z2: =AVERAGE(Z6:Z168) -> 6.9965905e-05 | AB2: =AVERAGE(AB6:AB168) -> 0.0053982753 | AC2: =AVERAGE(AC6:AC168) -> 0.0017674491 | AD2: =AVERAGE(AD6:AD168) -> 0.008807976 | AE2: =AVERAGE(AE6:AE168) -> 0.0012818179 | AG2: =AVERAGE(AG6:AG168) -> 3.1136062e-19 | AH2: =AVERAGE(AH6:AH168) -> 1.4122428e-18 | AI2: =AVERAGE(AI6:AI168) -> 0 | AJ2: =AVERAGE(AJ6:AJ168) -> -6.6720134e-19
B3: Std | C3: =_xlfn.STDEV.S(C6:C168) -> 0.0047735265 | D3: =_xlfn.STDEV.S(D6:D168) -> 0.023496297 | E3: =_xlfn.STDEV.S(E6:E168) -> 0.0046391663 | F3: =_xlfn.STDEV.S(F6:F168) -> 0.012438568 | G3: =_xlfn.STDEV.S(G6:G168) -> 0.0093981957 | H3: =_xlfn.STDEV.S(H6:H168) -> 0.011857607 | I3: =_xlfn.STDEV.S(I6:I168) -> 0.0073769186 | J3: =_xlfn.STDEV.S(J6:J168) -> 0.13684142 | ... Z3: =_xlfn.STDEV.S(Z6:Z168) -> 0.00049551165 | AB3: =_xlfn.STDEV.S(AB6:AB168) -> 0.0064607331 | AC3: =_xlfn.STDEV.S(AC6:AC168) -> 0.01204077 | AD3: =_xlfn.STDEV.S(AD6:AD168) -> 0.0095570974 | AE3: =_xlfn.STDEV.S(AE6:AE168) -> 0.0082923845 | AG3: =_xlfn.STDEV.S(AG6:AG168) -> 0.0064607331 | AH3: =_xlfn.STDEV.S(AH6:AH168) -> 0.01204077 | AI3: =_xlfn.STDEV.S(AI6:AI168) -> 0.0095570974 | AJ3: =_xlfn.STDEV.S(AJ6:AJ168) -> 0.0082923845
A4: Quarter | B4: Q Name | C4: l_pi_c | D4: l_IC | E4: l_pi_d | F4: l_Output | G4: l_HC | H4: l_WC | I4: l_NSR | J4: l_NB | K4: l_NEC | L4: l_Solow | M4: l_pi_c | N4: l_IC | O4: l_pi_d | P4: l_Output | Q4: l_HC | R4: l_WC | S4: l_NSR | T4: l_NB | U4: l_NEC | V4: l_Solow | W4: fdr | X4: edr | Y4: fdr_p | Z4: edr_p | AB4: nu_fdr | AC4: nu_edr | AD4: nu_fdr_p | AE4: nu_edr_p | AG4: nu_fdr | AH4: nu_edr | AI4: nu_fdr_p | AJ4: nu_edr_p
A5: 29221 | B5: =YEAR(A5)&"Q"&QUOTIENT(MONTH(A5)-1,3)+1 -> 1980Q1 | M5: =IF(AND($A5>=$A$1,$A5<$A$2),C5-C$2,"") | N5: =IF(AND($A5>=$A$1,$A5<$A$2),D5-D$2,"") | O5: =IF(AND($A5>=$A$1,$A5<$A$2),E5-E$2,"") | P5: =IF(AND($A5>=$A$1,$A5<$A$2),F5-F$2,"") | Q5: =IF(AND($A5>=$A$1,$A5<$A$2),G5-G$2,"") | R5: =IF(AND($A5>=$A$1,$A5<$A$2),H5-H$2,"") | S5: =IF(AND($A5>=$A$1,$A5<$A$2),I5-I$2,"") | T5: =IF(AND($A5>=$A$1,$A5<$A$2),J5-J$2,"") | U5: =IF(AND($A5>=$A$1,$A5<$A$2),K5-K$2,"")
A6: =EDATE(A5,3) -> 29312 | B6: =YEAR(A6)&"Q"&QUOTIENT(MONTH(A6)-1,3)+1 -> 1980Q2 | C6: =l_pi_c!H4 -> 0.02590596 | D6: ='l_IC,pi_d'!E4 -> 0.0056935603 | E6: ='l_IC,pi_d'!G4 -> 0.019766327 | F6: =l_Output!D4 -> -0.0097713917 | G6: ='l_HC,WC'!L4 -> 0.0014711655 | H6: ='l_HC,WC'!N4 -> 0.018468565 | I6: =l_NSR!C4 -> 0.030425911 | J6: ='l_NB,NEC'!Q4 -> 0.0041926592 | K6: ='l_NB,NEC'!R4 -> 0.018390464 | L6: =l_Solow!I4 -> -0.004841788 | M6: =IF(AND($A6>=$A$1,$A6<$A$2),C6-C$2,"") | N6: =IF(AND($A6>=$A$1,$A6<$A$2),D6-D$2,"") | O6: =IF(AND($A6>=$A$1,$A6<$A$2),E6-E$2,"") | P6: =IF(AND($A6>=$A$1,$A6<$A$2),F6-F$2,"") | Q6: =IF(AND($A6>=$A$1,$A6<$A$2),G6-G$2,"") | R6: =IF(AND($A6>=$A$1,$A6<$A$2),H6-H$2,"") | S6: =IF(AND($A6>=$A$1,$A6<$A$2),I6-I$2,"") | T6: =IF(AND($A6>=$A$1,$A6<$A$2),J6-J$2,"") | ... V6: =IF(AND($A6>=$A$1,$A6<$A$2),L6-L$2,"")
A7: =EDATE(A6,3) -> 29403 | B7: =YEAR(A7)&"Q"&QUOTIENT(MONTH(A7)-1,3)+1 -> 1980Q3 | C7: =l_pi_c!H5 -> 0.010582979 | D7: ='l_IC,pi_d'!E5 -> -0.0074242424 | E7: ='l_IC,pi_d'!G5 -> 0.01358693 | F7: =l_Output!D5 -> 0.018401877 | G7: ='l_HC,WC'!L5 -> -0.0071026992 | H7: ='l_HC,WC'!N5 -> 0.037840412 | I7: =l_NSR!C5 -> 0.029472845 | J7: ='l_NB,NEC'!Q5 -> 0.016169455 | K7: ='l_NB,NEC'!R5 -> 0.028829053 | L7: =l_Solow!I5 -> 0.022806971 | M7: =IF(AND($A7>=$A$1,$A7<$A$2),C7-C$2,"") | N7: =IF(AND($A7>=$A$1,$A7<$A$2),D7-D$2,"") | O7: =IF(AND($A7>=$A$1,$A7<$A$2),E7-E$2,"") | P7: =IF(AND($A7>=$A$1,$A7<$A$2),F7-F$2,"") | Q7: =IF(AND($A7>=$A$1,$A7<$A$2),G7-G$2,"") | R7: =IF(AND($A7>=$A$1,$A7<$A$2),H7-H$2,"") | S7: =IF(AND($A7>=$A$1,$A7<$A$2),I7-I$2,"") | T7: =IF(AND($A7>=$A$1,$A7<$A$2),J7-J$2,"") | ... V7: =IF(AND($A7>=$A$1,$A7<$A$2),L7-L$2,"")
A8: =EDATE(A7,3) -> 29495 | B8: =YEAR(A8)&"Q"&QUOTIENT(MONTH(A8)-1,3)+1 -> 1980Q4 | C8: =l_pi_c!H6 -> 0.0092768876 | D8: ='l_IC,pi_d'!E6 -> 0.024514135 | E8: ='l_IC,pi_d'!G6 -> 0.00065200617 | F8: =l_Output!D6 -> 0.018657658 | G8: ='l_HC,WC'!L6 -> 3.9340002e-05 | H8: ='l_HC,WC'!N6 -> 0.019865419 | I8: =l_NSR!C6 -> 0.024628189 | J8: ='l_NB,NEC'!Q6 -> 0.014421895 | K8: ='l_NB,NEC'!R6 -> 0.04806148 | L8: =l_Solow!I6 -> 0.018306056 | M8: =IF(AND($A8>=$A$1,$A8<$A$2),C8-C$2,"") | N8: =IF(AND($A8>=$A$1,$A8<$A$2),D8-D$2,"") | O8: =IF(AND($A8>=$A$1,$A8<$A$2),E8-E$2,"") | P8: =IF(AND($A8>=$A$1,$A8<$A$2),F8-F$2,"") | Q8: =IF(AND($A8>=$A$1,$A8<$A$2),G8-G$2,"") | R8: =IF(AND($A8>=$A$1,$A8<$A$2),H8-H$2,"") | S8: =IF(AND($A8>=$A$1,$A8<$A$2),I8-I$2,"") | T8: =IF(AND($A8>=$A$1,$A8<$A$2),J8-J$2,"") | ... V8: =IF(AND($A8>=$A$1,$A8<$A$2),L8-L$2,"")
A9: =EDATE(A8,3) -> 29587 | B9: =YEAR(A9)&"Q"&QUOTIENT(MONTH(A9)-1,3)+1 -> 1981Q1 | C9: =l_pi_c!H7 -> 0.0029148367 | D9: ='l_IC,pi_d'!E7 -> 0.0049381591 | E9: ='l_IC,pi_d'!G7 -> 0.0056823711 | F9: =l_Output!D7 -> 0.0056790277 | G9: ='l_HC,WC'!L7 -> -0.0017421249 | H9: ='l_HC,WC'!N7 -> 0.010612129 | I9: =l_NSR!C7 -> 0.021066341 | J9: ='l_NB,NEC'!Q7 -> 0.061338615 | K9: ='l_NB,NEC'!R7 -> 0.047345692 | L9: =l_Solow!I7 -> 0.0046043361 | M9: =IF(AND($A9>=$A$1,$A9<$A$2),C9-C$2,"") -> 0.0027846044 | N9: =IF(AND($A9>=$A$1,$A9<$A$2),D9-D$2,"") -> -0.00045873031 | O9: =IF(AND($A9>=$A$1,$A9<$A$2),E9-E$2,"") -> 0.0067402807 | P9: =IF(AND($A9>=$A$1,$A9<$A$2),F9-F$2,"") -> 0.0010552605 | Q9: =IF(AND($A9>=$A$1,$A9<$A$2),G9-G$2,"") -> -0.0017642513 | R9: =IF(AND($A9>=$A$1,$A9<$A$2),H9-H$2,"") -> 0.0052390651 | S9: =IF(AND($A9>=$A$1,$A9<$A$2),I9-I$2,"") -> 0.016002831 | T9: =IF(AND($A9>=$A$1,$A9<$A$2),J9-J$2,"") -> 0.05879122 | ... V9: =IF(AND($A9>=$A$1,$A9<$A$2),L9-L$2,"") -> 0.0016402926 | W9: ='fdr,edr'!S7 -> 1.8811945e-06 | X9: ='fdr,edr'!T7 -> 0 | Y9: ='fdr,edr (TFP)'!S7 -> 1.8816085e-05 | Z9: ='fdr,edr (TFP)'!T7 -> 0 | AB9: =SQRT(W9) -> 0.0013715664 | AC9: =SQRT(X9) -> 0 | AD9: =SQRT(Y9) -> 0.0043377512 | AE9: =SQRT(Z9) -> 0 | AG9: =AB9-AB$2 -> -0.0040267089 | AH9: =AC9-AC$2 -> -0.0017674491 | AI9: =AD9-AD$2 -> -0.0044702248 | AJ9: =AE9-AE$2 -> -0.0012818179
A10: =EDATE(A9,3) -> 29677 | B10: =YEAR(A10)&"Q"&QUOTIENT(MONTH(A10)-1,3)+1 -> 1981Q2 | C10: =l_pi_c!H8 -> 0.0049375082 | D10: ='l_IC,pi_d'!E8 -> -4.4879673e-05 | E10: ='l_IC,pi_d'!G8 -> -0.0025728595 | F10: =l_Output!D8 -> 0.0084153075 | G10: ='l_HC,WC'!L8 -> 0.0020291169 | H10: ='l_HC,WC'!N8 -> 0.021765195 | I10: =l_NSR!C8 -> 0.01770332 | J10: ='l_NB,NEC'!Q8 -> 0.075138219 | K10: ='l_NB,NEC'!R8 -> 0.11306869 | L10: =l_Solow!I8 -> 0.0056281602 | M10: =IF(AND($A10>=$A$1,$A10<$A$2),C10-C$2,"") -> 0.0048072759 | N10: =IF(AND($A10>=$A$1,$A10<$A$2),D10-D$2,"") -> -0.0054417691 | O10: =IF(AND($A10>=$A$1,$A10<$A$2),E10-E$2,"") -> -0.0015149499 | P10: =IF(AND($A10>=$A$1,$A10<$A$2),F10-F$2,"") -> 0.0037915402 | Q10: =IF(AND($A10>=$A$1,$A10<$A$2),G10-G$2,"") -> 0.0020069905 | R10: =IF(AND($A10>=$A$1,$A10<$A$2),H10-H$2,"") -> 0.016392131 | S10: =IF(AND($A10>=$A$1,$A10<$A$2),I10-I$2,"") -> 0.012639809 | T10: =IF(AND($A10>=$A$1,$A10<$A$2),J10-J$2,"") -> 0.072590823 | ... V10: =IF(AND($A10>=$A$1,$A10<$A$2),L10-L$2,"") -> 0.0026641167 | W10: ='fdr,edr'!S8 -> 1.0176172e-05 | X10: ='fdr,edr'!T8 -> 0 | Y10: ='fdr,edr (TFP)'!S8 -> 0.0001021931 | Z10: ='fdr,edr (TFP)'!T8 -> 0 | AB10: =SQRT(W10) -> 0.0031900112 | AC10: =SQRT(X10) -> 0 | AD10: =SQRT(Y10) -> 0.01010906 | AE10: =SQRT(Z10) -> 0 | AG10: =AB10-AB$2 -> -0.0022082641 | AH10: =AC10-AC$2 -> -0.0017674491 | AI10: =AD10-AD$2 -> 0.0013010842 | AJ10: =AE10-AE$2 -> -0.0012818179
A11: =EDATE(A10,3) -> 29768 | B11: =YEAR(A11)&"Q"&QUOTIENT(MONTH(A11)-1,3)+1 -> 1981Q3 | C11: =l_pi_c!H9 -> 0.0038925346 | D11: ='l_IC,pi_d'!E9 -> 0.0099586911 | E11: ='l_IC,pi_d'!G9 -> -0.00024401736 | F11: =l_Output!D9 -> 0.0025080576 | G11: ='l_HC,WC'!L9 -> -0.0014125174 | H11: ='l_HC,WC'!N9 -> 0.011207904 | I11: =l_NSR!C9 -> 0.018020168 | J11: ='l_NB,NEC'!Q9 -> 0.03327 | K11: ='l_NB,NEC'!R9 -> 0.0239042 | L11: =l_Solow!I9 -> 0.0007902338 | M11: =IF(AND($A11>=$A$1,$A11<$A$2),C11-C$2,"") -> 0.0037623024 | N11: =IF(AND($A11>=$A$1,$A11<$A$2),D11-D$2,"") -> 0.0045618017 | O11: =IF(AND($A11>=$A$1,$A11<$A$2),E11-E$2,"") -> 0.00081389227 | P11: =IF(AND($A11>=$A$1,$A11<$A$2),F11-F$2,"") -> -0.0021157097 | Q11: =IF(AND($A11>=$A$1,$A11<$A$2),G11-G$2,"") -> -0.0014346438 | R11: =IF(AND($A11>=$A$1,$A11<$A$2),H11-H$2,"") -> 0.0058348398 | S11: =IF(AND($A11>=$A$1,$A11<$A$2),I11-I$2,"") -> 0.012956657 | T11: =IF(AND($A11>=$A$1,$A11<$A$2),J11-J$2,"") -> 0.030722605 | ... V11: =IF(AND($A11>=$A$1,$A11<$A$2),L11-L$2,"") -> -0.0021738097 | W11: ='fdr,edr'!S9 -> 0.00012791863 | X11: ='fdr,edr'!T9 -> 0 | Y11: ='fdr,edr (TFP)'!S9 -> 0.0012825875 | Z11: ='fdr,edr (TFP)'!T9 -> 0 | AB11: =SQRT(W11) -> 0.011310112 | AC11: =SQRT(X11) -> 0 | AD11: =SQRT(Y11) -> 0.035813231 | AE11: =SQRT(Z11) -> 0 | AG11: =AB11-AB$2 -> 0.0059118364 | AH11: =AC11-AC$2 -> -0.0017674491 | AI11: =AD11-AD$2 -> 0.027005255 | AJ11: =AE11-AE$2 -> -0.0012818179
A12: =EDATE(A11,3) -> 29860 | B12: =YEAR(A12)&"Q"&QUOTIENT(MONTH(A12)-1,3)+1 -> 1981Q4 | C12: =l_pi_c!H10 -> 0.0080689092 | D12: ='l_IC,pi_d'!E10 -> 0.017091494 | E12: ='l_IC,pi_d'!G10 -> 0.0025054911 | F12: =l_Output!D10 -> 0.0039753993 | G12: ='l_HC,WC'!L10 -> 0.0063466878 | H12: ='l_HC,WC'!N10 -> 0.020972778 | I12: =l_NSR!C10 -> 0.017049239 | J12: ='l_NB,NEC'!Q10 -> 0.031675862 | K12: ='l_NB,NEC'!R10 -> -0.035505288 | L12: =l_Solow!I10 -> -0.00052079572 | M12: =IF(AND($A12>=$A$1,$A12<$A$2),C12-C$2,"") -> 0.0079386769 | N12: =IF(AND($A12>=$A$1,$A12<$A$2),D12-D$2,"") -> 0.011694605 | O12: =IF(AND($A12>=$A$1,$A12<$A$2),E12-E$2,"") -> 0.0035634008 | P12: =IF(AND($A12>=$A$1,$A12<$A$2),F12-F$2,"") -> -0.00064836801 | Q12: =IF(AND($A12>=$A$1,$A12<$A$2),G12-G$2,"") -> 0.0063245614 | R12: =IF(AND($A12>=$A$1,$A12<$A$2),H12-H$2,"") -> 0.015599714 | S12: =IF(AND($A12>=$A$1,$A12<$A$2),I12-I$2,"") -> 0.011985728 | T12: =IF(AND($A12>=$A$1,$A12<$A$2),J12-J$2,"") -> 0.029128466 | ... V12: =IF(AND($A12>=$A$1,$A12<$A$2),L12-L$2,"") -> -0.0034848393 | W12: ='fdr,edr'!S10 -> 3.3841984e-05 | X12: ='fdr,edr'!T10 -> 0 | Y12: ='fdr,edr (TFP)'!S10 -> 0.00033680802 | Z12: ='fdr,edr (TFP)'!T10 -> 0 | AB12: =SQRT(W12) -> 0.0058173863 | AC12: =SQRT(X12) -> 0 | AD12: =SQRT(Y12) -> 0.01835233 | AE12: =SQRT(Z12) -> 0 | AG12: =AB12-AB$2 -> 0.00041911099 | AH12: =AC12-AC$2 -> -0.0017674491 | AI12: =AD12-AD$2 -> 0.0095443542 | AJ12: =AE12-AE$2 -> -0.0012818179
A13: =EDATE(A12,3) -> 29952 | B13: =YEAR(A13)&"Q"&QUOTIENT(MONTH(A13)-1,3)+1 -> 1982Q1 | C13: =l_pi_c!H11 -> 0.0082373494 | D13: ='l_IC,pi_d'!E11 -> -0.024184116 | E13: ='l_IC,pi_d'!G11 -> 0.010281773 | F13: =l_Output!D11 -> 0.011701462 | G13: ='l_HC,WC'!L11 -> -0.0054453874 | H13: ='l_HC,WC'!N11 -> 0.0012114778 | I13: =l_NSR!C11 -> 0.016463756 | J13: ='l_NB,NEC'!Q11 -> 0.051743682 | K13: ='l_NB,NEC'!R11 -> -0.013075491 | L13: =l_Solow!I11 -> 0.015727813 | M13: =IF(AND($A13>=$A$1,$A13<$A$2),C13-C$2,"") -> 0.0081071171 | N13: =IF(AND($A13>=$A$1,$A13<$A$2),D13-D$2,"") -> -0.029581005 | O13: =IF(AND($A13>=$A$1,$A13<$A$2),E13-E$2,"") -> 0.011339683 | P13: =IF(AND($A13>=$A$1,$A13<$A$2),F13-F$2,"") -> 0.0070776947 | Q13: =IF(AND($A13>=$A$1,$A13<$A$2),G13-G$2,"") -> -0.0054675138 | R13: =IF(AND($A13>=$A$1,$A13<$A$2),H13-H$2,"") -> -0.0041615862 | S13: =IF(AND($A13>=$A$1,$A13<$A$2),I13-I$2,"") -> 0.011400246 | T13: =IF(AND($A13>=$A$1,$A13<$A$2),J13-J$2,"") -> 0.049196286 | ... V13: =IF(AND($A13>=$A$1,$A13<$A$2),L13-L$2,"") -> 0.01276377 | W13: ='fdr,edr'!S11 -> 3.7262107e-09 | X13: ='fdr,edr'!T11 -> 0 | Y13: ='fdr,edr (TFP)'!S11 -> 1.2790655e-08 | Z13: ='fdr,edr (TFP)'!T11 -> 0 | AB13: =SQRT(W13) -> 6.1042695e-05 | AC13: =SQRT(X13) -> 0 | AD13: =SQRT(Y13) -> 0.00011309578 | AE13: =SQRT(Z13) -> 0 | AG13: =AB13-AB$2 -> -0.0053372326 | AH13: =AC13-AC$2 -> -0.0017674491 | AI13: =AD13-AD$2 -> -0.0086948802 | AJ13: =AE13-AE$2 -> -0.0012818179
A14: =EDATE(A13,3) -> 30042 | B14: =YEAR(A14)&"Q"&QUOTIENT(MONTH(A14)-1,3)+1 -> 1982Q2 | C14: =l_pi_c!H12 -> -0.0016526779 | D14: ='l_IC,pi_d'!E12 -> 0.022770039 | E14: ='l_IC,pi_d'!G12 -> -0.0090105792 | F14: =l_Output!D12 -> 0.004182757 | G14: ='l_HC,WC'!L12 -> -0.00069383888 | H14: ='l_HC,WC'!N12 -> 0.0162474 | I14: =l_NSR!C12 -> 0.01782974 | J14: ='l_NB,NEC'!Q12 -> -0.0019905157 | K14: ='l_NB,NEC'!R12 -> -0.025599253 | L14: =l_Solow!I12 -> 0.0017983292 | M14: =IF(AND($A14>=$A$1,$A14<$A$2),C14-C$2,"") -> -0.0017829102 | N14: =IF(AND($A14>=$A$1,$A14<$A$2),D14-D$2,"") -> 0.01737315 | O14: =IF(AND($A14>=$A$1,$A14<$A$2),E14-E$2,"") -> -0.0079526696 | P14: =IF(AND($A14>=$A$1,$A14<$A$2),F14-F$2,"") -> -0.00044101021 | Q14: =IF(AND($A14>=$A$1,$A14<$A$2),G14-G$2,"") -> -0.00071596527 | R14: =IF(AND($A14>=$A$1,$A14<$A$2),H14-H$2,"") -> 0.010874336 | S14: =IF(AND($A14>=$A$1,$A14<$A$2),I14-I$2,"") -> 0.012766229 | T14: =IF(AND($A14>=$A$1,$A14<$A$2),J14-J$2,"") -> -0.0045379114 | ... V14: =IF(AND($A14>=$A$1,$A14<$A$2),L14-L$2,"") -> -0.0011657143 | W14: ='fdr,edr'!S12 -> 7.9622957e-07 | X14: ='fdr,edr'!T12 -> 0 | Y14: ='fdr,edr (TFP)'!S12 -> 2.7419417e-06 | Z14: ='fdr,edr (TFP)'!T12 -> 0 | AB14: =SQRT(W14) -> 0.00089231697 | AC14: =SQRT(X14) -> 0 | AD14: =SQRT(Y14) -> 0.0016558809 | AE14: =SQRT(Z14) -> 0 | AG14: =AB14-AB$2 -> -0.0045059584 | AH14: =AC14-AC$2 -> -0.0017674491 | AI14: =AD14-AD$2 -> -0.007152095 | AJ14: =AE14-AE$2 -> -0.0012818179
A15: =EDATE(A14,3) -> 30133 | B15: =YEAR(A15)&"Q"&QUOTIENT(MONTH(A15)-1,3)+1 -> 1982Q3 | C15: =l_pi_c!H13 -> 0.0040665027 | D15: ='l_IC,pi_d'!E13 -> -0.0042259054 | E15: ='l_IC,pi_d'!G13 -> 0.0068489161 | F15: =l_Output!D13 -> 0.0013155637 | G15: ='l_HC,WC'!L13 -> 0.0047938304 | H15: ='l_HC,WC'!N13 -> 0.0075886223 | I15: =l_NSR!C13 -> 0.017699121 | J15: ='l_NB,NEC'!Q13 -> -0.0081870184 | K15: ='l_NB,NEC'!R13 -> -0.032279855 | L15: =l_Solow!I13 -> -0.003165263 | M15: =IF(AND($A15>=$A$1,$A15<$A$2),C15-C$2,"") -> 0.0039362704 | N15: =IF(AND($A15>=$A$1,$A15<$A$2),D15-D$2,"") -> -0.0096227948 | O15: =IF(AND($A15>=$A$1,$A15<$A$2),E15-E$2,"") -> 0.0079068257 | P15: =IF(AND($A15>=$A$1,$A15<$A$2),F15-F$2,"") -> -0.0033082036 | Q15: =IF(AND($A15>=$A$1,$A15<$A$2),G15-G$2,"") -> 0.004771704 | R15: =IF(AND($A15>=$A$1,$A15<$A$2),H15-H$2,"") -> 0.0022155584 | S15: =IF(AND($A15>=$A$1,$A15<$A$2),I15-I$2,"") -> 0.012635611 | T15: =IF(AND($A15>=$A$1,$A15<$A$2),J15-J$2,"") -> -0.010734414 | ... V15: =IF(AND($A15>=$A$1,$A15<$A$2),L15-L$2,"") -> -0.0061293065 | W15: ='fdr,edr'!S13 -> 0.00043801327 | X15: ='fdr,edr'!T13 -> 0 | Y15: ='fdr,edr (TFP)'!S13 -> 0.0015062354 | Z15: ='fdr,edr (TFP)'!T13 -> 0 | AB15: =SQRT(W15) -> 0.020928766 | AC15: =SQRT(X15) -> 0 | AD15: =SQRT(Y15) -> 0.038810249 | AE15: =SQRT(Z15) -> 0 | AG15: =AB15-AB$2 -> 0.015530491 | AH15: =AC15-AC$2 -> -0.0017674491 | AI15: =AD15-AD$2 -> 0.030002273 | AJ15: =AE15-AE$2 -> -0.0012818179
A16: =EDATE(A15,3) -> 30225 | B16: =YEAR(A16)&"Q"&QUOTIENT(MONTH(A16)-1,3)+1 -> 1982Q4 | C16: =l_pi_c!H14 -> -0.0016118908 | D16: ='l_IC,pi_d'!E14 -> -0.016598123 | E16: ='l_IC,pi_d'!G14 -> 0.0037212774 | F16: =l_Output!D14 -> 0.011905669 | G16: ='l_HC,WC'!L14 -> -0.0015776729 | H16: ='l_HC,WC'!N14 -> 0.012969195 | I16: =l_NSR!C14 -> 0.017027315 | J16: ='l_NB,NEC'!Q14 -> 0.033287285 | K16: ='l_NB,NEC'!R14 -> 0.09584621 | L16: =l_Solow!I14 -> 0.0098467301 | M16: =IF(AND($A16>=$A$1,$A16<$A$2),C16-C$2,"") -> -0.0017421231 | N16: =IF(AND($A16>=$A$1,$A16<$A$2),D16-D$2,"") -> -0.021995012 | O16: =IF(AND($A16>=$A$1,$A16<$A$2),E16-E$2,"") -> 0.0047791871 | P16: =IF(AND($A16>=$A$1,$A16<$A$2),F16-F$2,"") -> 0.0072819017 | Q16: =IF(AND($A16>=$A$1,$A16<$A$2),G16-G$2,"") -> -0.0015997993 | R16: =IF(AND($A16>=$A$1,$A16<$A$2),H16-H$2,"") -> 0.0075961307 | S16: =IF(AND($A16>=$A$1,$A16<$A$2),I16-I$2,"") -> 0.011963804 | T16: =IF(AND($A16>=$A$1,$A16<$A$2),J16-J$2,"") -> 0.030739889 | ... V16: =IF(AND($A16>=$A$1,$A16<$A$2),L16-L$2,"") -> 0.0068826866 | W16: ='fdr,edr'!S14 -> 1.5471717e-05 | X16: ='fdr,edr'!T14 -> 0 | Y16: ='fdr,edr (TFP)'!S14 -> 5.2835882e-05 | Z16: ='fdr,edr (TFP)'!T14 -> 0 | AB16: =SQRT(W16) -> 0.0039334104 | AC16: =SQRT(X16) -> 0 | AD16: =SQRT(Y16) -> 0.0072688295 | AE16: =SQRT(Z16) -> 0 | AG16: =AB16-AB$2 -> -0.001464865 | AH16: =AC16-AC$2 -> -0.0017674491 | AI16: =AD16-AD$2 -> -0.0015391465 | AJ16: =AE16-AE$2 -> -0.0012818179
A17: =EDATE(A16,3) -> 30317 | B17: =YEAR(A17)&"Q"&QUOTIENT(MONTH(A17)-1,3)+1 -> 1983Q1 | C17: =l_pi_c!H15 -> 0.007377215 | D17: ='l_IC,pi_d'!E15 -> 0.0058627922 | E17: ='l_IC,pi_d'!G15 -> 0.0022545341 | F17: =l_Output!D15 -> 0.0024607292 | G17: ='l_HC,WC'!L15 -> 0.0014196428 | H17: ='l_HC,WC'!N15 -> 0.013458372 | I17: =l_NSR!C15 -> 0.016528014 | J17: ='l_NB,NEC'!Q15 -> 0.026712529 | K17: ='l_NB,NEC'!R15 -> 0.054546516 | L17: =l_Solow!I15 -> 0.0020245188 | M17: =IF(AND($A17>=$A$1,$A17<$A$2),C17-C$2,"") -> 0.0072469827 | N17: =IF(AND($A17>=$A$1,$A17<$A$2),D17-D$2,"") -> 0.00046590275 | O17: =IF(AND($A17>=$A$1,$A17<$A$2),E17-E$2,"") -> 0.0033124437 | P17: =IF(AND($A17>=$A$1,$A17<$A$2),F17-F$2,"") -> -0.002163038 | Q17: =IF(AND($A17>=$A$1,$A17<$A$2),G17-G$2,"") -> 0.0013975164 | R17: =IF(AND($A17>=$A$1,$A17<$A$2),H17-H$2,"") -> 0.0080853081 | S17: =IF(AND($A17>=$A$1,$A17<$A$2),I17-I$2,"") -> 0.011464503 | T17: =IF(AND($A17>=$A$1,$A17<$A$2),J17-J$2,"") -> 0.024165133 | ... V17: =IF(AND($A17>=$A$1,$A17<$A$2),L17-L$2,"") -> -0.00093952474 | W17: ='fdr,edr'!S15 -> 7.256219e-08 | X17: ='fdr,edr'!T15 -> 0 | Y17: ='fdr,edr (TFP)'!S15 -> 7.553346e-07 | Z17: ='fdr,edr (TFP)'!T15 -> 0 | AB17: =SQRT(W17) -> 0.0002693737 | AC17: =SQRT(X17) -> 0 | AD17: =SQRT(Y17) -> 0.00086909988 | AE17: =SQRT(Z17) -> 0 | AG17: =AB17-AB$2 -> -0.0051289016 | AH17: =AC17-AC$2 -> -0.0017674491 | AI17: =AD17-AD$2 -> -0.0079388761 | AJ17: =AE17-AE$2 -> -0.0012818179
A18: =EDATE(A17,3) -> 30407 | B18: =YEAR(A18)&"Q"&QUOTIENT(MONTH(A18)-1,3)+1 -> 1983Q2 | C18: =l_pi_c!H16 -> 0.001053412 | D18: ='l_IC,pi_d'!E16 -> 0.027703267 | E18: ='l_IC,pi_d'!G16 -> -0.008821117 | F18: =l_Output!D16 -> 0.0059107339 | G18: ='l_HC,WC'!L16 -> 0.0033008926 | H18: ='l_HC,WC'!N16 -> -0.0028950208 | I18: =l_NSR!C16 -> 0.015445275 | J18: ='l_NB,NEC'!Q16 -> 0.015075519 | K18: ='l_NB,NEC'!R16 -> 0.084009966 | L18: =l_Solow!I16 -> 0.0024993645 | M18: =IF(AND($A18>=$A$1,$A18<$A$2),C18-C$2,"") -> 0.00092317972 | N18: =IF(AND($A18>=$A$1,$A18<$A$2),D18-D$2,"") -> 0.022306377 | O18: =IF(AND($A18>=$A$1,$A18<$A$2),E18-E$2,"") -> -0.0077632074 | P18: =IF(AND($A18>=$A$1,$A18<$A$2),F18-F$2,"") -> 0.0012869666 | Q18: =IF(AND($A18>=$A$1,$A18<$A$2),G18-G$2,"") -> 0.0032787662 | R18: =IF(AND($A18>=$A$1,$A18<$A$2),H18-H$2,"") -> -0.0082680848 | S18: =IF(AND($A18>=$A$1,$A18<$A$2),I18-I$2,"") -> 0.010381764 | T18: =IF(AND($A18>=$A$1,$A18<$A$2),J18-J$2,"") -> 0.012528124 | ... V18: =IF(AND($A18>=$A$1,$A18<$A$2),L18-L$2,"") -> -0.00046467901 | W18: ='fdr,edr'!S16 -> 1.4628971e-05 | X18: ='fdr,edr'!T16 -> 0 | Y18: ='fdr,edr (TFP)'!S16 -> 0.0001526301 | Z18: ='fdr,edr (TFP)'!T16 -> 0 | AB18: =SQRT(W18) -> 0.0038247838 | AC18: =SQRT(X18) -> 0 | AD18: =SQRT(Y18) -> 0.012354355 | AE18: =SQRT(Z18) -> 0 | AG18: =AB18-AB$2 -> -0.0015734916 | AH18: =AC18-AC$2 -> -0.0017674491 | AI18: =AD18-AD$2 -> 0.0035463794 | AJ18: =AE18-AE$2 -> -0.0012818179
A19: =EDATE(A18,3) -> 30498 | B19: =YEAR(A19)&"Q"&QUOTIENT(MONTH(A19)-1,3)+1 -> 1983Q3 | C19: =l_pi_c!H17 -> -2.5455171e-05 | D19: ='l_IC,pi_d'!E17 -> -0.0048801509 | E19: ='l_IC,pi_d'!G17 -> -0.0024379452 | F19: =l_Output!D17 -> 0.010983946 | G19: ='l_HC,WC'!L17 -> 0.0011118185 | H19: ='l_HC,WC'!N17 -> 0.012128816 | I19: =l_NSR!C17 -> 0.016097751 | J19: ='l_NB,NEC'!Q17 -> 0.0032010432 | K19: ='l_NB,NEC'!R17 -> 0.081526839 | L19: =l_Solow!I17 -> 0.0079241653 | M19: =IF(AND($A19>=$A$1,$A19<$A$2),C19-C$2,"") -> -0.00015568745 | N19: =IF(AND($A19>=$A$1,$A19<$A$2),D19-D$2,"") -> -0.01027704 | O19: =IF(AND($A19>=$A$1,$A19<$A$2),E19-E$2,"") -> -0.0013800356 | P19: =IF(AND($A19>=$A$1,$A19<$A$2),F19-F$2,"") -> 0.0063601784 | Q19: =IF(AND($A19>=$A$1,$A19<$A$2),G19-G$2,"") -> 0.0010896921 | R19: =IF(AND($A19>=$A$1,$A19<$A$2),H19-H$2,"") -> 0.0067557518 | S19: =IF(AND($A19>=$A$1,$A19<$A$2),I19-I$2,"") -> 0.01103424 | T19: =IF(AND($A19>=$A$1,$A19<$A$2),J19-J$2,"") -> 0.00065364744 | ... V19: =IF(AND($A19>=$A$1,$A19<$A$2),L19-L$2,"") -> 0.0049601218 | W19: ='fdr,edr'!S17 -> 0.00011627605 | X19: ='fdr,edr'!T17 -> 0 | Y19: ='fdr,edr (TFP)'!S17 -> 0.0012102654 | Z19: ='fdr,edr (TFP)'!T17 -> 0 | AB19: =SQRT(W19) -> 0.010783137 | AC19: =SQRT(X19) -> 0 | AD19: =SQRT(Y19) -> 0.034788869 | AE19: =SQRT(Z19) -> 0 | AG19: =AB19-AB$2 -> 0.0053848621 | AH19: =AC19-AC$2 -> -0.0017674491 | AI19: =AD19-AD$2 -> 0.025980893 | AJ19: =AE19-AE$2 -> -0.0012818179
A20: =EDATE(A19,3) -> 30590 | B20: =YEAR(A20)&"Q"&QUOTIENT(MONTH(A20)-1,3)+1 -> 1983Q4 | C20: =l_pi_c!H18 -> 0.0034504058 | D20: ='l_IC,pi_d'!E18 -> 0.0010458705 | E20: ='l_IC,pi_d'!G18 -> -0.0011032094 | F20: =l_Output!D18 -> 0.004750893 | G20: ='l_HC,WC'!L18 -> -0.0022324316 | H20: ='l_HC,WC'!N18 -> 0.00636324 | I20: =l_NSR!C18 -> 0.015671327 | J20: ='l_NB,NEC'!Q18 -> 0.0047624439 | K20: ='l_NB,NEC'!R18 -> 0.053119827 | L20: =l_Solow!I18 -> 0.0054578677 | M20: =IF(AND($A20>=$A$1,$A20<$A$2),C20-C$2,"") -> 0.0033201735 | N20: =IF(AND($A20>=$A$1,$A20<$A$2),D20-D$2,"") -> -0.0043510189 | O20: =IF(AND($A20>=$A$1,$A20<$A$2),E20-E$2,"") -> -4.5299758e-05 | P20: =IF(AND($A20>=$A$1,$A20<$A$2),F20-F$2,"") -> 0.00012712574 | Q20: =IF(AND($A20>=$A$1,$A20<$A$2),G20-G$2,"") -> -0.002254558 | R20: =IF(AND($A20>=$A$1,$A20<$A$2),H20-H$2,"") -> 0.000990176 | S20: =IF(AND($A20>=$A$1,$A20<$A$2),I20-I$2,"") -> 0.010607817 | T20: =IF(AND($A20>=$A$1,$A20<$A$2),J20-J$2,"") -> 0.0022150482 | ... V20: =IF(AND($A20>=$A$1,$A20<$A$2),L20-L$2,"") -> 0.0024938241 | W20: ='fdr,edr'!S18 -> 3.0948793e-07 | X20: ='fdr,edr'!T18 -> 0 | Y20: ='fdr,edr (TFP)'!S18 -> 3.198023e-06 | Z20: ='fdr,edr (TFP)'!T18 -> 0 | AB20: =SQRT(W20) -> 0.0005563164 | AC20: =SQRT(X20) -> 0 | AD20: =SQRT(Y20) -> 0.0017883017 | AE20: =SQRT(Z20) -> 0 | AG20: =AB20-AB$2 -> -0.0048419589 | AH20: =AC20-AC$2 -> -0.0017674491 | AI20: =AD20-AD$2 -> -0.0070196743 | AJ20: =AE20-AE$2 -> -0.0012818179
... A164: =EDATE(A163,3) -> 43739 | B164: =YEAR(A164)&"Q"&QUOTIENT(MONTH(A164)-1,3)+1 -> 2019Q4 | C164: =l_pi_c!H162 -> -0.002480613 | D164: ='l_IC,pi_d'!E162 -> -0.044062641 | E164: ='l_IC,pi_d'!G162 -> 0.00084917077 | F164: =l_Output!D162 -> -0.018266882 | G164: ='l_HC,WC'!L162 -> -0.0035127892 | H164: ='l_HC,WC'!N162 -> 0.012173975 | I164: =l_NSR!C162 -> -8.5844387e-05 | J164: ='l_NB,NEC'!Q162 -> 0.081947039 | K164: ='l_NB,NEC'!R162 -> 0.085411693 | L164: =l_Solow!I162 -> -0.017421084 | M164: =IF(AND($A164>=$A$1,$A164<$A$2),C164-C$2,"") -> -0.0026108453 | N164: =IF(AND($A164>=$A$1,$A164<$A$2),D164-D$2,"") -> -0.049459531 | O164: =IF(AND($A164>=$A$1,$A164<$A$2),E164-E$2,"") -> 0.0019070804 | P164: =IF(AND($A164>=$A$1,$A164<$A$2),F164-F$2,"") -> -0.022890649 | Q164: =IF(AND($A164>=$A$1,$A164<$A$2),G164-G$2,"") -> -0.0035349156 | R164: =IF(AND($A164>=$A$1,$A164<$A$2),H164-H$2,"") -> 0.0068009114 | S164: =IF(AND($A164>=$A$1,$A164<$A$2),I164-I$2,"") -> -0.0051493551 | T164: =IF(AND($A164>=$A$1,$A164<$A$2),J164-J$2,"") -> 0.079399644 | ... V164: =IF(AND($A164>=$A$1,$A164<$A$2),L164-L$2,"") -> -0.020385128 | W164: ='fdr,edr'!S162 -> 0.0011271662 | X164: ='fdr,edr'!T162 -> 0 | Y164: ='fdr,edr (TFP)'!S162 -> 0.00071660115 | Z164: ='fdr,edr (TFP)'!T162 -> 0 | AB164: =SQRT(W164) -> 0.033573296 | AC164: =SQRT(X164) -> 0 | AD164: =SQRT(Y164) -> 0.026769407 | AE164: =SQRT(Z164) -> 0 | AG164: =AB164-AB$2 -> 0.028175021 | AH164: =AC164-AC$2 -> -0.0017674491 | AI164: =AD164-AD$2 -> 0.017961431 | AJ164: =AE164-AE$2 -> -0.0012818179
A165: =EDATE(A164,3) -> 43831 | B165: =YEAR(A165)&"Q"&QUOTIENT(MONTH(A165)-1,3)+1 -> 2020Q1 | C165: =l_pi_c!H163 -> 0.00056170954 | D165: ='l_IC,pi_d'!E163 -> 0.012346076 | E165: ='l_IC,pi_d'!G163 -> 0.0033306458 | F165: =l_Output!D163 -> -0.0045584806 | G165: ='l_HC,WC'!L163 -> -0.0057101229 | H165: ='l_HC,WC'!N163 -> 0.0088783463 | I165: =l_NSR!C163 -> -7.9176069e-05 | J165: ='l_NB,NEC'!Q163 -> -0.20412564 | K165: ='l_NB,NEC'!R163 -> -0.1978419 | L165: =l_Solow!I163 -> #N/A | M165: =IF(AND($A165>=$A$1,$A165<$A$2),C165-C$2,"") | N165: =IF(AND($A165>=$A$1,$A165<$A$2),D165-D$2,"") | O165: =IF(AND($A165>=$A$1,$A165<$A$2),E165-E$2,"") | P165: =IF(AND($A165>=$A$1,$A165<$A$2),F165-F$2,"") | Q165: =IF(AND($A165>=$A$1,$A165<$A$2),G165-G$2,"") | R165: =IF(AND($A165>=$A$1,$A165<$A$2),H165-H$2,"") | S165: =IF(AND($A165>=$A$1,$A165<$A$2),I165-I$2,"") | T165: =IF(AND($A165>=$A$1,$A165<$A$2),J165-J$2,"") | ... V165: =IF(AND($A165>=$A$1,$A165<$A$2),L165-L$2,"")
A166: =EDATE(A165,3) -> 43922 | B166: =YEAR(A166)&"Q"&QUOTIENT(MONTH(A166)-1,3)+1 -> 2020Q2 | C166: =l_pi_c!H164 -> 0.0035253428 | D166: ='l_IC,pi_d'!E164 -> -0.060248436 | E166: ='l_IC,pi_d'!G164 -> -0.0093376765 | F166: =l_Output!D164 -> -0.081093737 | G166: ='l_HC,WC'!L164 -> -0.05392376 | H166: ='l_HC,WC'!N164 -> 0.017162791 | I166: =l_NSR!C164 -> -0.00010918455 | J166: ='l_NB,NEC'!Q164 -> 0.019298495 | K166: ='l_NB,NEC'!R164 -> 0.12005635 | L166: =l_Solow!I164 -> #N/A | M166: =IF(AND($A166>=$A$1,$A166<$A$2),C166-C$2,"") | N166: =IF(AND($A166>=$A$1,$A166<$A$2),D166-D$2,"") | O166: =IF(AND($A166>=$A$1,$A166<$A$2),E166-E$2,"") | P166: =IF(AND($A166>=$A$1,$A166<$A$2),F166-F$2,"") | Q166: =IF(AND($A166>=$A$1,$A166<$A$2),G166-G$2,"") | R166: =IF(AND($A166>=$A$1,$A166<$A$2),H166-H$2,"") | S166: =IF(AND($A166>=$A$1,$A166<$A$2),I166-I$2,"") | T166: =IF(AND($A166>=$A$1,$A166<$A$2),J166-J$2,"") | ... V166: =IF(AND($A166>=$A$1,$A166<$A$2),L166-L$2,"")
A167: =EDATE(A166,3) -> 44013 | B167: =YEAR(A167)&"Q"&QUOTIENT(MONTH(A167)-1,3)+1 -> 2020Q3 | C167: =l_pi_c!H165 -> 0.00062294724 | D167: ='l_IC,pi_d'!E165 -> -0.019145108 | E167: ='l_IC,pi_d'!G165 -> 0.0020070516 | F167: =l_Output!D165 -> 0.054054686 | G167: ='l_HC,WC'!L165 -> 0.027864587 | H167: ='l_HC,WC'!N165 -> -0.019719411 | I167: =l_NSR!C165 -> -9.7514263e-05 | J167: ='l_NB,NEC'!Q165 -> 0.010844113 | K167: ='l_NB,NEC'!R165 -> 0.056811569 | L167: =l_Solow!I165 -> #N/A | M167: =IF(AND($A167>=$A$1,$A167<$A$2),C167-C$2,"") | N167: =IF(AND($A167>=$A$1,$A167<$A$2),D167-D$2,"") | O167: =IF(AND($A167>=$A$1,$A167<$A$2),E167-E$2,"") | P167: =IF(AND($A167>=$A$1,$A167<$A$2),F167-F$2,"") | Q167: =IF(AND($A167>=$A$1,$A167<$A$2),G167-G$2,"") | R167: =IF(AND($A167>=$A$1,$A167<$A$2),H167-H$2,"") | S167: =IF(AND($A167>=$A$1,$A167<$A$2),I167-I$2,"") | T167: =IF(AND($A167>=$A$1,$A167<$A$2),J167-J$2,"") | ... V167: =IF(AND($A167>=$A$1,$A167<$A$2),L167-L$2,"")
A168: =EDATE(A167,3) -> 44105 | B168: =YEAR(A168)&"Q"&QUOTIENT(MONTH(A168)-1,3)+1 -> 2020Q4 | C168: =l_pi_c!H166 -> -0.0048855172 | D168: ='l_IC,pi_d'!E166 -> 0.043904312 | E168: ='l_IC,pi_d'!G166 -> -0.0045104401 | F168: =l_Output!D166 -> 0.029982953 | G168: ='l_HC,WC'!L166 -> 0.012399969 | H168: ='l_HC,WC'!N166 -> -0.0068111193 | I168: =l_NSR!C166 -> -6.5006338e-05 | J168: ='l_NB,NEC'!Q166 -> -0.067115952 | K168: ='l_NB,NEC'!R166 -> 0.080885299 | L168: =l_Solow!I166 -> #N/A | M168: =IF(AND($A168>=$A$1,$A168<$A$2),C168-C$2,"") | N168: =IF(AND($A168>=$A$1,$A168<$A$2),D168-D$2,"") | O168: =IF(AND($A168>=$A$1,$A168<$A$2),E168-E$2,"") | P168: =IF(AND($A168>=$A$1,$A168<$A$2),F168-F$2,"") | Q168: =IF(AND($A168>=$A$1,$A168<$A$2),G168-G$2,"") | R168: =IF(AND($A168>=$A$1,$A168<$A$2),H168-H$2,"") | S168: =IF(AND($A168>=$A$1,$A168<$A$2),I168-I$2,"") | T168: =IF(AND($A168>=$A$1,$A168<$A$2),J168-J$2,"") | ... V168: =IF(AND($A168>=$A$1,$A168<$A$2),L168-L$2,"")

Sheet l_pi_c
B1: GDP | D1: Deflator | J1: https://www.sangiin.go.jp/japanese/annai/chousa/rippou_chousa/backnumber/2014pdf/20140203034.pdf
B2: Nominal | C2: Real | D2: Level (incl. VAT) | E2: YoY (incl. VAT) | F2: YoY (excl. VAT) | G2: Level (excl. VAT) | H2: QoQ (excl. VAT)
A3: 29281 | B3: =nG_h23!B8*nG!$B$8/nG_h23!$B$64 -> 245801.57 | C3: =rG_h23!B8*rG!$B$8/rG_h23!$B$64 -> 270758.12 | D3: =B3/C3*100 -> 90.782713 | G3: =D3 -> 90.782713 | J3: ＜消費税調整用＞
A4: =EDATE(A3,3) -> 29373 | B4: =nG_h23!B9*nG!$B$8/nG_h23!$B$64 -> 250409.15 | C4: =rG_h23!B9*rG!$B$8/rG_h23!$B$64 -> 268779.55 | D4: =B4/C4*100 -> 93.165254 | G4: =D4 -> 93.165254 | H4: =LN(G4)-LN(G3) -> 0.02590596 | J4: 2014年増税の寄与 | K4: 0.014
A5: =EDATE(A4,3) -> 29465 | B5: =nG_h23!B10*nG!$B$8/nG_h23!$B$64 -> 258384.02 | C5: =rG_h23!B10*rG!$B$8/rG_h23!$B$64 -> 274419.87 | D5: =B5/C5*100 -> 94.156456 | G5: =D5 -> 94.156456 | H5: =LN(G5)-LN(G4) -> 0.010582979 | J5: 1％あたり寄与分 | K5: =K4/3 -> 0.0046666667
A6: =EDATE(A5,3) -> 29556 | B6: =nG_h23!B11*nG!$B$8/nG_h23!$B$64 -> 266236.92 | C6: =rG_h23!B11*rG!$B$8/rG_h23!$B$64 -> 280149.13 | D6: =B6/C6*100 -> 95.033999 | G6: =D6 -> 95.033999 | H6: =LN(G6)-LN(G5) -> 0.0092768876
A7: =EDATE(A6,3) -> 29646 | B7: =nG_h23!B12*nG!$B$8/nG_h23!$B$64 -> 268962.66 | C7: =rG_h23!B12*rG!$B$8/rG_h23!$B$64 -> 282193.55 | D7: =B7/C7*100 -> 95.311411 | E7: =LN(D7)-LN(D3) -> 0.048680664 | F7: =E7-SUMIFS($L$15:$L$18,$J$15:$J$18,"<"&$A7,$K$15:$K$18,">"&$A7) -> 0.048680664 | G7: =EXP(LN(G3)+F7) -> 95.311411 | H7: =LN(G7)-LN(G6) -> 0.0029148367 | J7: ＜消費税の増税幅＞
A8: =EDATE(A7,3) -> 29738 | B8: =nG_h23!B13*nG!$B$8/nG_h23!$B$64 -> 272900.73 | C8: =rG_h23!B13*rG!$B$8/rG_h23!$B$64 -> 284915.1 | D8: =B8/C8*100 -> 95.783176 | E8: =LN(D8)-LN(D4) -> 0.027712212 | F8: =E8-SUMIFS($L$15:$L$18,$J$15:$J$18,"<"&$A8,$K$15:$K$18,">"&$A8) -> 0.027712212 | G8: =EXP(LN(G4)+F8) -> 95.783176 | H8: =LN(G8)-LN(G7) -> 0.0049375082 | J8: 32599 | K8: 3
